Workbook

Sheet 01 Buckets
A1: AI ROI | MARKET MAP & MONETIZATION BUCKETS — 2030
A3: RESEARCH FRAMEWORK | Opportunity ≠ monetizable vendor revenue • Assumptions in blue • Public input values show source • Do not sum alternative methods
A5: CORE CONTROLS | PRIOR MODEL VALUES AND ILLUSTRATIVE PARAMETERS — REPLACE ONLY WHERE APPROPRIATE
B6: Projection year | C6: 2030 | E6: B2B / consumer market CAGR (illustrative) | F6: 0.03 | H6: U.S. labor gap wages ($bn) | I6: 586 | K6: Core model values: U.S. exposed wages ~$5.3T; global ex-China ~$14T; U.S. counterfactual missing-labor wage value ~$586B. All seat counts, market CAGR and hurdle numbers are examples.
B7: U.S. exposed wage pool ($bn) | C7: 5300 | E7: Global ex-China wage pool ($bn) | F7: 14000 | H7: Ex-China includes U.S. | I7: YES
B8: Hurdle LOW ($bn/yr) - scenario | C8: 600 | E8: Hurdle BASE ($bn/yr) - scenario | F8: 900 | H8: Hurdle HIGH ($bn/yr) - scenario | I8: 1200 | K8: Revenue map default: U.S. evidence pilot. Global ex-China wages are shown as a separate alternate geography, NOT added to U.S. value. Public B2B / B2C market sizes below are U.S. only.
B9: U.S. potential seats (million) - placeholder | C9: 100 | E9: Enterprise paid penetration - scenario | F9: 0.3 | H9: Annual price / paid seat ($) - scenario | I9: 1200
B10: Ex-China potential seats (million) - placeholder | C10: 400 | E10: Ex-China paid penetration - scenario | F10: 0.3 | H10: Annual price / paid seat ($) - scenario | I10: 1200
B11: 2025 consumer subscriptions ($bn) - example | C11: 18 | E11: Economic viability / exposed tasks | F11: 0.23 | H11: Effective task utilization | I11: 0.5 | K11: FORMULA: Projected market/wage base × in-scope % × AI-addressable % × effective utilization % × benefit or spending-shift % = economic opportunity; × vendor share = illustrative AI vendor revenue. For B2B, in-scope = comparable supplier operating margin, NOT gross profit. For a seat-based alternative, direct paying seats × annual fee becomes a separately tagged row.
B12: Realizable task labor saving | C12: 0.25 | E12: Vendor share of realized economic benefit | F12: 0.5 | H12: Labor gap AI-addressable portion | I12: 0.5
B13: Labor gap AI-fulfilled portion | C13: 0.5 | E13: Vendor share of missing-labor value | F13: 0.65 | H13: Illustrative B2C AI device share shift | I13: 0.01
A15: A | ALL BUCKETS — BASE DATA, 2030 SCENARIO, AI ECONOMICS, AND OVERLAP GATES
A17: ID | B17: Primary bucket | C17: Submarket / use case | D17: Economic channel | E17: What buyer gains / what is displaced | F17: Source year | G17: Market geography | H17: Source market / wages ($bn) | I17: Projected 2030 base ($bn) | J17: In-scope % | K17: AI-addressable % | L17: Utilization % | M17: Benefit or spend shift % | N17: Vendor capture % | O17: Economic value ($bn/yr) | P17: Vendor rev proxy ($bn/yr) | Q17: Include (0 / 1) | R17: Core waterfall ($bn/yr) | S17: Evidence status | T17: Public source / download link | U17: Boundary / overlap check
A19: L01 | B19: LABOR | C19: Missing workers: U.S. growth-trend gap | D19: FILL / SAVINGS | E19: Value of counterfactual positions that might be serviced without equivalent hires | F19: 2030 | G19: U.S. - prior model | H19: =I6 -> 586 | I19: =IF(H19="","",H19*(1+$F$6)^MAX(0,$C$6-F19)) -> 586 | J19: 1 | K19: =I12 -> 0.5 | L19: =C13 -> 0.5 | M19: 1 | N19: =F13 -> 0.65 | O19: =IF(I19="","",I19*J19*K19*L19*M19) -> 146.5 | P19: =IF(O19="","",O19*N19) -> 95.225 | Q19: 0 | R19: =IF(P19="",0,P19*Q19) -> 0 | S19: PRIOR MODEL + SCENARIO | T19: Link labor-gap workbook; BLS employment projections | U19: Potentially overlaps with enterprise-seat revenue and wage-augmentation benefits; default exclude
A20: L02 | B20: LABOR | C20: Existing workers: wage-value capture | D20: AUGMENT / SAVE | E20: Working wage pool; exposure already embedded in 2030 exposed-wage base | F20: 2030 | G20: U.S. - prior model | H20: =C7 -> 5300 | I20: =IF(H20="","",H20*(1+$F$6)^MAX(0,$C$6-F20)) -> 5300 | J20: 1 | K20: =F11 -> 0.23 | L20: =I11 -> 0.5 | M20: =C12 -> 0.25 | N20: =F12 -> 0.5 | O20: =IF(I20="","",I20*J20*K20*L20*M20) -> 152.375 | P20: =IF(O20="","",O20*N20) -> 76.1875 | Q20: 1 | R20: =IF(P20="",0,P20*Q20) -> 76.1875 | S20: PRIOR MODEL + PWBM ASSUMPTIONS | T20: https://budgetmodel.wharton.upenn.edu/p/2025-09-08-the-projected-impact-of-generative-ai-on-future-productivity-growth/ | U20: This value supports willingness to pay; do not add to seat-based enterprise subscription revenue
A21: L03 | B21: LABOR | C21: Existing workers: global ex-China value | D21: AUGMENT / SAVE | E21: Alternative geography to L02; includes U.S. | F21: 2030 | G21: Global ex-China | H21: =F7 -> 14000 | I21: =IF(H21="","",H21*(1+$F$6)^MAX(0,$C$6-F21)) -> 14000 | J21: 1 | K21: =F11 -> 0.23 | L21: =I11 -> 0.5 | M21: =C12 -> 0.25 | N21: =F12 -> 0.5 | O21: =IF(I21="","",I21*J21*K21*L21*M21) -> 402.5 | P21: =IF(O21="","",O21*N21) -> 201.25 | Q21: 0 | R21: =IF(P21="",0,P21*Q21) -> 0 | S21: PRIOR MODEL + SCENARIO | T21: Link existing global ex-China exposure model | U21: Alternative to L02, not incremental US revenue; do not enter US waterfall
A22: L04 | B22: LABOR | C22: Enterprise paid seats: U.S. method | D22: SEAT / PRICE | E22: Cross-check enterprise vendor revenue based on potential seats, paid share and pricing | F22: 2030 | G22: U.S. - illustrative | H22: =C9*F9*I9/1000 -> 36 | I22: =IF(H22="","",H22*(1+$F$6)^MAX(0,$C$6-F22)) -> 36 | J22: 1 | K22: 1 | L22: 1 | M22: 1 | N22: 1 | O22: =IF(I22="","",I22*J22*K22*L22*M22) -> 36 | P22: =IF(O22="","",O22*N22) -> 36 | Q22: 0 | R22: =IF(P22="",0,P22*Q22) -> 0 | S22: ILLUSTRATIVE SEATS | T22: Link previously computed U.S. exposed headcount; Copilot seat benchmark | U22: Alternative to L02, no sum; potential exposed headcount must not be task-adjusted worker count
A23: L05 | B23: LABOR | C23: Enterprise paid seats: global ex-China | D23: SEAT / PRICE | E23: Global seat-based cross-check | F23: 2030 | G23: Global ex-China | H23: =C10*F10*I10/1000 -> 144 | I23: =IF(H23="","",H23*(1+$F$6)^MAX(0,$C$6-F23)) -> 144 | J23: 1 | K23: 1 | L23: 1 | M23: 1 | N23: 1 | O23: =IF(I23="","",I23*J23*K23*L23*M23) -> 144 | P23: =IF(O23="","",O23*N23) -> 144 | Q23: 0 | R23: =IF(P23="",0,P23*Q23) -> 0 | S23: ILLUSTRATIVE SEATS | T23: Link previously computed global ex-China exposed headcount | U23: Alternative geography / method; not additive with L03 or L04
A24: B01 | B24: B2B | C24: Enterprise application software / SaaS | D24: PROFIT TRANSFER | E24: Internal-build AI agents may substitute purchased software features | F24: 2024 | G24: U.S. official | H24: 567.77238 | I24: =IF(H24="","",H24*(1+$F$6)^MAX(0,$C$6-F24)) -> 677.94991 | J24: 0.3298 | K24: 0.4 | L24: 0.35 | M24: 1 | N24: 0.5 | O24: =IF(I24="","",I24*J24*K24*L24*M24) -> 31.302303 | P24: =IF(O24="","",O24*N24) -> 15.651152 | Q24: 0 | R24: =IF(P24="",0,P24*Q24) -> 0 | S24: PUBLIC MARKET / PROXY MARGIN | T24: https://fred.stlouisfed.org/series/AIES5112RCT00US | U24: Supplier operating profit only; wage cost is already represented in labor bucket. Excludes broad cloud infra sales
A25: B02 | B25: B2B | C25: IT services and systems integration | D25: PROFIT TRANSFER | E25: Automated migration, integration, implementation, maintenance | F25: 2024 | G25: U.S. official | H25: 663.5005 | I25: =IF(H25="","",H25*(1+$F$6)^MAX(0,$C$6-F25)) -> 792.2543 | J25: 0.0741 | K25: 0.45 | L25: 0.35 | M25: 1 | N25: 0.5 | O25: =IF(I25="","",I25*J25*K25*L25*M25) -> 9.2462019 | P25: =IF(O25="","",O25*N25) -> 4.6231009 | Q25: 0 | R25: =IF(P25="",0,P25*Q25) -> 0 | S25: PUBLIC MARKET / PROXY MARGIN | T25: https://fred.stlouisfed.org/series/AIES5415RCT00US | U25: Distinct from software publishers NAICS; excludes labor to avoid duplicates
A26: B03 | B26: B2B | C26: Law firms / document review | D26: PROFIT TRANSFER | E26: Contract drafting, discovery, document analysis, legal support | F26: 2024 | G26: U.S. official | H26: 414.84748 | I26: =IF(H26="","",H26*(1+$F$6)^MAX(0,$C$6-F26)) -> 495.34959 | J26: 0.111 | K26: 0.5 | L26: 0.35 | M26: 1 | N26: 0.5 | O26: =IF(I26="","",I26*J26*K26*L26*M26) -> 9.6221657 | P26: =IF(O26="","",O26*N26) -> 4.8110828 | Q26: 0 | R26: =IF(P26="",0,P26*Q26) -> 0 | S26: PUBLIC MARKET / MARGIN PROXY | T26: https://fred.stlouisfed.org/series/AIES54111RCT00US | U26: Law offices, not all legal services. General services EBIT margin is only a proxy
A27: B04 | B27: B2B | C27: Management consulting & analysis | D27: PROFIT TRANSFER | E27: Automate first drafts, analysis, diligence and research workflow | F27: 2024 | G27: U.S. official | H27: 396.91531 | I27: =IF(H27="","",H27*(1+$F$6)^MAX(0,$C$6-F27)) -> 473.93764 | J27: 0.111 | K27: 0.4 | L27: 0.35 | M27: 1 | N27: 0.5 | O27: =IF(I27="","",I27*J27*K27*L27*M27) -> 7.3649909 | P27: =IF(O27="","",O27*N27) -> 3.6824955 | Q27: 0 | R27: =IF(P27="",0,P27*Q27) -> 0 | S27: PUBLIC MARKET / MARGIN PROXY | T27: https://fred.stlouisfed.org/series/AIES54161RCT00US | U27: Consulting scope includes labor; do NOT treat full fees as incremental AI spend
A28: B05 | B28: B2B | C28: Advertising agencies & creative production | D28: PROFIT TRANSFER | E28: Creative, media planning, content and campaign analytics | F28: 2024 | G28: U.S. official | H28: 69.402338 | I28: =IF(H28="","",H28*(1+$F$6)^MAX(0,$C$6-F28)) -> 82.870021 | J28: 0.1007 | K28: 0.5 | L28: 0.35 | M28: 1 | N28: 0.5 | O28: =IF(I28="","",I28*J28*K28*L28*M28) -> 1.4603769 | P28: =IF(O28="","",O28*N28) -> 0.73018847 | Q28: 0 | R28: =IF(P28="",0,P28*Q28) -> 0 | S28: PUBLIC MARKET / PROXY MARGIN | T28: https://fred.stlouisfed.org/series/AIES54181RCT00US | U28: Agency fees only, not ad media spend; avoid double count marketing employee wages
A29: B06 | B29: B2B | C29: Accounting, audit and payroll operations | D29: PROFIT TRANSFER | E29: Bookkeeping, financial close, tax drafting, audit preparation | F29: 2024 | G29: U.S. - source needed | I29: =IF(H29="","",H29*(1+$F$6)^MAX(0,$C$6-F29)) | J29: 0.11 | K29: 0.4 | L29: 0.3 | M29: 1 | N29: 0.5 | O29: =IF(I29="","",I29*J29*K29*L29*M29) | P29: =IF(O29="","",O29*N29) | Q29: 0 | R29: =IF(P29="",0,P29*Q29) -> 0 | S29: NEEDS DISTINCT MARKET BASE | T29: https://www.census.gov/programs-surveys/aies.html | U29: Separate audit / payroll revenues to avoid overlapping management consulting
A30: B07 | B30: B2B | C30: Customer contact-center outsourcing | D30: PROFIT TRANSFER | E30: Replace outsourced service vendor work; AI voice / support automation | F30: 2024 | G30: U.S. - source needed | I30: =IF(H30="","",H30*(1+$F$6)^MAX(0,$C$6-F30)) | J30: 0.11 | K30: 0.5 | L30: 0.35 | M30: 1 | N30: 0.5 | O30: =IF(I30="","",I30*J30*K30*L30*M30) | P30: =IF(O30="","",O30*N30) | Q30: 0 | R30: =IF(P30="",0,P30*Q30) -> 0 | S30: NEEDS DISTINCT MARKET BASE | T30: https://www.census.gov/programs-surveys/aies.html | U30: Could overlap with existing in-house labor productivity and contact-center agent subscription
A31: B08 | B31: B2B | C31: Recruitment & HR outsourcing | D31: PROFIT TRANSFER | E31: Recruiter workflows, screening, onboarding and HR administration | F31: 2024 | G31: U.S. - source needed | I31: =IF(H31="","",H31*(1+$F$6)^MAX(0,$C$6-F31)) | J31: 0.11 | K31: 0.4 | L31: 0.35 | M31: 1 | N31: 0.5 | O31: =IF(I31="","",I31*J31*K31*L31*M31) | P31: =IF(O31="","",O31*N31) | Q31: 0 | R31: =IF(P31="",0,P31*Q31) -> 0 | S31: NEEDS DISTINCT MARKET BASE | T31: https://www.census.gov/programs-surveys/aies.html | U31: Staffing pass-through wages are NOT AI vendor revenue
A32: B09 | B32: B2B | C32: Market data, research and information licensing | D32: PROFIT TRANSFER | E32: Agent retrieval, data aggregation and analyst tools substitute contracted services | F32: 2024 | G32: U.S. - source needed | I32: =IF(H32="","",H32*(1+$F$6)^MAX(0,$C$6-F32)) | J32: 0.18 | K32: 0.45 | L32: 0.35 | M32: 1 | N32: 0.5 | O32: =IF(I32="","",I32*J32*K32*L32*M32) | P32: =IF(O32="","",O32*N32) | Q32: 0 | R32: =IF(P32="",0,P32*Q32) -> 0 | S32: NEEDS DISTINCT MARKET BASE | T32: https://www.census.gov/programs-surveys/aies.html | U32: Avoid licensing / data ownership and cannibalization assumptions
A33: B10 | B33: B2B | C33: Cybersecurity / compliance managed services | D33: PROFIT TRANSFER | E33: AI triage, security operations, compliance surveillance | F33: 2024 | G33: U.S. - source needed | I33: =IF(H33="","",H33*(1+$F$6)^MAX(0,$C$6-F33)) | J33: 0.14 | K33: 0.35 | L33: 0.3 | M33: 1 | N33: 0.5 | O33: =IF(I33="","",I33*J33*K33*L33*M33) | P33: =IF(O33="","",O33*N33) | Q33: 0 | R33: =IF(P33="",0,P33*Q33) -> 0 | S33: NEEDS DISTINCT MARKET BASE | T33: https://www.census.gov/programs-surveys/aies.html | U33: Could create net new cyber spend, not just eliminate existing margins
A34: B11 | B34: B2B | C34: Procurement, logistics and supply chain services | D34: PROFIT TRANSFER | E34: Automation of sourcing / claims / scheduling / freight administration | F34: 2024 | G34: U.S. - source needed | I34: =IF(H34="","",H34*(1+$F$6)^MAX(0,$C$6-F34)) | J34: 0.11 | K34: 0.3 | L34: 0.25 | M34: 1 | N34: 0.5 | O34: =IF(I34="","",I34*J34*K34*L34*M34) | P34: =IF(O34="","",O34*N34) | Q34: 0 | R34: =IF(P34="",0,P34*Q34) -> 0 | S34: NEEDS DISTINCT MARKET BASE | T34: https://www.census.gov/programs-surveys/aies.html | U34: Separate platform margins from physical goods/freight; avoid gross merchandise flow
A35: B12 | B35: B2B | C35: Industrial robotics, manufacturing agents | D35: NEW CAPABILITY | E35: Physical automation-as-a-service; new productive capacity | F35: 2030 | G35: Global - potential | I35: =IF(H35="","",H35*(1+$F$6)^MAX(0,$C$6-F35)) | J35: 1 | K35: 0.3 | L35: 0.3 | M35: 0.1 | N35: 0.5 | O35: =IF(I35="","",I35*J35*K35*L35*M35) | P35: =IF(O35="","",O35*N35) | Q35: 0 | R35: =IF(P35="",0,P35*Q35) -> 0 | S35: FRONTIER / NO BASE | T35: https://ifr.org/ | U35: New spend category; adoption and unique pricing needed before inclusion
A36: B13 | B36: B2B | C36: Drug discovery & life-science AI services | D36: NEW CAPABILITY | E36: Molecule screening / clinical design / R&D support | F36: 2030 | G36: Global - potential | I36: =IF(H36="","",H36*(1+$F$6)^MAX(0,$C$6-F36)) | J36: 1 | K36: 0.3 | L36: 0.25 | M36: 0.08 | N36: 0.5 | O36: =IF(I36="","",I36*J36*K36*L36*M36) | P36: =IF(O36="","",O36*N36) | Q36: 0 | R36: =IF(P36="",0,P36*Q36) -> 0 | S36: FRONTIER / NO BASE | T36: https://www.nih.gov/ | U36: Large economic benefits are not identical to AI provider revenue
A37: B14 | B37: B2B | C37: Energy & data center orchestration | D37: NEW CAPABILITY | E37: AI optimizes industrial electricity, grid scheduling and uptime | F37: 2030 | G37: Global - potential | I37: =IF(H37="","",H37*(1+$F$6)^MAX(0,$C$6-F37)) | J37: 1 | K37: 0.3 | L37: 0.25 | M37: 0.07 | N37: 0.5 | O37: =IF(I37="","",I37*J37*K37*L37*M37) | P37: =IF(O37="","",O37*N37) | Q37: 0 | R37: =IF(P37="",0,P37*Q37) -> 0 | S37: FRONTIER / NO BASE | T37: https://www.eia.gov/ | U37: Avoid counting energy-infrastructure capital spend as software revenue
A38: C01 | B38: B2C | C38: Personal AI subscriptions / assistants | D38: SUBSCRIPTION | E38: Direct consumer recurring fees, separate from employer-paid seats | F38: 2030 | G38: U.S. illustrative | H38: =C11 -> 18 | I38: =IF(H38="","",H38*(1+$F$6)^MAX(0,$C$6-F38)) -> 18 | J38: 1 | K38: 1 | L38: 1 | M38: 1 | N38: 1 | O38: =IF(I38="","",I38*J38*K38*L38*M38) -> 18 | P38: =IF(O38="","",O38*N38) -> 18 | Q38: 1 | R38: =IF(P38="",0,P38*Q38) -> 18 | S38: ILLUSTRATIVE / LINK YOUR MODEL | T38: Link existing consumer subscriptions workbook | U38: Treat as observed AI vendor revenue only if subscription billings independently derived
A39: C02 | B39: B2C | C39: AI PCs & consumer technology premium | D39: SPEND REALLOCATION | E39: Consumer hardware premium / AI-enabled device refresh, net incremental wallet unclear | F39: 2025 | G39: U.S. official | H39: 427.604 | I39: =IF(H39="","",H39*(1+$F$6)^MAX(0,$C$6-F39)) -> 495.71023 | J39: 1 | K39: 1 | L39: 1 | M39: =I13 -> 0.01 | N39: 0.25 | O39: =IF(I39="","",I39*J39*K39*L39*M39) -> 4.9571023 | P39: =IF(O39="","",O39*N39) -> 1.2392756 | Q39: 0 | R39: =IF(P39="",0,P39*Q39) -> 0 | S39: PUBLIC SPEND BASE + SCENARIO | T39: https://fred.stlouisfed.org/series/DVAPRC1A027NBEA | U39: 1% of PCE is a SPEND SHIFT, not new AI revenue; vendor share proxy; no overlap with device services
A40: C03 | B40: B2C | C40: Smart glasses, wearables, personal interfaces | D40: NEW PRODUCTS | E40: Premium devices and bundled AI experiences | F40: 2025 | G40: U.S. - overlaps C02 | I40: =IF(H40="","",H40*(1+$F$6)^MAX(0,$C$6-F40)) | J40: 1 | K40: 0.2 | L40: 0.3 | M40: 0.1 | N40: 0.25 | O40: =IF(I40="","",I40*J40*K40*L40*M40) | P40: =IF(O40="","",O40*N40) | Q40: 0 | R40: =IF(P40="",0,P40*Q40) -> 0 | S40: SEPARATE SUBSEGMENT NEEDED | T40: https://www.bea.gov/data/consumer-spending/main | U40: Do not add to C02 broad consumer equipment category without netting subcategory
A41: C04 | B41: B2C | C41: Education, tutoring and language learning | D41: SUBSCRIPTION | E41: Households purchase personalized AI tutors / learning services | F41: 2030 | G41: Global - potential | I41: =IF(H41="","",H41*(1+$F$6)^MAX(0,$C$6-F41)) | J41: 1 | K41: 0.35 | L41: 0.3 | M41: 0.2 | N41: 0.7 | O41: =IF(I41="","",I41*J41*K41*L41*M41) | P41: =IF(O41="","",O41*N41) | Q41: 0 | R41: =IF(P41="",0,P41*Q41) -> 0 | S41: NEEDS CONSUMER PRICE / USERS | T41: https://www.bea.gov/data/consumer-spending/main | U41: Exclude paid enterprise / school edtech overlapping institutional SaaS
A42: C05 | B42: B2C | C42: Wellness, health navigation, coaching | D42: SUBSCRIPTION | E42: Consumer care support, coaching, non-diagnostic wellness | F42: 2030 | G42: Global - potential | I42: =IF(H42="","",H42*(1+$F$6)^MAX(0,$C$6-F42)) | J42: 1 | K42: 0.3 | L42: 0.25 | M42: 0.2 | N42: 0.65 | O42: =IF(I42="","",I42*J42*K42*L42*M42) | P42: =IF(O42="","",O42*N42) | Q42: 0 | R42: =IF(P42="",0,P42*Q42) -> 0 | S42: NEEDS CONSUMER PRICE / USERS | T42: https://www.bea.gov/data/consumer-spending/main | U42: Regulatory and clinical constraints; distinct from employer healthcare platforms
A43: C06 | B43: B2C | C43: Entertainment, games and personalized media | D43: NEW MEDIA | E43: AI-generated interactive entertainment / premium media plans | F43: 2030 | G43: Global - potential | I43: =IF(H43="","",H43*(1+$F$6)^MAX(0,$C$6-F43)) | J43: 1 | K43: 0.3 | L43: 0.3 | M43: 0.1 | N43: 0.5 | O43: =IF(I43="","",I43*J43*K43*L43*M43) | P43: =IF(O43="","",O43*N43) | Q43: 0 | R43: =IF(P43="",0,P43*Q43) -> 0 | S43: NEEDS PRICE / CATALOG | T43: https://www.bea.gov/data/consumer-spending/main | U43: Avoid claiming total streaming/game spend incremental from AI
A44: C07 | B44: B2C | C44: AI shopping agents and commerce | D44: COMMISSION | E44: Consumer commerce agents; vendor earns take rate on attributable transactions | F44: 2030 | G44: Global - potential | I44: =IF(H44="","",H44*(1+$F$6)^MAX(0,$C$6-F44)) | J44: 1 | K44: 0.3 | L44: 0.3 | M44: 0.02 | N44: 0.5 | O44: =IF(I44="","",I44*J44*K44*L44*M44) | P44: =IF(O44="","",O44*N44) | Q44: 0 | R44: =IF(P44="",0,P44*Q44) -> 0 | S44: NEEDS AGENT GMV / TAKE RATE | T44: https://www.census.gov/retail/ | U44: Do not use full GMV as AI vendor revenue; only attributable incremental fee
A45: C08 | B45: B2C | C45: Creator, photo, audio and video AI tools | D45: SUBSCRIPTION | E45: New individual prosumer software and asset creation | F45: 2030 | G45: Global - potential | I45: =IF(H45="","",H45*(1+$F$6)^MAX(0,$C$6-F45)) | J45: 1 | K45: 0.4 | L45: 0.3 | M45: 0.1 | N45: 0.7 | O45: =IF(I45="","",I45*J45*K45*L45*M45) | P45: =IF(O45="","",O45*N45) | Q45: 0 | R45: =IF(P45="",0,P45*Q45) -> 0 | S45: NEEDS NON-OVERLAPPING USERS | T45: https://www.bea.gov/data/consumer-spending/main | U45: Check overlap with C01 AI assistant subscriptions and workplace creator seats
...

Sheet 02 Football Field
A1: AI ROI | FOOTBALL FIELD & REVENUE BRIDGE — 2030
A3: DOLLARS PER YEAR ($bn) • U.S. public-market pilot, plus separate Global ex-China labor scenarios • Blue = input • Green = linked worksheet • Shaded = illustrative / unverified
A5: 01 | ONE-PAGE ROI SCORECARD — SOURCE VALUE, ECONOMIC POOL, AND VENDOR REVENUE ARE DIFFERENT THINGS
A6: ID | B6: Measure / bucket | C6: U.S. ($bn/yr) | D6: Global ex-China ($bn/yr) | E6: Revenue interpretation | F6: Next model step
A7: ECON | B7: AI-exposed wage base | C7: ='01 Buckets'!C7 -> 5300 | D7: ='01 Buckets'!F7 -> 14000 | E7: Technical wage exposure; NOT spend | F7: Preserve base from existing model
A8: LABOR | B8: Counterfactual missing labor gap | C8: ='01 Buckets'!I6 -> 586 | E8: Economic need, not observed vendor revenue | F8: Link Global ex-China gap when available
A9: LABOR | B9: Existing worker economic value | C9: ='01 Buckets'!O20 -> 152.375 | D9: ='01 Buckets'!O21 -> 402.5 | E9: Employer-side value BEFORE vendor capture | F9: Check 23% viability and realized task saving
A10: LABOR | B10: Existing worker vendor capture | C10: ='01 Buckets'!P20 -> 76.1875 | D10: ='01 Buckets'!P21 -> 201.25 | E10: Alternative to seat-subscription model | F10: Avoid adding to per-seat subscription revenue
A11: LABOR | B11: Enterprise seat subscription alternative | C11: ='01 Buckets'!P22 -> 36 | D11: ='01 Buckets'!P23 -> 144 | E11: Paid seats × annual price (illustrative) | F11: Connect actual employee denominators
A12: B2B | B12: U.S. incumbent provider profit capture | C12: =SUM('01 Buckets'!P24:P37) -> 29.498019 | E12: Screened supplier profit transfer only | F12: Needs non-overlap sign-off and global data
A13: B2C | B13: Direct consumer subscriptions | C13: ='01 Buckets'!P38 -> 18 | E13: Distinct household-paid revenue | F13: Replace illustrative consumer subscriber model
A14: B2C | B14: AI consumer device spend shift | C14: ='01 Buckets'!P39 -> 1.2392756 | E14: Potential wallet reallocation; not proven net AI revenue | F14: Validate incremental AI content / value capture
A15: RESULT | B15: CORE selected model sum | C15: =SUM('01 Buckets'!R19:R49) -> 94.1875 | E15: Scenario screening metric; US-oriented pilot | F15: Compare to matched regional infrastructure hurdle
A16: RESULT | B16: Gross exploratory proxy, NOT additive | C16: =SUM('01 Buckets'!P19:P49) -> 601.39979 | E16: Includes regional / methodological doubles | F16: NEVER use as publishable total
A17: HURDLE | B17: Annual required revenue — illustrative low | C17: ='01 Buckets'!C8 -> 600 | E17: Not a matched U.S. investment hurdle yet | F17: LINK CapEx / capital recovery output
A18: HURDLE | B18: Annual required revenue — illustrative base | C18: ='01 Buckets'!F8 -> 900 | E18: Not a matched U.S. investment hurdle yet | F18: LINK CapEx / capital recovery output
A19: HURDLE | B19: Annual required revenue — illustrative high | C19: ='01 Buckets'!I8 -> 1200 | E19: Not a matched U.S. investment hurdle yet | F19: LINK CapEx / capital recovery output
A21: 02 | FOOTBALL-FIELD RANGES BY MONETIZATION BUCKET — ILLUSTRATIVE SCENARIOS
A22: Code | B22: Opportunity category | C22: Low 0.6× ($bn) | D22: Base ($bn) | E22: High 1.5× ($bn) | F22: Boundary / inclusion note
A23: R1 | B23: Missing labor | C23: =D23*0.6 -> 57.135 | D23: ='01 Buckets'!P19 -> 95.225 | E23: =D23*1.5 -> 142.8375 | F23: Independent monetization is UNVERIFIED; core waterfall OFF
A24: R2 | B24: Existing worker AI | C24: =D24*0.6 -> 45.7125 | D24: ='01 Buckets'!P20 -> 76.1875 | E24: =D24*1.5 -> 114.28125 | F24: Wage-value capture; alternative to enterprise price per seat
A25: R3 | B25: Enterprise seats — alternative | C25: =D25*0.6 -> 21.6 | D25: ='01 Buckets'!P22 -> 36 | E25: =D25*1.5 -> 54 | F25: Do NOT add with existing worker captured wages
A26: R4 | B26: B2B supplier profit | C26: =D26*0.6 -> 17.698812 | D26: =SUM('01 Buckets'!P24:P37) -> 29.498019 | E26: =D26*1.5 -> 44.247029 | F26: Only incumbent nonlabor profit proxy; confidence low
A27: R5 | B27: Consumer subscriptions | C27: =D27*0.6 -> 10.8 | D27: ='01 Buckets'!P38 -> 18 | E27: =D27*1.5 -> 27 | F27: Subscription estimate to link to existing consumer model
A28: R6 | B28: Consumer devices / tech share shift | C28: =D28*0.6 -> 0.74356535 | D28: ='01 Buckets'!P39 -> 1.2392756 | E28: =D28*1.5 -> 1.8589134 | F28: Spend reallocation proxy; not proven vendor increment
A30: Low and High are presentation sensitivities (0.6× / 1.5×), not statistical confidence intervals. The source opportunity is NOT additive to wages/seat alternatives by default.
A34: 03 | UPWARD WATERFALL — SELECTED US REVENUE CHANNELS ONLY (DO NOT MIX GLOBAL WAGE BASE)
A35: Step | B35: Annual revenue component | C35: Flow ($bn) | D35: Cumulative ($bn) | E35: Waterfall offset | F35: Included?
A36: 1 | B36: Labor gap | C36: ='01 Buckets'!R19 -> 0 | D36: =SUM($C$36:C36) -> 0 | E36: =D36-C36 -> 0 | F36: ='01 Buckets'!Q19 -> 0
A37: 2 | B37: Enterprise: existing labor | C37: ='01 Buckets'!R20 -> 76.1875 | D37: =SUM($C$36:C37) -> 76.1875 | E37: =D37-C37 -> 0 | F37: ='01 Buckets'!Q20 -> 1
A38: 3 | B38: B2B: software publishers | C38: ='01 Buckets'!R24 -> 0 | D38: =SUM($C$36:C38) -> 76.1875 | E38: =D38-C38 -> 76.1875 | F38: ='01 Buckets'!Q24 -> 0
A39: 4 | B39: B2B: IT services | C39: ='01 Buckets'!R25 -> 0 | D39: =SUM($C$36:C39) -> 76.1875 | E39: =D39-C39 -> 76.1875 | F39: ='01 Buckets'!Q25 -> 0
A40: 5 | B40: B2B: legal | C40: ='01 Buckets'!R26 -> 0 | D40: =SUM($C$36:C40) -> 76.1875 | E40: =D40-C40 -> 76.1875 | F40: ='01 Buckets'!Q26 -> 0
A41: 6 | B41: B2B: consulting | C41: ='01 Buckets'!R27 -> 0 | D41: =SUM($C$36:C41) -> 76.1875 | E41: =D41-C41 -> 76.1875 | F41: ='01 Buckets'!Q27 -> 0
A42: 7 | B42: B2B: advertising | C42: ='01 Buckets'!R28 -> 0 | D42: =SUM($C$36:C42) -> 76.1875 | E42: =D42-C42 -> 76.1875 | F42: ='01 Buckets'!Q28 -> 0
A43: 8 | B43: B2C: subscriptions | C43: ='01 Buckets'!R38 -> 18 | D43: =SUM($C$36:C43) -> 94.1875 | E43: =D43-C43 -> 76.1875 | F43: ='01 Buckets'!Q38 -> 1
A44: 9 | B44: B2C: device upgrade shift | C44: ='01 Buckets'!R39 -> 0 | D44: =SUM($C$36:C44) -> 94.1875 | E44: =D44-C44 -> 94.1875 | F44: ='01 Buckets'!Q39 -> 0
B45: TOTAL SELECTED ANNUAL REVENUE | C45: =SUM(C36:C44) -> 94.1875
A47: The chart adds ONLY rows with Include = 1. Change inclusion gates in Buckets Q-column only after reconciling enterprise alternatives and provider profit transfer. Exhibit is illustrative, not a matched economic ROI forecast.
A50: 04 | MAP OF ECONOMIC RELATIONSHIPS — WHY BUCKETS CANNOT BE SUMMED AS IF ALL WERE VENDOR REVENUE
...
