Workbook

Sheet 01 Industry Model
A1: AI-EXPOSED WAGE POOL | U.S. PRIVATE INDUSTRIES (2025)
A2: Primary: QCEW private industry wages × Wharton task exposure, weighted by OEWS occupation wages. All mapping is formula-driven in DATA OEWS.
A4: NAICS | B4: Industry | C4: Private Wages ($bn) | D4: OEWS Wages ($bn) | E4: Matched Wages ($bn) | F4: Exposure-Weighted Wages ($bn) | G4: Wharton Match Rate | H4: Wharton Task Exposure | I4: GROSS EXPOSED ($bn) | J4: BTOS AI Using Firms | K4: BTOS Firm-Use Proxy ($bn)
A5: 11 | B5: Agriculture, forestry, fishing and hunting | C5: =IFERROR(XLOOKUP(A5,'DATA QCEW'!$A$2:$A$20,'DATA QCEW'!$C$2:$C$20)/1000000000,"") | D5: =SUMIF('DATA OEWS'!$A$2:$A$13458,A5,'DATA OEWS'!$G$2:$G$13458)/1000000000 | E5: =SUMIF('DATA OEWS'!$A$2:$A$13458,A5,'DATA OEWS'!$I$2:$I$13458)/1000000000 | F5: =SUMIF('DATA OEWS'!$A$2:$A$13458,A5,'DATA OEWS'!$J$2:$J$13458)/1000000000 | G5: =IF(D5=0,"",E5/D5) | H5: =IF(E5=0,"",F5/E5) | I5: =C5*H5 | J5: =IFERROR(XLOOKUP(A5,'DATA Census'!$A$2:$A$20,'DATA Census'!$C$2:$C$20),"") | K5: =I5*J5
A6: 21 | B6: Mining, quarrying, and oil and gas extraction | C6: =IFERROR(XLOOKUP(A6,'DATA QCEW'!$A$2:$A$20,'DATA QCEW'!$C$2:$C$20)/1000000000,"") | D6: =SUMIF('DATA OEWS'!$A$2:$A$13458,A6,'DATA OEWS'!$G$2:$G$13458)/1000000000 | E6: =SUMIF('DATA OEWS'!$A$2:$A$13458,A6,'DATA OEWS'!$I$2:$I$13458)/1000000000 | F6: =SUMIF('DATA OEWS'!$A$2:$A$13458,A6,'DATA OEWS'!$J$2:$J$13458)/1000000000 | G6: =IF(D6=0,"",E6/D6) | H6: =IF(E6=0,"",F6/E6) | I6: =C6*H6 | J6: =IFERROR(XLOOKUP(A6,'DATA Census'!$A$2:$A$20,'DATA Census'!$C$2:$C$20),"") | K6: =I6*J6
A7: 22 | B7: Utilities | C7: =IFERROR(XLOOKUP(A7,'DATA QCEW'!$A$2:$A$20,'DATA QCEW'!$C$2:$C$20)/1000000000,"") | D7: =SUMIF('DATA OEWS'!$A$2:$A$13458,A7,'DATA OEWS'!$G$2:$G$13458)/1000000000 | E7: =SUMIF('DATA OEWS'!$A$2:$A$13458,A7,'DATA OEWS'!$I$2:$I$13458)/1000000000 | F7: =SUMIF('DATA OEWS'!$A$2:$A$13458,A7,'DATA OEWS'!$J$2:$J$13458)/1000000000 | G7: =IF(D7=0,"",E7/D7) | H7: =IF(E7=0,"",F7/E7) | I7: =C7*H7 | J7: =IFERROR(XLOOKUP(A7,'DATA Census'!$A$2:$A$20,'DATA Census'!$C$2:$C$20),"") | K7: =I7*J7
A8: 23 | B8: Construction | C8: =IFERROR(XLOOKUP(A8,'DATA QCEW'!$A$2:$A$20,'DATA QCEW'!$C$2:$C$20)/1000000000,"") | D8: =SUMIF('DATA OEWS'!$A$2:$A$13458,A8,'DATA OEWS'!$G$2:$G$13458)/1000000000 | E8: =SUMIF('DATA OEWS'!$A$2:$A$13458,A8,'DATA OEWS'!$I$2:$I$13458)/1000000000 | F8: =SUMIF('DATA OEWS'!$A$2:$A$13458,A8,'DATA OEWS'!$J$2:$J$13458)/1000000000 | G8: =IF(D8=0,"",E8/D8) | H8: =IF(E8=0,"",F8/E8) | I8: =C8*H8 | J8: =IFERROR(XLOOKUP(A8,'DATA Census'!$A$2:$A$20,'DATA Census'!$C$2:$C$20),"") | K8: =I8*J8
A9: 31-33 | B9: Manufacturing | C9: =IFERROR(XLOOKUP(A9,'DATA QCEW'!$A$2:$A$20,'DATA QCEW'!$C$2:$C$20)/1000000000,"") | D9: =SUMIF('DATA OEWS'!$A$2:$A$13458,A9,'DATA OEWS'!$G$2:$G$13458)/1000000000 | E9: =SUMIF('DATA OEWS'!$A$2:$A$13458,A9,'DATA OEWS'!$I$2:$I$13458)/1000000000 | F9: =SUMIF('DATA OEWS'!$A$2:$A$13458,A9,'DATA OEWS'!$J$2:$J$13458)/1000000000 | G9: =IF(D9=0,"",E9/D9) | H9: =IF(E9=0,"",F9/E9) | I9: =C9*H9 | J9: =IFERROR(XLOOKUP(A9,'DATA Census'!$A$2:$A$20,'DATA Census'!$C$2:$C$20),"") | K9: =I9*J9
A10: 42 | B10: Wholesale trade | C10: =IFERROR(XLOOKUP(A10,'DATA QCEW'!$A$2:$A$20,'DATA QCEW'!$C$2:$C$20)/1000000000,"") | D10: =SUMIF('DATA OEWS'!$A$2:$A$13458,A10,'DATA OEWS'!$G$2:$G$13458)/1000000000 | E10: =SUMIF('DATA OEWS'!$A$2:$A$13458,A10,'DATA OEWS'!$I$2:$I$13458)/1000000000 | F10: =SUMIF('DATA OEWS'!$A$2:$A$13458,A10,'DATA OEWS'!$J$2:$J$13458)/1000000000 | G10: =IF(D10=0,"",E10/D10) | H10: =IF(E10=0,"",F10/E10) | I10: =C10*H10 | J10: =IFERROR(XLOOKUP(A10,'DATA Census'!$A$2:$A$20,'DATA Census'!$C$2:$C$20),"") | K10: =I10*J10
A11: 44-45 | B11: Retail trade | C11: =IFERROR(XLOOKUP(A11,'DATA QCEW'!$A$2:$A$20,'DATA QCEW'!$C$2:$C$20)/1000000000,"") | D11: =SUMIF('DATA OEWS'!$A$2:$A$13458,A11,'DATA OEWS'!$G$2:$G$13458)/1000000000 | E11: =SUMIF('DATA OEWS'!$A$2:$A$13458,A11,'DATA OEWS'!$I$2:$I$13458)/1000000000 | F11: =SUMIF('DATA OEWS'!$A$2:$A$13458,A11,'DATA OEWS'!$J$2:$J$13458)/1000000000 | G11: =IF(D11=0,"",E11/D11) | H11: =IF(E11=0,"",F11/E11) | I11: =C11*H11 | J11: =IFERROR(XLOOKUP(A11,'DATA Census'!$A$2:$A$20,'DATA Census'!$C$2:$C$20),"") | K11: =I11*J11
A12: 48-49 | B12: Transportation and warehousing | C12: =IFERROR(XLOOKUP(A12,'DATA QCEW'!$A$2:$A$20,'DATA QCEW'!$C$2:$C$20)/1000000000,"") | D12: =SUMIF('DATA OEWS'!$A$2:$A$13458,A12,'DATA OEWS'!$G$2:$G$13458)/1000000000 | E12: =SUMIF('DATA OEWS'!$A$2:$A$13458,A12,'DATA OEWS'!$I$2:$I$13458)/1000000000 | F12: =SUMIF('DATA OEWS'!$A$2:$A$13458,A12,'DATA OEWS'!$J$2:$J$13458)/1000000000 | G12: =IF(D12=0,"",E12/D12) | H12: =IF(E12=0,"",F12/E12) | I12: =C12*H12 | J12: =IFERROR(XLOOKUP(A12,'DATA Census'!$A$2:$A$20,'DATA Census'!$C$2:$C$20),"") | K12: =I12*J12
A13: 51 | B13: Information | C13: =IFERROR(XLOOKUP(A13,'DATA QCEW'!$A$2:$A$20,'DATA QCEW'!$C$2:$C$20)/1000000000,"") | D13: =SUMIF('DATA OEWS'!$A$2:$A$13458,A13,'DATA OEWS'!$G$2:$G$13458)/1000000000 | E13: =SUMIF('DATA OEWS'!$A$2:$A$13458,A13,'DATA OEWS'!$I$2:$I$13458)/1000000000 | F13: =SUMIF('DATA OEWS'!$A$2:$A$13458,A13,'DATA OEWS'!$J$2:$J$13458)/1000000000 | G13: =IF(D13=0,"",E13/D13) | H13: =IF(E13=0,"",F13/E13) | I13: =C13*H13 | J13: =IFERROR(XLOOKUP(A13,'DATA Census'!$A$2:$A$20,'DATA Census'!$C$2:$C$20),"") | K13: =I13*J13
A14: 52 | B14: Finance and insurance | C14: =IFERROR(XLOOKUP(A14,'DATA QCEW'!$A$2:$A$20,'DATA QCEW'!$C$2:$C$20)/1000000000,"") | D14: =SUMIF('DATA OEWS'!$A$2:$A$13458,A14,'DATA OEWS'!$G$2:$G$13458)/1000000000 | E14: =SUMIF('DATA OEWS'!$A$2:$A$13458,A14,'DATA OEWS'!$I$2:$I$13458)/1000000000 | F14: =SUMIF('DATA OEWS'!$A$2:$A$13458,A14,'DATA OEWS'!$J$2:$J$13458)/1000000000 | G14: =IF(D14=0,"",E14/D14) | H14: =IF(E14=0,"",F14/E14) | I14: =C14*H14 | J14: =IFERROR(XLOOKUP(A14,'DATA Census'!$A$2:$A$20,'DATA Census'!$C$2:$C$20),"") | K14: =I14*J14
A15: 53 | B15: Real estate and rental and leasing | C15: =IFERROR(XLOOKUP(A15,'DATA QCEW'!$A$2:$A$20,'DATA QCEW'!$C$2:$C$20)/1000000000,"") | D15: =SUMIF('DATA OEWS'!$A$2:$A$13458,A15,'DATA OEWS'!$G$2:$G$13458)/1000000000 | E15: =SUMIF('DATA OEWS'!$A$2:$A$13458,A15,'DATA OEWS'!$I$2:$I$13458)/1000000000 | F15: =SUMIF('DATA OEWS'!$A$2:$A$13458,A15,'DATA OEWS'!$J$2:$J$13458)/1000000000 | G15: =IF(D15=0,"",E15/D15) | H15: =IF(E15=0,"",F15/E15) | I15: =C15*H15 | J15: =IFERROR(XLOOKUP(A15,'DATA Census'!$A$2:$A$20,'DATA Census'!$C$2:$C$20),"") | K15: =I15*J15
A16: 54 | B16: Professional, scientific, and technical services | C16: =IFERROR(XLOOKUP(A16,'DATA QCEW'!$A$2:$A$20,'DATA QCEW'!$C$2:$C$20)/1000000000,"") | D16: =SUMIF('DATA OEWS'!$A$2:$A$13458,A16,'DATA OEWS'!$G$2:$G$13458)/1000000000 | E16: =SUMIF('DATA OEWS'!$A$2:$A$13458,A16,'DATA OEWS'!$I$2:$I$13458)/1000000000 | F16: =SUMIF('DATA OEWS'!$A$2:$A$13458,A16,'DATA OEWS'!$J$2:$J$13458)/1000000000 | G16: =IF(D16=0,"",E16/D16) | H16: =IF(E16=0,"",F16/E16) | I16: =C16*H16 | J16: =IFERROR(XLOOKUP(A16,'DATA Census'!$A$2:$A$20,'DATA Census'!$C$2:$C$20),"") | K16: =I16*J16
... A23: 81 | B23: Other services (except public administration) | C23: =IFERROR(XLOOKUP(A23,'DATA QCEW'!$A$2:$A$20,'DATA QCEW'!$C$2:$C$20)/1000000000,"") | D23: =SUMIF('DATA OEWS'!$A$2:$A$13458,A23,'DATA OEWS'!$G$2:$G$13458)/1000000000 | E23: =SUMIF('DATA OEWS'!$A$2:$A$13458,A23,'DATA OEWS'!$I$2:$I$13458)/1000000000 | F23: =SUMIF('DATA OEWS'!$A$2:$A$13458,A23,'DATA OEWS'!$J$2:$J$13458)/1000000000 | G23: =IF(D23=0,"",E23/D23) | H23: =IF(E23=0,"",F23/E23) | I23: =C23*H23 | J23: =IFERROR(XLOOKUP(A23,'DATA Census'!$A$2:$A$20,'DATA Census'!$C$2:$C$20),"") | K23: =I23*J23
A25: TOTAL | B25: 19 private industries (excluding NAICS 99 unclassified) | C25: =SUM(C5:C23) | D25: =SUM(D5:D23) | E25: =SUM(E5:E23) | F25: =SUM(F5:F23) | G25: =IF(D25=0,"",E25/D25) | H25: =IF(E25=0,"",F25/E25) | I25: =SUM(I5:I23) | K25: =SUM(K5:K23)
A27: CHECK | B27: Value ($bn) | C27: Explanation
A28: US QCEW private wages | B28: 10532.191 | C28: All industries including NAICS 99
A29: Unclassified NAICS 99 | B29: 16.545878 | C29: Excluded from the 19-sector exposed wage calculation
A30: Reconciliation (should equal zero) | B30: =B28-C25-B29
A32: IMPORTANT: BTOS firm-use percentage is NOT the share of workers using AI. Column K is a scenario proxy, not measured wage savings.
A33: Ownership caveat: OEWS 48-49, 71 and 72 occupational weights contain mixed ownership. Industry QCEW payroll remains private only.

Sheet Five-Year Projection
A1: FIVE-YEAR PROJECTION | AI-EXPOSED WAGE POOL (2025–2030)
A2: BLS 2025–2035 job growth | projected nominal wages | Wharton exposure | Census 2026 firm-level AI adoption + editable annual growth
A3: Gross exposure is NOT wages saved. Adoption-adjusted exposure is a scenario proxy, NOT realized AI economic benefit.
A5: U.S. PRIVATE SECTORS ($bn unless indicated) | B5: 2025 | C5: 2026 | D5: 2027 | E5: 2028 | F5: 2029 | G5: 2030
A6: Industry wages ($bn) | B6: =SUMIF($C$17:$C$130,B$5,$F$17:$F$130) -> 10515.646 | C6: =SUMIF($C$17:$C$130,C$5,$F$17:$F$130) -> 10877.917 | D6: =SUMIF($C$17:$C$130,D$5,$F$17:$F$130) -> 11252.782 | E6: =SUMIF($C$17:$C$130,E$5,$F$17:$F$130) -> 11640.684 | F6: =SUMIF($C$17:$C$130,F$5,$F$17:$F$130) -> 12042.078 | G6: =SUMIF($C$17:$C$130,G$5,$F$17:$F$130) -> 12457.439
A7: Gross AI-exposed wage pool ($bn) | B7: =SUMIF($C$17:$C$130,B$5,$J$17:$J$130) -> 4435.9142 | C7: =SUMIF($C$17:$C$130,C$5,$J$17:$J$130) -> 4588.4232 | D7: =SUMIF($C$17:$C$130,D$5,$J$17:$J$130) -> 4746.2206 | E7: =SUMIF($C$17:$C$130,E$5,$J$17:$J$130) -> 4909.4915 | F7: =SUMIF($C$17:$C$130,F$5,$J$17:$J$130) -> 5078.4273 | G7: =SUMIF($C$17:$C$130,G$5,$J$17:$J$130) -> 5253.2262
A8: Firm-use-adjusted wage pool ($bn) | B8: =IF(B$5=2025,"",SUMIF($C$17:$C$130,B$5,$L$17:$L$130)) | C8: =IF(C$5=2025,"",SUMIF($C$17:$C$130,C$5,$L$17:$L$130)) -> 1357.2013 | D8: =IF(D$5=2025,"",SUMIF($C$17:$C$130,D$5,$L$17:$L$130)) -> 1641.8751 | E8: =IF(E$5=2025,"",SUMIF($C$17:$C$130,E$5,$L$17:$L$130)) -> 1944.5421 | F8: =IF(F$5=2025,"",SUMIF($C$17:$C$130,F$5,$L$17:$L$130)) -> 2266.1112 | G8: =IF(G$5=2025,"",SUMIF($C$17:$C$130,G$5,$L$17:$L$130)) -> 2607.5329
A9: Firm-use proxy / gross exposure | B9: =IF(B$5=2025,"",B8/B7) | C9: =IF(C$5=2025,"",C8/C7) -> 0.29578817 | D9: =IF(D$5=2025,"",D8/D7) -> 0.34593315 | E9: =IF(E$5=2025,"",E8/E7) -> 0.3960781 | F9: =IF(F$5=2025,"",F8/F7) -> 0.44622303 | G9: =IF(G$5=2025,"",G8/G7) -> 0.49636791
A10: Gross exposed vs. 2025 | B10: =B7/$B$7-1 -> 0 | C10: =C7/$B$7-1 -> 0.034380507 | D10: =D7/$B$7-1 -> 0.069953204 | E10: =E7/$B$7-1 -> 0.10675979 | F10: =F7/$B$7-1 -> 0.14484343 | G10: =G7/$B$7-1 -> 0.18424883
A12: 2025 = measured wage base; 2026–2030 = modeled forward scenario. All nominal dollars; no discounting or AI capture rate.
A13: How to edit: change Projection Assumptions!C5:C7 globally, or per-industry C13:E31; job growth always comes from DATA BLS Projections.
A15: INDUSTRY × YEAR DETAIL | ONE ROW PER YEAR; FORMULAS COPY DOWN
A16: NAICS | B16: Industry | C16: Year | D16: BLS Jobs CAGR | E16: Wage / Worker CAGR | F16: Wage Bill ($bn) | G16: 2025 AI Task Exposure | H16: Annual Exposure Δ (pp) | I16: Projected Task Exposure | J16: Gross Exposed ($bn) | K16: AI-Using Firms | L16: Use-Adjusted Proxy ($bn)
A17: 11 | B17: Agriculture, forestry, fishing and hunting | C17: 2025 | D17: =IFERROR(XLOOKUP(A17,'DATA BLS Projections'!$A$5:$A$23,'DATA BLS Projections'!$E$5:$E$23),"") -> 0.001474046 | E17: =IFERROR(XLOOKUP(A17,'Projection Assumptions'!$A$13:$A$31,'Projection Assumptions'!$C$13:$C$31),"") -> 0.03 | F17: =IFERROR(XLOOKUP(A17,'01 Industry Model'!$A$5:$A$23,'01 Industry Model'!$C$5:$C$23),"") -> 60.088225 | G17: =IFERROR(XLOOKUP(A17,'01 Industry Model'!$A$5:$A$23,'01 Industry Model'!$H$5:$H$23),"") -> 0.18131399 | H17: =IFERROR(XLOOKUP(A17,'Projection Assumptions'!$A$13:$A$31,'Projection Assumptions'!$E$13:$E$31),"") -> 0 | I17: =MIN(1,MAX(0,G17+(C17-2025)*H17)) -> 0.18131399 | J17: =F17*I17 -> 10.894836 | K17: =IF(C17=2025,"",0) | L17: =IF(K17="","",J17*K17)
A18: 11 | B18: Agriculture, forestry, fishing and hunting | C18: 2026 | D18: =IFERROR(XLOOKUP(A18,'DATA BLS Projections'!$A$5:$A$23,'DATA BLS Projections'!$E$5:$E$23),"") -> 0.001474046 | E18: =IFERROR(XLOOKUP(A18,'Projection Assumptions'!$A$13:$A$31,'Projection Assumptions'!$C$13:$C$31),"") -> 0.03 | F18: =F17*(1+D18)*(1+E18) -> 61.982102 | G18: =IFERROR(XLOOKUP(A18,'01 Industry Model'!$A$5:$A$23,'01 Industry Model'!$H$5:$H$23),"") -> 0.18131399 | H18: =IFERROR(XLOOKUP(A18,'Projection Assumptions'!$A$13:$A$31,'Projection Assumptions'!$E$13:$E$31),"") -> 0 | I18: =MIN(1,MAX(0,G18+(C18-2025)*H18)) -> 0.18131399 | J18: =F18*I18 -> 11.238222 | K18: =IFERROR(XLOOKUP(A18,'DATA Census'!$A$2:$A$20,'DATA Census'!$C$2:$C$20),"") -> 0.095 | L18: =IF(K18="","",J18*K18) -> 1.0676311
A19: 11 | B19: Agriculture, forestry, fishing and hunting | C19: 2027 | D19: =IFERROR(XLOOKUP(A19,'DATA BLS Projections'!$A$5:$A$23,'DATA BLS Projections'!$E$5:$E$23),"") -> 0.001474046 | E19: =IFERROR(XLOOKUP(A19,'Projection Assumptions'!$A$13:$A$31,'Projection Assumptions'!$C$13:$C$31),"") -> 0.03 | F19: =F18*(1+D19)*(1+E19) -> 63.93567 | G19: =IFERROR(XLOOKUP(A19,'01 Industry Model'!$A$5:$A$23,'01 Industry Model'!$H$5:$H$23),"") -> 0.18131399 | H19: =IFERROR(XLOOKUP(A19,'Projection Assumptions'!$A$13:$A$31,'Projection Assumptions'!$E$13:$E$31),"") -> 0 | I19: =MIN(1,MAX(0,G19+(C19-2025)*H19)) -> 0.18131399 | J19: =F19*I19 -> 11.592431 | K19: =MIN(1,K18+XLOOKUP(A19,'Projection Assumptions'!$A$13:$A$31,'Projection Assumptions'!$D$13:$D$31)) -> 0.145 | L19: =IF(K19="","",J19*K19) -> 1.6809026
A20: 11 | B20: Agriculture, forestry, fishing and hunting | C20: 2028 | D20: =IFERROR(XLOOKUP(A20,'DATA BLS Projections'!$A$5:$A$23,'DATA BLS Projections'!$E$5:$E$23),"") -> 0.001474046 | E20: =IFERROR(XLOOKUP(A20,'Projection Assumptions'!$A$13:$A$31,'Projection Assumptions'!$C$13:$C$31),"") -> 0.03 | F20: =F19*(1+D20)*(1+E20) -> 65.950812 | G20: =IFERROR(XLOOKUP(A20,'01 Industry Model'!$A$5:$A$23,'01 Industry Model'!$H$5:$H$23),"") -> 0.18131399 | H20: =IFERROR(XLOOKUP(A20,'Projection Assumptions'!$A$13:$A$31,'Projection Assumptions'!$E$13:$E$31),"") -> 0 | I20: =MIN(1,MAX(0,G20+(C20-2025)*H20)) -> 0.18131399 | J20: =F20*I20 -> 11.957805 | K20: =MIN(1,K19+XLOOKUP(A20,'Projection Assumptions'!$A$13:$A$31,'Projection Assumptions'!$D$13:$D$31)) -> 0.195 | L20: =IF(K20="","",J20*K20) -> 2.3317719
A21: 11 | B21: Agriculture, forestry, fishing and hunting | C21: 2029 | D21: =IFERROR(XLOOKUP(A21,'DATA BLS Projections'!$A$5:$A$23,'DATA BLS Projections'!$E$5:$E$23),"") -> 0.001474046 | E21: =IFERROR(XLOOKUP(A21,'Projection Assumptions'!$A$13:$A$31,'Projection Assumptions'!$C$13:$C$31),"") -> 0.03 | F21: =F20*(1+D21)*(1+E21) -> 68.029467 | G21: =IFERROR(XLOOKUP(A21,'01 Industry Model'!$A$5:$A$23,'01 Industry Model'!$H$5:$H$23),"") -> 0.18131399 | H21: =IFERROR(XLOOKUP(A21,'Projection Assumptions'!$A$13:$A$31,'Projection Assumptions'!$E$13:$E$31),"") -> 0 | I21: =MIN(1,MAX(0,G21+(C21-2025)*H21)) -> 0.18131399 | J21: =F21*I21 -> 12.334694 | K21: =MIN(1,K20+XLOOKUP(A21,'Projection Assumptions'!$A$13:$A$31,'Projection Assumptions'!$D$13:$D$31)) -> 0.245 | L21: =IF(K21="","",J21*K21) -> 3.022
A22: 11 | B22: Agriculture, forestry, fishing and hunting | C22: 2030 | D22: =IFERROR(XLOOKUP(A22,'DATA BLS Projections'!$A$5:$A$23,'DATA BLS Projections'!$E$5:$E$23),"") -> 0.001474046 | E22: =IFERROR(XLOOKUP(A22,'Projection Assumptions'!$A$13:$A$31,'Projection Assumptions'!$C$13:$C$31),"") -> 0.03 | F22: =F21*(1+D22)*(1+E22) -> 70.173638 | G22: =IFERROR(XLOOKUP(A22,'01 Industry Model'!$A$5:$A$23,'01 Industry Model'!$H$5:$H$23),"") -> 0.18131399 | H22: =IFERROR(XLOOKUP(A22,'Projection Assumptions'!$A$13:$A$31,'Projection Assumptions'!$E$13:$E$31),"") -> 0 | I22: =MIN(1,MAX(0,G22+(C22-2025)*H22)) -> 0.18131399 | J22: =F22*I22 -> 12.723462 | K22: =MIN(1,K21+XLOOKUP(A22,'Projection Assumptions'!$A$13:$A$31,'Projection Assumptions'!$D$13:$D$31)) -> 0.295 | L22: =IF(K22="","",J22*K22) -> 3.7534214
A23: 21 | B23: Mining, quarrying, and oil and gas extraction | C23: 2025 | D23: =IFERROR(XLOOKUP(A23,'DATA BLS Projections'!$A$5:$A$23,'DATA BLS Projections'!$E$5:$E$23),"") -> 0.00066063067 | E23: =IFERROR(XLOOKUP(A23,'Projection Assumptions'!$A$13:$A$31,'Projection Assumptions'!$C$13:$C$31),"") -> 0.03 | F23: =IFERROR(XLOOKUP(A23,'01 Industry Model'!$A$5:$A$23,'01 Industry Model'!$C$5:$C$23),"") -> 76.216722 | G23: =IFERROR(XLOOKUP(A23,'01 Industry Model'!$A$5:$A$23,'01 Industry Model'!$H$5:$H$23),"") -> 0.29026433 | H23: =IFERROR(XLOOKUP(A23,'Projection Assumptions'!$A$13:$A$31,'Projection Assumptions'!$E$13:$E$31),"") -> 0 | I23: =MIN(1,MAX(0,G23+(C23-2025)*H23)) -> 0.29026433 | J23: =F23*I23 -> 22.122996 | K23: =IF(C23=2025,"",0) | L23: =IF(K23="","",J23*K23)
A24: 21 | B24: Mining, quarrying, and oil and gas extraction | C24: 2026 | D24: =IFERROR(XLOOKUP(A24,'DATA BLS Projections'!$A$5:$A$23,'DATA BLS Projections'!$E$5:$E$23),"") -> 0.00066063067 | E24: =IFERROR(XLOOKUP(A24,'Projection Assumptions'!$A$13:$A$31,'Projection Assumptions'!$C$13:$C$31),"") -> 0.03 | F24: =F23*(1+D24)*(1+E24) -> 78.555085 | G24: =IFERROR(XLOOKUP(A24,'01 Industry Model'!$A$5:$A$23,'01 Industry Model'!$H$5:$H$23),"") -> 0.29026433 | H24: =IFERROR(XLOOKUP(A24,'Projection Assumptions'!$A$13:$A$31,'Projection Assumptions'!$E$13:$E$31),"") -> 0 | I24: =MIN(1,MAX(0,G24+(C24-2025)*H24)) -> 0.29026433 | J24: =F24*I24 -> 22.801739 | K24: =IFERROR(XLOOKUP(A24,'DATA Census'!$A$2:$A$20,'DATA Census'!$C$2:$C$20),"") -> 0.13 | L24: =IF(K24="","",J24*K24) -> 2.9642261
A25: 21 | B25: Mining, quarrying, and oil and gas extraction | C25: 2027 | D25: =IFERROR(XLOOKUP(A25,'DATA BLS Projections'!$A$5:$A$23,'DATA BLS Projections'!$E$5:$E$23),"") -> 0.00066063067 | E25: =IFERROR(XLOOKUP(A25,'Projection Assumptions'!$A$13:$A$31,'Projection Assumptions'!$C$13:$C$31),"") -> 0.03 | F25: =F24*(1+D25)*(1+E25) -> 80.965191 | G25: =IFERROR(XLOOKUP(A25,'01 Industry Model'!$A$5:$A$23,'01 Industry Model'!$H$5:$H$23),"") -> 0.29026433 | H25: =IFERROR(XLOOKUP(A25,'Projection Assumptions'!$A$13:$A$31,'Projection Assumptions'!$E$13:$E$31),"") -> 0 | I25: =MIN(1,MAX(0,G25+(C25-2025)*H25)) -> 0.29026433 | J25: =F25*I25 -> 23.501307 | K25: =MIN(1,K24+XLOOKUP(A25,'Projection Assumptions'!$A$13:$A$31,'Projection Assumptions'!$D$13:$D$31)) -> 0.18 | L25: =IF(K25="","",J25*K25) -> 4.2302352
A26: 21 | B26: Mining, quarrying, and oil and gas extraction | C26: 2028 | D26: =IFERROR(XLOOKUP(A26,'DATA BLS Projections'!$A$5:$A$23,'DATA BLS Projections'!$E$5:$E$23),"") -> 0.00066063067 | E26: =IFERROR(XLOOKUP(A26,'Projection Assumptions'!$A$13:$A$31,'Projection Assumptions'!$C$13:$C$31),"") -> 0.03 | F26: =F25*(1+D26)*(1+E26) -> 83.449239 | G26: =IFERROR(XLOOKUP(A26,'01 Industry Model'!$A$5:$A$23,'01 Industry Model'!$H$5:$H$23),"") -> 0.29026433 | H26: =IFERROR(XLOOKUP(A26,'Projection Assumptions'!$A$13:$A$31,'Projection Assumptions'!$E$13:$E$31),"") -> 0 | I26: =MIN(1,MAX(0,G26+(C26-2025)*H26)) -> 0.29026433 | J26: =F26*I26 -> 24.222338 | K26: =MIN(1,K25+XLOOKUP(A26,'Projection Assumptions'!$A$13:$A$31,'Projection Assumptions'!$D$13:$D$31)) -> 0.23 | L26: =IF(K26="","",J26*K26) -> 5.5711376
A27: 21 | B27: Mining, quarrying, and oil and gas extraction | C27: 2029 | D27: =IFERROR(XLOOKUP(A27,'DATA BLS Projections'!$A$5:$A$23,'DATA BLS Projections'!$E$5:$E$23),"") -> 0.00066063067 | E27: =IFERROR(XLOOKUP(A27,'Projection Assumptions'!$A$13:$A$31,'Projection Assumptions'!$C$13:$C$31),"") -> 0.03 | F27: =F26*(1+D27)*(1+E27) -> 86.009499 | G27: =IFERROR(XLOOKUP(A27,'01 Industry Model'!$A$5:$A$23,'01 Industry Model'!$H$5:$H$23),"") -> 0.29026433 | H27: =IFERROR(XLOOKUP(A27,'Projection Assumptions'!$A$13:$A$31,'Projection Assumptions'!$E$13:$E$31),"") -> 0 | I27: =MIN(1,MAX(0,G27+(C27-2025)*H27)) -> 0.29026433 | J27: =F27*I27 -> 24.96549 | K27: =MIN(1,K26+XLOOKUP(A27,'Projection Assumptions'!$A$13:$A$31,'Projection Assumptions'!$D$13:$D$31)) -> 0.28 | L27: =IF(K27="","",J27*K27) -> 6.9903371
A28: 21 | B28: Mining, quarrying, and oil and gas extraction | C28: 2030 | D28: =IFERROR(XLOOKUP(A28,'DATA BLS Projections'!$A$5:$A$23,'DATA BLS Projections'!$E$5:$E$23),"") -> 0.00066063067 | E28: =IFERROR(XLOOKUP(A28,'Projection Assumptions'!$A$13:$A$31,'Projection Assumptions'!$C$13:$C$31),"") -> 0.03 | F28: =F27*(1+D28)*(1+E28) -> 88.648309 | G28: =IFERROR(XLOOKUP(A28,'01 Industry Model'!$A$5:$A$23,'01 Industry Model'!$H$5:$H$23),"") -> 0.29026433 | H28: =IFERROR(XLOOKUP(A28,'Projection Assumptions'!$A$13:$A$31,'Projection Assumptions'!$E$13:$E$31),"") -> 0 | I28: =MIN(1,MAX(0,G28+(C28-2025)*H28)) -> 0.29026433 | J28: =F28*I28 -> 25.731442 | K28: =MIN(1,K27+XLOOKUP(A28,'Projection Assumptions'!$A$13:$A$31,'Projection Assumptions'!$D$13:$D$31)) -> 0.33 | L28: =IF(K28="","",J28*K28) -> 8.4913759
A29: 22 | B29: Utilities | C29: 2025 | D29: =IFERROR(XLOOKUP(A29,'DATA BLS Projections'!$A$5:$A$23,'DATA BLS Projections'!$E$5:$E$23),"") -> 0.0093733937 | E29: =IFERROR(XLOOKUP(A29,'Projection Assumptions'!$A$13:$A$31,'Projection Assumptions'!$C$13:$C$31),"") -> 0.03 | F29: =IFERROR(XLOOKUP(A29,'01 Industry Model'!$A$5:$A$23,'01 Industry Model'!$C$5:$C$23),"") -> 85.024862 | G29: =IFERROR(XLOOKUP(A29,'01 Industry Model'!$A$5:$A$23,'01 Industry Model'!$H$5:$H$23),"") -> 0.3664496 | H29: =IFERROR(XLOOKUP(A29,'Projection Assumptions'!$A$13:$A$31,'Projection Assumptions'!$E$13:$E$31),"") -> 0 | I29: =MIN(1,MAX(0,G29+(C29-2025)*H29)) -> 0.3664496 | J29: =F29*I29 -> 31.157326 | K29: =IF(C29=2025,"",0) | L29: =IF(K29="","",J29*K29)
A30: 22 | B30: Utilities | C30: 2026 | D30: =IFERROR(XLOOKUP(A30,'DATA BLS Projections'!$A$5:$A$23,'DATA BLS Projections'!$E$5:$E$23),"") -> 0.0093733937 | E30: =IFERROR(XLOOKUP(A30,'Projection Assumptions'!$A$13:$A$31,'Projection Assumptions'!$C$13:$C$31),"") -> 0.03 | F30: =F29*(1+D30)*(1+E30) -> 88.396488 | G30: =IFERROR(XLOOKUP(A30,'01 Industry Model'!$A$5:$A$23,'01 Industry Model'!$H$5:$H$23),"") -> 0.3664496 | H30: =IFERROR(XLOOKUP(A30,'Projection Assumptions'!$A$13:$A$31,'Projection Assumptions'!$E$13:$E$31),"") -> 0 | I30: =MIN(1,MAX(0,G30+(C30-2025)*H30)) -> 0.3664496 | J30: =F30*I30 -> 32.392857 | K30: =IFERROR(XLOOKUP(A30,'DATA Census'!$A$2:$A$20,'DATA Census'!$C$2:$C$20),"") -> 0.167 | L30: =IF(K30="","",J30*K30) -> 5.4096072
A31: 22 | B31: Utilities | C31: 2027 | D31: =IFERROR(XLOOKUP(A31,'DATA BLS Projections'!$A$5:$A$23,'DATA BLS Projections'!$E$5:$E$23),"") -> 0.0093733937 | E31: =IFERROR(XLOOKUP(A31,'Projection Assumptions'!$A$13:$A$31,'Projection Assumptions'!$C$13:$C$31),"") -> 0.03 | F31: =F30*(1+D31)*(1+E31) -> 91.901815 | G31: =IFERROR(XLOOKUP(A31,'01 Industry Model'!$A$5:$A$23,'01 Industry Model'!$H$5:$H$23),"") -> 0.3664496 | H31: =IFERROR(XLOOKUP(A31,'Projection Assumptions'!$A$13:$A$31,'Projection Assumptions'!$E$13:$E$31),"") -> 0 | I31: =MIN(1,MAX(0,G31+(C31-2025)*H31)) -> 0.3664496 | J31: =F31*I31 -> 33.677383 | K31: =MIN(1,K30+XLOOKUP(A31,'Projection Assumptions'!$A$13:$A$31,'Projection Assumptions'!$D$13:$D$31)) -> 0.217 | L31: =IF(K31="","",J31*K31) -> 7.3079921
A32: 22 | B32: Utilities | C32: 2028 | D32: =IFERROR(XLOOKUP(A32,'DATA BLS Projections'!$A$5:$A$23,'DATA BLS Projections'!$E$5:$E$23),"") -> 0.0093733937 | E32: =IFERROR(XLOOKUP(A32,'Projection Assumptions'!$A$13:$A$31,'Projection Assumptions'!$C$13:$C$31),"") -> 0.03 | F32: =F31*(1+D32)*(1+E32) -> 95.546144 | G32: =IFERROR(XLOOKUP(A32,'01 Industry Model'!$A$5:$A$23,'01 Industry Model'!$H$5:$H$23),"") -> 0.3664496 | H32: =IFERROR(XLOOKUP(A32,'Projection Assumptions'!$A$13:$A$31,'Projection Assumptions'!$E$13:$E$31),"") -> 0 | I32: =MIN(1,MAX(0,G32+(C32-2025)*H32)) -> 0.3664496 | J32: =F32*I32 -> 35.012846 | K32: =MIN(1,K31+XLOOKUP(A32,'Projection Assumptions'!$A$13:$A$31,'Projection Assumptions'!$D$13:$D$31)) -> 0.267 | L32: =IF(K32="","",J32*K32) -> 9.3484299
A33: 22 | B33: Utilities | C33: 2029 | D33: =IFERROR(XLOOKUP(A33,'DATA BLS Projections'!$A$5:$A$23,'DATA BLS Projections'!$E$5:$E$23),"") -> 0.0093733937 | E33: =IFERROR(XLOOKUP(A33,'Projection Assumptions'!$A$13:$A$31,'Projection Assumptions'!$C$13:$C$31),"") -> 0.03 | F33: =F32*(1+D33)*(1+E33) -> 99.334988 | G33: =IFERROR(XLOOKUP(A33,'01 Industry Model'!$A$5:$A$23,'01 Industry Model'!$H$5:$H$23),"") -> 0.3664496 | H33: =IFERROR(XLOOKUP(A33,'Projection Assumptions'!$A$13:$A$31,'Projection Assumptions'!$E$13:$E$31),"") -> 0 | I33: =MIN(1,MAX(0,G33+(C33-2025)*H33)) -> 0.3664496 | J33: =F33*I33 -> 36.401266 | K33: =MIN(1,K32+XLOOKUP(A33,'Projection Assumptions'!$A$13:$A$31,'Projection Assumptions'!$D$13:$D$31)) -> 0.317 | L33: =IF(K33="","",J33*K33) -> 11.539201
A34: 22 | B34: Utilities | C34: 2030 | D34: =IFERROR(XLOOKUP(A34,'DATA BLS Projections'!$A$5:$A$23,'DATA BLS Projections'!$E$5:$E$23),"") -> 0.0093733937 | E34: =IFERROR(XLOOKUP(A34,'Projection Assumptions'!$A$13:$A$31,'Projection Assumptions'!$C$13:$C$31),"") -> 0.03 | F34: =F33*(1+D34)*(1+E34) -> 103.27408 | G34: =IFERROR(XLOOKUP(A34,'01 Industry Model'!$A$5:$A$23,'01 Industry Model'!$H$5:$H$23),"") -> 0.3664496 | H34: =IFERROR(XLOOKUP(A34,'Projection Assumptions'!$A$13:$A$31,'Projection Assumptions'!$E$13:$E$31),"") -> 0 | I34: =MIN(1,MAX(0,G34+(C34-2025)*H34)) -> 0.3664496 | J34: =F34*I34 -> 37.844744 | K34: =MIN(1,K33+XLOOKUP(A34,'Projection Assumptions'!$A$13:$A$31,'Projection Assumptions'!$D$13:$D$31)) -> 0.367 | L34: =IF(K34="","",J34*K34) -> 13.889021
A35: 23 | B35: Construction | C35: 2025 | D35: =IFERROR(XLOOKUP(A35,'DATA BLS Projections'!$A$5:$A$23,'DATA BLS Projections'!$E$5:$E$23),"") -> 0.0048604285 | E35: =IFERROR(XLOOKUP(A35,'Projection Assumptions'!$A$13:$A$31,'Projection Assumptions'!$C$13:$C$31),"") -> 0.03 | F35: =IFERROR(XLOOKUP(A35,'01 Industry Model'!$A$5:$A$23,'01 Industry Model'!$C$5:$C$23),"") -> 699.89625 | G35: =IFERROR(XLOOKUP(A35,'01 Industry Model'!$A$5:$A$23,'01 Industry Model'!$H$5:$H$23),"") -> 0.26597382 | H35: =IFERROR(XLOOKUP(A35,'Projection Assumptions'!$A$13:$A$31,'Projection Assumptions'!$E$13:$E$31),"") -> 0 | I35: =MIN(1,MAX(0,G35+(C35-2025)*H35)) -> 0.26597382 | J35: =F35*I35 -> 186.15408 | K35: =IF(C35=2025,"",0) | L35: =IF(K35="","",J35*K35)
A36: 23 | B36: Construction | C36: 2026 | D36: =IFERROR(XLOOKUP(A36,'DATA BLS Projections'!$A$5:$A$23,'DATA BLS Projections'!$E$5:$E$23),"") -> 0.0048604285 | E36: =IFERROR(XLOOKUP(A36,'Projection Assumptions'!$A$13:$A$31,'Projection Assumptions'!$C$13:$C$31),"") -> 0.03 | F36: =F35*(1+D36)*(1+E36) -> 724.39699 | G36: =IFERROR(XLOOKUP(A36,'01 Industry Model'!$A$5:$A$23,'01 Industry Model'!$H$5:$H$23),"") -> 0.26597382 | H36: =IFERROR(XLOOKUP(A36,'Projection Assumptions'!$A$13:$A$31,'Projection Assumptions'!$E$13:$E$31),"") -> 0 | I36: =MIN(1,MAX(0,G36+(C36-2025)*H36)) -> 0.26597382 | J36: =F36*I36 -> 192.67063 | K36: =IFERROR(XLOOKUP(A36,'DATA Census'!$A$2:$A$20,'DATA Census'!$C$2:$C$20),"") -> 0.172 | L36: =IF(K36="","",J36*K36) -> 33.139349
A37: 23 | B37: Construction | C37: 2027 | D37: =IFERROR(XLOOKUP(A37,'DATA BLS Projections'!$A$5:$A$23,'DATA BLS Projections'!$E$5:$E$23),"") -> 0.0048604285 | E37: =IFERROR(XLOOKUP(A37,'Projection Assumptions'!$A$13:$A$31,'Projection Assumptions'!$C$13:$C$31),"") -> 0.03 | F37: =F36*(1+D37)*(1+E37) -> 749.7554 | G37: =IFERROR(XLOOKUP(A37,'01 Industry Model'!$A$5:$A$23,'01 Industry Model'!$H$5:$H$23),"") -> 0.26597382 | H37: =IFERROR(XLOOKUP(A37,'Projection Assumptions'!$A$13:$A$31,'Projection Assumptions'!$E$13:$E$31),"") -> 0 | I37: =MIN(1,MAX(0,G37+(C37-2025)*H37)) -> 0.26597382 | J37: =F37*I37 -> 199.41531 | K37: =MIN(1,K36+XLOOKUP(A37,'Projection Assumptions'!$A$13:$A$31,'Projection Assumptions'!$D$13:$D$31)) -> 0.222 | L37: =IF(K37="","",J37*K37) -> 44.270198
A38: 23 | B38: Construction | C38: 2028 | D38: =IFERROR(XLOOKUP(A38,'DATA BLS Projections'!$A$5:$A$23,'DATA BLS Projections'!$E$5:$E$23),"") -> 0.0048604285 | E38: =IFERROR(XLOOKUP(A38,'Projection Assumptions'!$A$13:$A$31,'Projection Assumptions'!$C$13:$C$31),"") -> 0.03 | F38: =F37*(1+D38)*(1+E38) -> 776.00152 | G38: =IFERROR(XLOOKUP(A38,'01 Industry Model'!$A$5:$A$23,'01 Industry Model'!$H$5:$H$23),"") -> 0.26597382 | H38: =IFERROR(XLOOKUP(A38,'Projection Assumptions'!$A$13:$A$31,'Projection Assumptions'!$E$13:$E$31),"") -> 0 | I38: =MIN(1,MAX(0,G38+(C38-2025)*H38)) -> 0.26597382 | J38: =F38*I38 -> 206.39609 | K38: =MIN(1,K37+XLOOKUP(A38,'Projection Assumptions'!$A$13:$A$31,'Projection Assumptions'!$D$13:$D$31)) -> 0.272 | L38: =IF(K38="","",J38*K38) -> 56.139736
A39: 23 | B39: Construction | C39: 2029 | D39: =IFERROR(XLOOKUP(A39,'DATA BLS Projections'!$A$5:$A$23,'DATA BLS Projections'!$E$5:$E$23),"") -> 0.0048604285 | E39: =IFERROR(XLOOKUP(A39,'Projection Assumptions'!$A$13:$A$31,'Projection Assumptions'!$C$13:$C$31),"") -> 0.03 | F39: =F38*(1+D39)*(1+E39) -> 803.16642 | G39: =IFERROR(XLOOKUP(A39,'01 Industry Model'!$A$5:$A$23,'01 Industry Model'!$H$5:$H$23),"") -> 0.26597382 | H39: =IFERROR(XLOOKUP(A39,'Projection Assumptions'!$A$13:$A$31,'Projection Assumptions'!$E$13:$E$31),"") -> 0 | I39: =MIN(1,MAX(0,G39+(C39-2025)*H39)) -> 0.26597382 | J39: =F39*I39 -> 213.62124 | K39: =MIN(1,K38+XLOOKUP(A39,'Projection Assumptions'!$A$13:$A$31,'Projection Assumptions'!$D$13:$D$31)) -> 0.322 | L39: =IF(K39="","",J39*K39) -> 68.786039
A40: 23 | B40: Construction | C40: 2030 | D40: =IFERROR(XLOOKUP(A40,'DATA BLS Projections'!$A$5:$A$23,'DATA BLS Projections'!$E$5:$E$23),"") -> 0.0048604285 | E40: =IFERROR(XLOOKUP(A40,'Projection Assumptions'!$A$13:$A$31,'Projection Assumptions'!$C$13:$C$31),"") -> 0.03 | F40: =F39*(1+D40)*(1+E40) -> 831.28225 | G40: =IFERROR(XLOOKUP(A40,'01 Industry Model'!$A$5:$A$23,'01 Industry Model'!$H$5:$H$23),"") -> 0.26597382 | H40: =IFERROR(XLOOKUP(A40,'Projection Assumptions'!$A$13:$A$31,'Projection Assumptions'!$E$13:$E$31),"") -> 0 | I40: =MIN(1,MAX(0,G40+(C40-2025)*H40)) -> 0.26597382 | J40: =F40*I40 -> 221.09932 | K40: =MIN(1,K39+XLOOKUP(A40,'Projection Assumptions'!$A$13:$A$31,'Projection Assumptions'!$D$13:$D$31)) -> 0.372 | L40: =IF(K40="","",J40*K40) -> 82.248946
A41: 31-33 | B41: Manufacturing | C41: 2025 | D41: =IFERROR(XLOOKUP(A41,'DATA BLS Projections'!$A$5:$A$23,'DATA BLS Projections'!$E$5:$E$23),"") -> 0.00056923549 | E41: =IFERROR(XLOOKUP(A41,'Projection Assumptions'!$A$13:$A$31,'Projection Assumptions'!$C$13:$C$31),"") -> 0.03 | F41: =IFERROR(XLOOKUP(A41,'01 Industry Model'!$A$5:$A$23,'01 Industry Model'!$C$5:$C$23),"") -> 1125.5427 | G41: =IFERROR(XLOOKUP(A41,'01 Industry Model'!$A$5:$A$23,'01 Industry Model'!$H$5:$H$23),"") -> 0.33208008 | H41: =IFERROR(XLOOKUP(A41,'Projection Assumptions'!$A$13:$A$31,'Projection Assumptions'!$E$13:$E$31),"") -> 0 | I41: =MIN(1,MAX(0,G41+(C41-2025)*H41)) -> 0.33208008 | J41: =F41*I41 -> 373.7703 | K41: =IF(C41=2025,"",0) | L41: =IF(K41="","",J41*K41)
A42: 31-33 | B42: Manufacturing | C42: 2026 | D42: =IFERROR(XLOOKUP(A42,'DATA BLS Projections'!$A$5:$A$23,'DATA BLS Projections'!$E$5:$E$23),"") -> 0.00056923549 | E42: =IFERROR(XLOOKUP(A42,'Projection Assumptions'!$A$13:$A$31,'Projection Assumptions'!$C$13:$C$31),"") -> 0.03 | F42: =F41*(1+D42)*(1+E42) -> 1159.9689 | G42: =IFERROR(XLOOKUP(A42,'01 Industry Model'!$A$5:$A$23,'01 Industry Model'!$H$5:$H$23),"") -> 0.33208008 | H42: =IFERROR(XLOOKUP(A42,'Projection Assumptions'!$A$13:$A$31,'Projection Assumptions'!$E$13:$E$31),"") -> 0 | I42: =MIN(1,MAX(0,G42+(C42-2025)*H42)) -> 0.33208008 | J42: =F42*I42 -> 385.20255 | K42: =IFERROR(XLOOKUP(A42,'DATA Census'!$A$2:$A$20,'DATA Census'!$C$2:$C$20),"") -> 0.208 | L42: =IF(K42="","",J42*K42) -> 80.122131
A43: 31-33 | B43: Manufacturing | C43: 2027 | D43: =IFERROR(XLOOKUP(A43,'DATA BLS Projections'!$A$5:$A$23,'DATA BLS Projections'!$E$5:$E$23),"") -> 0.00056923549 | E43: =IFERROR(XLOOKUP(A43,'Projection Assumptions'!$A$13:$A$31,'Projection Assumptions'!$C$13:$C$31),"") -> 0.03 | F43: =F42*(1+D43)*(1+E43) -> 1195.448 | G43: =IFERROR(XLOOKUP(A43,'01 Industry Model'!$A$5:$A$23,'01 Industry Model'!$H$5:$H$23),"") -> 0.33208008 | H43: =IFERROR(XLOOKUP(A43,'Projection Assumptions'!$A$13:$A$31,'Projection Assumptions'!$E$13:$E$31),"") -> 0 | I43: =MIN(1,MAX(0,G43+(C43-2025)*H43)) -> 0.33208008 | J43: =F43*I43 -> 396.98448 | K43: =MIN(1,K42+XLOOKUP(A43,'Projection Assumptions'!$A$13:$A$31,'Projection Assumptions'!$D$13:$D$31)) -> 0.258 | L43: =IF(K43="","",J43*K43) -> 102.422
...

Sheet Projection Assumptions
A1: PROJECTION ASSUMPTIONS | USER-EDITABLE
A2: Blue = assumption/input. Yellow = global assumption. Industry-level cells initially link to globals but may be overwritten.
B5: Nominal wage growth per employee / year | C5: 0.03 | D5: Illustrative assumption, NOT an official BLS wage forecast
B6: AI-using firms: additional percentage points / year | C6: 0.05 | D6: Illustrative linear adoption assumption after 2026; cap = 100%
B7: AI task exposure: additional percentage points / year | C7: 0 | D7: Keep 2025 Wharton exposure fixed by default; scenario knob
A9: 2025 baseline: QCEW private wages + Wharton exposure | 2026 adoption reference: Census BTOS Q7 Yes
A10: 2026 firm adoption is a CROSS-SECTION observation; using it as annual-average is a simplifying scenario assumption.
A12: NAICS | B12: Industry | C12: Nominal wage CAGR | D12: Annual adoption change (pp) | E12: Annual exposure change (pp) | F12: Notes / edit instructions
A13: 11 | B13: Agriculture, forestry, fishing and hunting | C13: =$C$5 -> 0.03 | D13: =$C$6 -> 0.05 | E13: =$C$7 -> 0 | F13: Override C/D/E for this industry if desired; global defaults above otherwise
A14: 21 | B14: Mining, quarrying, and oil and gas extraction | C14: =$C$5 -> 0.03 | D14: =$C$6 -> 0.05 | E14: =$C$7 -> 0 | F14: Override C/D/E for this industry if desired; global defaults above otherwise
A15: 22 | B15: Utilities | C15: =$C$5 -> 0.03 | D15: =$C$6 -> 0.05 | E15: =$C$7 -> 0 | F15: Override C/D/E for this industry if desired; global defaults above otherwise
A16: 23 | B16: Construction | C16: =$C$5 -> 0.03 | D16: =$C$6 -> 0.05 | E16: =$C$7 -> 0 | F16: Override C/D/E for this industry if desired; global defaults above otherwise
A17: 31-33 | B17: Manufacturing | C17: =$C$5 -> 0.03 | D17: =$C$6 -> 0.05 | E17: =$C$7 -> 0 | F17: Override C/D/E for this industry if desired; global defaults above otherwise
A18: 42 | B18: Wholesale trade | C18: =$C$5 -> 0.03 | D18: =$C$6 -> 0.05 | E18: =$C$7 -> 0 | F18: Override C/D/E for this industry if desired; global defaults above otherwise
A19: 44-45 | B19: Retail trade | C19: =$C$5 -> 0.03 | D19: =$C$6 -> 0.05 | E19: =$C$7 -> 0 | F19: Override C/D/E for this industry if desired; global defaults above otherwise
A20: 48-49 | B20: Transportation and warehousing | C20: =$C$5 -> 0.03 | D20: =$C$6 -> 0.05 | E20: =$C$7 -> 0 | F20: Override C/D/E for this industry if desired; global defaults above otherwise
A21: 51 | B21: Information | C21: =$C$5 -> 0.03 | D21: =$C$6 -> 0.05 | E21: =$C$7 -> 0 | F21: Override C/D/E for this industry if desired; global defaults above otherwise
A22: 52 | B22: Finance and insurance | C22: =$C$5 -> 0.03 | D22: =$C$6 -> 0.05 | E22: =$C$7 -> 0 | F22: Override C/D/E for this industry if desired; global defaults above otherwise
A23: 53 | B23: Real estate and rental and leasing | C23: =$C$5 -> 0.03 | D23: =$C$6 -> 0.05 | E23: =$C$7 -> 0 | F23: Override C/D/E for this industry if desired; global defaults above otherwise
A24: 54 | B24: Professional, scientific, and technical services | C24: =$C$5 -> 0.03 | D24: =$C$6 -> 0.05 | E24: =$C$7 -> 0 | F24: Override C/D/E for this industry if desired; global defaults above otherwise
... A31: 81 | B31: Other services (except public administration) | C31: =$C$5 -> 0.03 | D31: =$C$6 -> 0.05 | E31: =$C$7 -> 0 | F31: Override C/D/E for this industry if desired; global defaults above otherwise
A33: Important: Firm-level AI Use × gross exposed wages is ONLY a sensitivity proxy, not measured labor savings.
A34: BLS employment source: https://www.bls.gov/emp/tables/employment-by-major-industry-sector.htm
A35: Census AI Use source: https://www.census.gov/hfp/btos/data_downloads

Sheet DATA BLS Projections
A1: DATA BLS EMPLOYMENT PROJECTIONS | 2025-2035
A2: BLS Employment Projections Table 2.1 (updated September 8, 2026) | 2025 & 2035 employees in thousands; compound annual growth for 2026-2030
A3: Official table: | B3: https://www.bls.gov/emp/tables/employment-by-major-industry-sector.htm
A4: NAICS (model) | B4: BLS Industry Sector | C4: 2025 Employment (000s) | D4: 2035 Employment (000s) | E4: Employment CAGR 2025–35 | F4: Coverage / NAICS mapping note | G4: Official Download / Source
A5: 11 | B5: Agriculture, forestry, fishing and hunting | C5: 1462.4 | D5: 1484.1 | E5: =(D5/C5)^(1/(2035-2025))-1 -> 0.001474046 | F5: Corresponding private-sector NAICS major sector; rounded BLS 2025 & 2035 employment | G5: https://www.bls.gov/emp/tables/employment-by-major-industry-sector.htm
A6: 21 | B6: Mining, quarrying, and oil and gas extraction | C6: 573.5 | D6: 577.3 | E6: =(D6/C6)^(1/(2035-2025))-1 -> 0.00066063067 | F6: Corresponding private-sector NAICS major sector; rounded BLS 2025 & 2035 employment | G6: https://www.bls.gov/emp/tables/employment-by-major-industry-sector.htm
A7: 22 | B7: Utilities | C7: 601.3 | D7: 660.1 | E7: =(D7/C7)^(1/(2035-2025))-1 -> 0.0093733937 | F7: Corresponding private-sector NAICS major sector; rounded BLS 2025 & 2035 employment | G7: https://www.bls.gov/emp/tables/employment-by-major-industry-sector.htm
A8: 23 | B8: Construction | C8: 8266.7 | D8: 8677.4 | E8: =(D8/C8)^(1/(2035-2025))-1 -> 0.0048604285 | F8: Corresponding private-sector NAICS major sector; rounded BLS 2025 & 2035 employment | G8: https://www.bls.gov/emp/tables/employment-by-major-industry-sector.htm
A9: 31-33 | B9: Manufacturing | C9: 12633.7 | D9: 12705.8 | E9: =(D9/C9)^(1/(2035-2025))-1 -> 0.00056923549 | F9: Corresponding private-sector NAICS major sector; rounded BLS 2025 & 2035 employment | G9: https://www.bls.gov/emp/tables/employment-by-major-industry-sector.htm
A10: 42 | B10: Wholesale trade | C10: 6059.5 | D10: 6184.7 | E10: =(D10/C10)^(1/(2035-2025))-1 -> 0.0020472139 | F10: Corresponding private-sector NAICS major sector; rounded BLS 2025 & 2035 employment | G10: https://www.bls.gov/emp/tables/employment-by-major-industry-sector.htm
A11: 44-45 | B11: Retail trade | C11: 15440.9 | D11: 15413.4 | E11: =(D11/C11)^(1/(2035-2025))-1 -> -0.00017824132 | F11: Corresponding private-sector NAICS major sector; rounded BLS 2025 & 2035 employment | G11: https://www.bls.gov/emp/tables/employment-by-major-industry-sector.htm
A12: 48-49 | B12: Transportation and warehousing | C12: 6639.5 | D12: 6846.8 | E12: =(D12/C12)^(1/(2035-2025))-1 -> 0.0030792041 | F12: BLS transportation excludes postal service; minor NAICS scope mismatch | G12: https://www.bls.gov/emp/tables/employment-by-major-industry-sector.htm
A13: 51 | B13: Information | C13: 2861.9 | D13: 3012.9 | E13: =(D13/C13)^(1/(2035-2025))-1 -> 0.0051549744 | F13: Corresponding private-sector NAICS major sector; rounded BLS 2025 & 2035 employment | G13: https://www.bls.gov/emp/tables/employment-by-major-industry-sector.htm
A14: 52 | B14: Finance and insurance | C14: 6739.3 | D14: 6893.6 | E14: =(D14/C14)^(1/(2035-2025))-1 -> 0.0022663025 | F14: Corresponding private-sector NAICS major sector; rounded BLS 2025 & 2035 employment | G14: https://www.bls.gov/emp/tables/employment-by-major-industry-sector.htm
A15: 53 | B15: Real estate and rental and leasing | C15: 2456.7 | D15: 2539.7 | E15: =(D15/C15)^(1/(2035-2025))-1 -> 0.0033282241 | F15: Corresponding private-sector NAICS major sector; rounded BLS 2025 & 2035 employment | G15: https://www.bls.gov/emp/tables/employment-by-major-industry-sector.htm
A16: 54 | B16: Professional, scientific, and technical services | C16: 10779.2 | D16: 11705.9 | E16: =(D16/C16)^(1/(2035-2025))-1 -> 0.0082815677 | F16: Corresponding private-sector NAICS major sector; rounded BLS 2025 & 2035 employment | G16: https://www.bls.gov/emp/tables/employment-by-major-industry-sector.htm
... A23: 81 | B23: Other services (except public administration) | C23: 6575.7 | D23: 6822.6 | E23: =(D23/C23)^(1/(2035-2025))-1 -> 0.003692761 | F23: Corresponding private-sector NAICS major sector; rounded BLS 2025 & 2035 employment | G23: https://www.bls.gov/emp/tables/employment-by-major-industry-sector.htm
A25: Scope: BLS projections are employment forecasts, not industry wage or AI adoption forecasts.
A26: BLS 2025–2035 employment CAGR is interpolated geometrically to 2030. QCEW private wage bill remains the 2025 baseline.

Sheet 02 Verified Inputs
A1: VERIFIED INPUTS | SOURCE DATA
A2: QCEW 2025 US000 / own_code 5; OEWS May 2025 detailed SOC, Wharton 2025 score; BTOS 202620 Q7=Yes. Currency: current dollars.
A4: NAICS | B4: Industry | C4: QCEW Private Annual Wages ($) | D4: OEWS Detailed Wages ($) | E4: Wharton Matched Wages ($) | F4: Wharton Exposure-Weighted Wages ($) | G4: Census BTOS Firms Using AI | H4: Census AI Supplement Firms Using AI | I4: OEWS Ownership Treatment / QA
A5: 11 | B5: Agriculture, forestry, fishing and hunting | C5: 60088224865 | D5: 18024128600 | E5: 17900932800 | F5: 3.2456895e+09 | G5: 0.095 | H5: 0.051 | I5: OEWS private sector 5
A6: 21 | B6: Mining, quarrying, and oil and gas extraction | C6: 76216722054 | D6: 46718540800 | E6: 46156543200 | F6: 1.3397598e+10 | G6: 0.13 | H6: 0.077 | I6: OEWS private sector 5
A7: 22 | B7: Utilities | C7: 85024861666 | D7: 61892073000 | E7: 61630077300 | F7: 2.2584317e+10 | G7: 0.167 | H7: 0.137 | I7: OEWS private sector 5
A8: 23 | B8: Construction | C8: 699896249139 | D8: 598121924700 | E8: 596275773800 | F8: 1.5859374e+11 | G8: 0.172 | H8: 0.092 | I8: OEWS private sector 5
A9: 31-33 | B9: Manufacturing | C9: 1125542676332 | D9: 874493524800 | E9: 864066610900 | F9: 2.8693931e+11 | G9: 0.208 | H9: 0.124 | I9: OEWS private sector 5
A10: 42 | B10: Wholesale trade | C10: 638878973832 | D10: 458154842200 | E10: 455375229800 | F10: 2.1041317e+11 | G10: 0.216 | H10: 0.136 | I10: OEWS private sector 5
A11: 44-45 | B11: Retail trade | C11: 668863568474 | D11: 693029757900 | E11: 689445511900 | F11: 3.0219336e+11 | G11: 0.168 | H11: 0.126 | I11: OEWS private sector 5
A12: 48-49 | B12: Transportation and warehousing | C12: 455483942924 | D12: 478826169400 | E12: 477192875600 | F12: 1.5708135e+11 | G12: 0.105 | H12: 0.076 | I12: MIXED: includes public postal service in OEWS weights
A13: 51 | B13: Information | C13: 544469565204 | D13: 323626172500 | E13: 321614756900 | F13: 1.8150197e+11 | G13: 0.502 | H13: 0.376 | I13: OEWS private sector 5
A14: 52 | B14: Finance and insurance | C14: 966666752201 | D14: 632312197400 | E14: 628985978900 | F14: 4.2699129e+11 | G14: 0.401 | H14: 0.304 | I14: OEWS private sector 5
A15: 53 | B15: Real estate and rental and leasing | C15: 193529178704 | D15: 157850571500 | E15: 156904776000 | F15: 7.3211257e+10 | G15: 0.308 | H15: 0.235 | I15: OEWS private sector 5
A16: 54 | B16: Professional, scientific, and technical services | C16: 1454390668355 | D16: 1171256518800 | E16: 1167218193400 | F16: 6.4740875e+11 | G16: 0.427 | H16: 0.342 | I16: OEWS private sector 5
... A23: 81 | B23: Other services (except public administration) | C23: 254468914292 | D23: 254714435300 | E23: 250743090000 | F23: 9.0672712e+10 | G23: 0.127 | H23: 0.098 | I23: OEWS private sector 5
A25: US QCEW control | B25: Private wage total including NAICS 99 | C25: 10532191402092
A26: NAICS 99 excluded | B26: Private unclassified annual wages | C26: 16545877587
A28: SOURCE NOTES: OEWS Exposure-Weighted Wages are SUM(Employment x Mean Annual Wage x Wharton SOC task-exposure score).

Sheet 03 Sources and QA
A1: DATA SOURCES, INDUSTRY MAPPING AND LIMITATIONS
A4: Data | B4: Official Source URL | C4: Uploaded Original | D4: Usage / filters
A5: BLS QCEW annual 2025 | B5: https://www.bls.gov/cew/downloadable-data-files.htm | C5: 2025_annual_by_industry (1).zip | D5: US000, own_code=5, annual total_annual_wages, NAICS 19 sectors plus 99
A6: BLS OEWS May 2025 | B6: https://www.bls.gov/oes/tables.htm | C6: natsector_M2025_dl.xlsx | D6: Sector x SOC detailed: TOT_EMP x A_MEAN; 61/62 ownership-adjusted
A7: BLS OEWS May 2025 ownership | B7: https://www.bls.gov/oes/2025/may/oessrci.htm | C7: nat3d_owner_M2025_dl.xlsx | D7: NAICS 611000 private only; subtract NAICS 622000 public hospital wages
A8: Penn Wharton occupational AI exposure | B8: https://budgetmodel.wharton.upenn.edu/p/2025-09-08-the-projected-impact-of-generative-ai-on-future-productivity-growth/ | C8: supp_exposure_by_occupation (1).csv | D8: 784 SOC; exposure (%) mapped to exact detailed occupation
A9: Census BTOS 202620 | B9: https://www.census.gov/hfp/btos/data_downloads | C9: Sector (3).xlsx | D9: Question ID 7 / Answer ID 1 / cycle 202620; share of BUSINESSES using AI
A10: Census AI Supplement 2026 | B10: https://www.census.gov/hfp/btos/data_downloads | C10: AI_Supplement_Table_2026 (1).xlsx | D10: Scope 1 / Question ID 1 / Answer ID 1 Yes; comparison only
A11: Detailed audit CSV | B11: https://www.bls.gov/oes/tables.htm | C11: AI_Wage_Exposure_Private_Adjusted_Detail.csv | D11: Detailed sector x SOC source with employment, annual wages, Wharton SOC score and match status
A14: Step 1 | B14: QCEW Annual Wages ($) for each 2025 private NAICS industry.
A15: Step 2 | B15: OEWS wage share by SOC = detailed occupation employment x mean annual wage.
A16: Step 3 | B16: Exact 6-digit SOC join to 784 Wharton task exposure scores.
A17: Step 4 | B17: OEWS task exposure share = Sum(matched wage x exposure)/Sum(matched wage).
A18: Step 5 | B18: Gross AI-exposed wage pool = QCEW private annual wage x Task Exposure Share.
A19: Formula workflow | B19: DATA OEWS: E×F; XLOOKUP SOC from DATA Wharton; matched and exposed wages. Main: SUMIF by NAICS, XLOOKUP QCEW/Census.
A20: Matching | B20: Missing Wharton SOC codes are omitted from numerator AND exposure denominator. Match coverage disclosed.
A21: Ownership | B21: Private QCEW always. OEWS 61 private from 611000, 62 subtract public hospitals, 48/71/72 mixed proxies.
A22: Mapping | B22: QCEW 31-33 / 44-45 / 48-49 map to Census sector codes 31 / 44 / 48.
A23: Reconcile | B23: QCEW private all-industries = sum 19 sector wage bills + NAICS 99 wage bill.

Sheet DATA QCEW
A1: NAICS | B1: Industry | C1: QCEW 2025 private annual wages ($) | D1: QCEW source
A2: 11 | B2: Agriculture, forestry, fishing and hunting | C2: 60088224865 | D2: https://www.bls.gov/cew/downloadable-data-files.htm
A3: 21 | B3: Mining, quarrying, and oil and gas extraction | C3: 76216722054 | D3: https://www.bls.gov/cew/downloadable-data-files.htm
A4: 22 | B4: Utilities | C4: 85024861666 | D4: https://www.bls.gov/cew/downloadable-data-files.htm
A5: 23 | B5: Construction | C5: 699896249139 | D5: https://www.bls.gov/cew/downloadable-data-files.htm
A6: 31-33 | B6: Manufacturing | C6: 1125542676332 | D6: https://www.bls.gov/cew/downloadable-data-files.htm
A7: 42 | B7: Wholesale trade | C7: 638878973832 | D7: https://www.bls.gov/cew/downloadable-data-files.htm
A8: 44-45 | B8: Retail trade | C8: 668863568474 | D8: https://www.bls.gov/cew/downloadable-data-files.htm
A9: 48-49 | B9: Transportation and warehousing | C9: 455483942924 | D9: https://www.bls.gov/cew/downloadable-data-files.htm
A10: 51 | B10: Information | C10: 544469565204 | D10: https://www.bls.gov/cew/downloadable-data-files.htm
A11: 52 | B11: Finance and insurance | C11: 966666752201 | D11: https://www.bls.gov/cew/downloadable-data-files.htm
A12: 53 | B12: Real estate and rental and leasing | C12: 193529178704 | D12: https://www.bls.gov/cew/downloadable-data-files.htm
A13: 54 | B13: Professional, scientific, and technical services | C13: 1454390668355 | D13: https://www.bls.gov/cew/downloadable-data-files.htm
... A20: 81 | B20: Other services (except public administration) | C20: 254468914292 | D20: https://www.bls.gov/cew/downloadable-data-files.htm

Sheet DATA OEWS
A1: NAICS | B1: Industry | C1: SOC code | D1: Occupation | E1: Employees | F1: Annual mean wage ($) | G1: Known occupation wages ($) | H1: Wharton task exposure | I1: Matched occupation wages ($) | J1: Exposure-weighted wages ($) | K1: Mapping status
A2: 11 | B2: Agriculture, Forestry, Fishing and Hunting | C2: 11-1011 | D2: Chief Executives | E2: 170 | F2: 277000 | G2: =IF(OR(E2="",F2=""),"",E2*F2) | H2: =IFERROR(XLOOKUP(C2,'DATA Wharton'!$A$2:$A$785,'DATA Wharton'!$C$2:$C$785),"") | I2: =IF(OR(G2="",H2=""),"",G2) | J2: =IF(OR(I2="",H2=""),"",I2*H2) | K2: =IF(G2="","Missing OEWS wage",IF(H2="","Missing Wharton SOC","Matched"))
A3: 11 | B3: Agriculture, Forestry, Fishing and Hunting | C3: 11-1021 | D3: General and Operations Managers | E3: 5660 | F3: 99340 | G3: =IF(OR(E3="",F3=""),"",E3*F3) | H3: =IFERROR(XLOOKUP(C3,'DATA Wharton'!$A$2:$A$785,'DATA Wharton'!$C$2:$C$785),"") | I3: =IF(OR(G3="",H3=""),"",G3) | J3: =IF(OR(I3="",H3=""),"",I3*H3) | K3: =IF(G3="","Missing OEWS wage",IF(H3="","Missing Wharton SOC","Matched"))
A4: 11 | B4: Agriculture, Forestry, Fishing and Hunting | C4: 11-2021 | D4: Marketing Managers | E4: 70 | F4: 129740 | G4: =IF(OR(E4="",F4=""),"",E4*F4) | H4: =IFERROR(XLOOKUP(C4,'DATA Wharton'!$A$2:$A$785,'DATA Wharton'!$C$2:$C$785),"") | I4: =IF(OR(G4="",H4=""),"",G4) | J4: =IF(OR(I4="",H4=""),"",I4*H4) | K4: =IF(G4="","Missing OEWS wage",IF(H4="","Missing Wharton SOC","Matched"))
A5: 11 | B5: Agriculture, Forestry, Fishing and Hunting | C5: 11-2022 | D5: Sales Managers | E5: 330 | F5: 162490 | G5: =IF(OR(E5="",F5=""),"",E5*F5) | H5: =IFERROR(XLOOKUP(C5,'DATA Wharton'!$A$2:$A$785,'DATA Wharton'!$C$2:$C$785),"") | I5: =IF(OR(G5="",H5=""),"",G5) | J5: =IF(OR(I5="",H5=""),"",I5*H5) | K5: =IF(G5="","Missing OEWS wage",IF(H5="","Missing Wharton SOC","Matched"))
A6: 11 | B6: Agriculture, Forestry, Fishing and Hunting | C6: 11-3012 | D6: Administrative Services Managers | E6: 150 | F6: 124650 | G6: =IF(OR(E6="",F6=""),"",E6*F6) | H6: =IFERROR(XLOOKUP(C6,'DATA Wharton'!$A$2:$A$785,'DATA Wharton'!$C$2:$C$785),"") | I6: =IF(OR(G6="",H6=""),"",G6) | J6: =IF(OR(I6="",H6=""),"",I6*H6) | K6: =IF(G6="","Missing OEWS wage",IF(H6="","Missing Wharton SOC","Matched"))
A7: 11 | B7: Agriculture, Forestry, Fishing and Hunting | C7: 11-3013 | D7: Facilities Managers | E7: 300 | F7: 115030 | G7: =IF(OR(E7="",F7=""),"",E7*F7) | H7: =IFERROR(XLOOKUP(C7,'DATA Wharton'!$A$2:$A$785,'DATA Wharton'!$C$2:$C$785),"") | I7: =IF(OR(G7="",H7=""),"",G7) | J7: =IF(OR(I7="",H7=""),"",I7*H7) | K7: =IF(G7="","Missing OEWS wage",IF(H7="","Missing Wharton SOC","Matched"))
A8: 11 | B8: Agriculture, Forestry, Fishing and Hunting | C8: 11-3021 | D8: Computer and Information Systems Managers | E8: 140 | F8: 160470 | G8: =IF(OR(E8="",F8=""),"",E8*F8) | H8: =IFERROR(XLOOKUP(C8,'DATA Wharton'!$A$2:$A$785,'DATA Wharton'!$C$2:$C$785),"") | I8: =IF(OR(G8="",H8=""),"",G8) | J8: =IF(OR(I8="",H8=""),"",I8*H8) | K8: =IF(G8="","Missing OEWS wage",IF(H8="","Missing Wharton SOC","Matched"))
A9: 11 | B9: Agriculture, Forestry, Fishing and Hunting | C9: 11-3031 | D9: Financial Managers | E9: 460 | F9: 156410 | G9: =IF(OR(E9="",F9=""),"",E9*F9) | H9: =IFERROR(XLOOKUP(C9,'DATA Wharton'!$A$2:$A$785,'DATA Wharton'!$C$2:$C$785),"") | I9: =IF(OR(G9="",H9=""),"",G9) | J9: =IF(OR(I9="",H9=""),"",I9*H9) | K9: =IF(G9="","Missing OEWS wage",IF(H9="","Missing Wharton SOC","Matched"))
A10: 11 | B10: Agriculture, Forestry, Fishing and Hunting | C10: 11-3051 | D10: Industrial Production Managers | E10: 580 | F10: 108020 | G10: =IF(OR(E10="",F10=""),"",E10*F10) | H10: =IFERROR(XLOOKUP(C10,'DATA Wharton'!$A$2:$A$785,'DATA Wharton'!$C$2:$C$785),"") | I10: =IF(OR(G10="",H10=""),"",G10) | J10: =IF(OR(I10="",H10=""),"",I10*H10) | K10: =IF(G10="","Missing OEWS wage",IF(H10="","Missing Wharton SOC","Matched"))
A11: 11 | B11: Agriculture, Forestry, Fishing and Hunting | C11: 11-3061 | D11: Purchasing Managers | E11: 50 | F11: 144980 | G11: =IF(OR(E11="",F11=""),"",E11*F11) | H11: =IFERROR(XLOOKUP(C11,'DATA Wharton'!$A$2:$A$785,'DATA Wharton'!$C$2:$C$785),"") | I11: =IF(OR(G11="",H11=""),"",G11) | J11: =IF(OR(I11="",H11=""),"",I11*H11) | K11: =IF(G11="","Missing OEWS wage",IF(H11="","Missing Wharton SOC","Matched"))
A12: 11 | B12: Agriculture, Forestry, Fishing and Hunting | C12: 11-3071 | D12: Transportation, Storage, and Distribution Managers | E12: 320 | F12: 100610 | G12: =IF(OR(E12="",F12=""),"",E12*F12) | H12: =IFERROR(XLOOKUP(C12,'DATA Wharton'!$A$2:$A$785,'DATA Wharton'!$C$2:$C$785),"") | I12: =IF(OR(G12="",H12=""),"",G12) | J12: =IF(OR(I12="",H12=""),"",I12*H12) | K12: =IF(G12="","Missing OEWS wage",IF(H12="","Missing Wharton SOC","Matched"))
A13: 11 | B13: Agriculture, Forestry, Fishing and Hunting | C13: 11-3121 | D13: Human Resources Managers | E13: 100 | F13: 141370 | G13: =IF(OR(E13="",F13=""),"",E13*F13) | H13: =IFERROR(XLOOKUP(C13,'DATA Wharton'!$A$2:$A$785,'DATA Wharton'!$C$2:$C$785),"") | I13: =IF(OR(G13="",H13=""),"",G13) | J13: =IF(OR(I13="",H13=""),"",I13*H13) | K13: =IF(G13="","Missing OEWS wage",IF(H13="","Missing Wharton SOC","Matched"))
... A15: 11 | B15: Agriculture, Forestry, Fishing and Hunting | C15: 11-9121 | D15: Natural Sciences Managers | E15: 50 | F15: 120590 | G15: =IF(OR(E15="",F15=""),"",E15*F15) | H15: =IFERROR(XLOOKUP(C15,'DATA Wharton'!$A$2:$A$785,'DATA Wharton'!$C$2:$C$785),"") | I15: =IF(OR(G15="",H15=""),"",G15) | J15: =IF(OR(I15="",H15=""),"",I15*H15) | K15: =IF(G15="","Missing OEWS wage",IF(H15="","Missing Wharton SOC","Matched"))
A16: 11 | B16: Agriculture, Forestry, Fishing and Hunting | C16: 11-9199 | D16: Managers, All Other | E16: 470 | G16: =IF(OR(E16="",F16=""),"",E16*F16) | H16: =IFERROR(XLOOKUP(C16,'DATA Wharton'!$A$2:$A$785,'DATA Wharton'!$C$2:$C$785),"") | I16: =IF(OR(G16="",H16=""),"",G16) | J16: =IF(OR(I16="",H16=""),"",I16*H16) | K16: =IF(G16="","Missing OEWS wage",IF(H16="","Missing Wharton SOC","Matched"))
A17: 11 | B17: Agriculture, Forestry, Fishing and Hunting | C17: 13-1020 | D17: Buyers and Purchasing Agents | E17: 520 | F17: 81950 | G17: =IF(OR(E17="",F17=""),"",E17*F17) | H17: =IFERROR(XLOOKUP(C17,'DATA Wharton'!$A$2:$A$785,'DATA Wharton'!$C$2:$C$785),"") | I17: =IF(OR(G17="",H17=""),"",G17) | J17: =IF(OR(I17="",H17=""),"",I17*H17) | K17: =IF(G17="","Missing OEWS wage",IF(H17="","Missing Wharton SOC","Matched"))
A18: 11 | B18: Agriculture, Forestry, Fishing and Hunting | C18: 13-1041 | D18: Compliance Officers | E18: 60 | F18: 67290 | G18: =IF(OR(E18="",F18=""),"",E18*F18) | H18: =IFERROR(XLOOKUP(C18,'DATA Wharton'!$A$2:$A$785,'DATA Wharton'!$C$2:$C$785),"") | I18: =IF(OR(G18="",H18=""),"",G18) | J18: =IF(OR(I18="",H18=""),"",I18*H18) | K18: =IF(G18="","Missing OEWS wage",IF(H18="","Missing Wharton SOC","Matched"))
A19: 11 | B19: Agriculture, Forestry, Fishing and Hunting | C19: 13-1071 | D19: Human Resources Specialists | E19: 700 | F19: 74400 | G19: =IF(OR(E19="",F19=""),"",E19*F19) | H19: =IFERROR(XLOOKUP(C19,'DATA Wharton'!$A$2:$A$785,'DATA Wharton'!$C$2:$C$785),"") | I19: =IF(OR(G19="",H19=""),"",G19) | J19: =IF(OR(I19="",H19=""),"",I19*H19) | K19: =IF(G19="","Missing OEWS wage",IF(H19="","Missing Wharton SOC","Matched"))
A20: 11 | B20: Agriculture, Forestry, Fishing and Hunting | C20: 13-1074 | D20: Farm Labor Contractors | E20: 270 | F20: 62420 | G20: =IF(OR(E20="",F20=""),"",E20*F20) | H20: =IFERROR(XLOOKUP(C20,'DATA Wharton'!$A$2:$A$785,'DATA Wharton'!$C$2:$C$785),"") | I20: =IF(OR(G20="",H20=""),"",G20) | J20: =IF(OR(I20="",H20=""),"",I20*H20) | K20: =IF(G20="","Missing OEWS wage",IF(H20="","Missing Wharton SOC","Matched"))
A21: 11 | B21: Agriculture, Forestry, Fishing and Hunting | C21: 13-1081 | D21: Logisticians | E21: 250 | F21: 75350 | G21: =IF(OR(E21="",F21=""),"",E21*F21) | H21: =IFERROR(XLOOKUP(C21,'DATA Wharton'!$A$2:$A$785,'DATA Wharton'!$C$2:$C$785),"") | I21: =IF(OR(G21="",H21=""),"",G21) | J21: =IF(OR(I21="",H21=""),"",I21*H21) | K21: =IF(G21="","Missing OEWS wage",IF(H21="","Missing Wharton SOC","Matched"))
A22: 11 | B22: Agriculture, Forestry, Fishing and Hunting | C22: 13-1082 | D22: Project Management Specialists | E22: 130 | F22: 90840 | G22: =IF(OR(E22="",F22=""),"",E22*F22) | H22: =IFERROR(XLOOKUP(C22,'DATA Wharton'!$A$2:$A$785,'DATA Wharton'!$C$2:$C$785),"") | I22: =IF(OR(G22="",H22=""),"",G22) | J22: =IF(OR(I22="",H22=""),"",I22*H22) | K22: =IF(G22="","Missing OEWS wage",IF(H22="","Missing Wharton SOC","Matched"))
A23: 11 | B23: Agriculture, Forestry, Fishing and Hunting | C23: 13-1111 | D23: Management Analysts | E23: 120 | G23: =IF(OR(E23="",F23=""),"",E23*F23) | H23: =IFERROR(XLOOKUP(C23,'DATA Wharton'!$A$2:$A$785,'DATA Wharton'!$C$2:$C$785),"") | I23: =IF(OR(G23="",H23=""),"",G23) | J23: =IF(OR(I23="",H23=""),"",I23*H23) | K23: =IF(G23="","Missing OEWS wage",IF(H23="","Missing Wharton SOC","Matched"))
A24: 11 | B24: Agriculture, Forestry, Fishing and Hunting | C24: 13-1121 | D24: Meeting, Convention, and Event Planners | E24: 50 | F24: 48850 | G24: =IF(OR(E24="",F24=""),"",E24*F24) | H24: =IFERROR(XLOOKUP(C24,'DATA Wharton'!$A$2:$A$785,'DATA Wharton'!$C$2:$C$785),"") | I24: =IF(OR(G24="",H24=""),"",G24) | J24: =IF(OR(I24="",H24=""),"",I24*H24) | K24: =IF(G24="","Missing OEWS wage",IF(H24="","Missing Wharton SOC","Matched"))
A25: 11 | B25: Agriculture, Forestry, Fishing and Hunting | C25: 13-1141 | D25: Compensation, Benefits, and Job Analysis Specialists | E25: 30 | G25: =IF(OR(E25="",F25=""),"",E25*F25) | H25: =IFERROR(XLOOKUP(C25,'DATA Wharton'!$A$2:$A$785,'DATA Wharton'!$C$2:$C$785),"") | I25: =IF(OR(G25="",H25=""),"",G25) | J25: =IF(OR(I25="",H25=""),"",I25*H25) | K25: =IF(G25="","Missing OEWS wage",IF(H25="","Missing Wharton SOC","Matched"))
A26: 11 | B26: Agriculture, Forestry, Fishing and Hunting | C26: 13-1151 | D26: Training and Development Specialists | E26: 100 | G26: =IF(OR(E26="",F26=""),"",E26*F26) | H26: =IFERROR(XLOOKUP(C26,'DATA Wharton'!$A$2:$A$785,'DATA Wharton'!$C$2:$C$785),"") | I26: =IF(OR(G26="",H26=""),"",G26) | J26: =IF(OR(I26="",H26=""),"",I26*H26) | K26: =IF(G26="","Missing OEWS wage",IF(H26="","Missing Wharton SOC","Matched"))
A27: 11 | B27: Agriculture, Forestry, Fishing and Hunting | C27: 13-1161 | D27: Market Research Analysts and Marketing Specialists | E27: 210 | F27: 92250 | G27: =IF(OR(E27="",F27=""),"",E27*F27) | H27: =IFERROR(XLOOKUP(C27,'DATA Wharton'!$A$2:$A$785,'DATA Wharton'!$C$2:$C$785),"") | I27: =IF(OR(G27="",H27=""),"",G27) | J27: =IF(OR(I27="",H27=""),"",I27*H27) | K27: =IF(G27="","Missing OEWS wage",IF(H27="","Missing Wharton SOC","Matched"))
A28: 11 | B28: Agriculture, Forestry, Fishing and Hunting | C28: 13-1199 | D28: Business Operations Specialists, All Other | E28: 660 | G28: =IF(OR(E28="",F28=""),"",E28*F28) | H28: =IFERROR(XLOOKUP(C28,'DATA Wharton'!$A$2:$A$785,'DATA Wharton'!$C$2:$C$785),"") | I28: =IF(OR(G28="",H28=""),"",G28) | J28: =IF(OR(I28="",H28=""),"",I28*H28) | K28: =IF(G28="","Missing OEWS wage",IF(H28="","Missing Wharton SOC","Matched"))
A29: 11 | B29: Agriculture, Forestry, Fishing and Hunting | C29: 13-2011 | D29: Accountants and Auditors | E29: 1110 | F29: 83410 | G29: =IF(OR(E29="",F29=""),"",E29*F29) | H29: =IFERROR(XLOOKUP(C29,'DATA Wharton'!$A$2:$A$785,'DATA Wharton'!$C$2:$C$785),"") | I29: =IF(OR(G29="",H29=""),"",G29) | J29: =IF(OR(I29="",H29=""),"",I29*H29) | K29: =IF(G29="","Missing OEWS wage",IF(H29="","Missing Wharton SOC","Matched"))
A30: 11 | B30: Agriculture, Forestry, Fishing and Hunting | C30: 15-1211 | D30: Computer Systems Analysts | E30: 40 | F30: 107730 | G30: =IF(OR(E30="",F30=""),"",E30*F30) | H30: =IFERROR(XLOOKUP(C30,'DATA Wharton'!$A$2:$A$785,'DATA Wharton'!$C$2:$C$785),"") | I30: =IF(OR(G30="",H30=""),"",G30) | J30: =IF(OR(I30="",H30=""),"",I30*H30) | K30: =IF(G30="","Missing OEWS wage",IF(H30="","Missing Wharton SOC","Matched"))
A31: 11 | B31: Agriculture, Forestry, Fishing and Hunting | C31: 15-1232 | D31: Computer User Support Specialists | E31: 230 | F31: 65730 | G31: =IF(OR(E31="",F31=""),"",E31*F31) | H31: =IFERROR(XLOOKUP(C31,'DATA Wharton'!$A$2:$A$785,'DATA Wharton'!$C$2:$C$785),"") | I31: =IF(OR(G31="",H31=""),"",G31) | J31: =IF(OR(I31="",H31=""),"",I31*H31) | K31: =IF(G31="","Missing OEWS wage",IF(H31="","Missing Wharton SOC","Matched"))
