Workbook

Sheet READ ME
A1: AI-EXPOSED WAGE POOL | COMPANY REBUILD GUIDE
A2: Formula-driven • Official data in local tabs • No website or external-workbook links • Blue = source inputs / Green = cross-sheet links
A4: STEP | B4: ACTION | C4: WHAT TO DO | D4: RESULT | E4: IMPORTANT
A5: 01 | B5: QCEW raw | C5: Paste the BLS Industry column into DATA QCEW Raw A, and Total Annual Wages into D. You may paste all ~2,000 rows. | D5: Columns E:G parse the NAICS codes automatically. | E5: Do not sum parent and child industries.
A6: 02 | B6: QCEW mapping | C6: DATA QCEW uses one XLOOKUP per 19 industry codes. | D6: Annual industry wage totals pulled from raw table. | E6: Rows labelled 1013 / 1022 are BLS aggregation IDs, not NAICS.
A7: 03 | B7: Wharton | C7: DATA Wharton has 784 SOC codes with task exposure as 0–1 fractions. | D7: Occupation-level AI task exposure. | E7: Original 47.75% in CSV must be 0.4775 internally.
A8: 04 | B8: OEWS | C8: DATA OEWS contains 7,805 unique sector × detailed SOC records. G/I/J/K are drag-down formulas; H is a verified 2025 Wharton SOC join (replace with XLOOKUP if scores change). | D8: G:K are simple drag-down formulas. | E8: Some suppressed occupations have blank wages.
A9: 05 | B9: Industry Model | C9: Read C:K in 01 Industry Model. | D9: QCEW wage bill × (OEWS weighted Wharton exposure). | E9: The base projection A:K is unchanged. New employee / price revenue scenarios are separate in columns L:Q.
A10: 06 | B10: Projection | C10: Five-Year Projection: 2025–2030 driven by BLS employment CAGR and editable wage / adoption growth. | D10: Simple annual sector forecast. | E10: No AI economic savings / revenue estimation.
A11: QA | B11: Reconciliation | C11: 19 industry wages + NAICS 99 must equal $10,532,191,402,092 in 2025. | D11: 0 reconciliation difference. | E11: Raw QCEW source must be US TOTAL, private, all sizes.
B13: Formula in DATA QCEW Raw!E2
A14: KEY FORMULA | B14: EXCEL EXAMPLE | C14: WHY
A15: Extract code from BLS Industry | B15: NAICS 31-33 Manufacturing → 31-33 | C15: Extract the code between NAICS and first following space.
A16: Wage weight | B16: SUMIF of occupation wage bills by NAICS | C16: Use occupation structure to compute exposure, not sector wages.
A17: Final Gross Exposure | B17: QCEW Annual Wages × Exposure Share | C17: Exposure value ≠ cost saved / layoffs.
A20: OPTIONAL LIVE WHARTON REFRESH | B20: DATA OEWS H2: paste this formula and drag down to H7806
A21: SOC lookup formula | B21: =IFERROR(XLOOKUP(C2,'DATA Wharton'!$A$2:$A$785,'DATA Wharton'!$C$2:$C$785),) | C21: Use only if Wharton scores changed; baseline H values already verified against the 2025 source.
A23: NEW | B23: QCEW employment | C23: Use BLS QCEW annual_avg_emplvl, filtered US000 + own_code 5 + 2025 + annual + all sizes. | D23: DATA QCEW Raw C → DATA QCEW F → Industry Model L. | E23: All data from supplied 2025 QCEW ZIP.
A24: NEW | B24: 2025 revenue proxy | C24: Task-exposed equivalents = QCEW employment × Wharton weighted task exposure. | D24: Industry Model M = L × H; implied revenue O = M × N × 12 / 1e9. | E24: Exposure ≠ actual employee AI-use or paid seat count.
A25: NEW | B25: Pricing | C25: Projection Assumptions C9 = editable monthly AI spend per seat; C10 = annual price growth. | D25: Industry Model N and Projection N pull price assumptions. | E25: $30 / month is illustrative, not observed market revenue.
A26: NEW | B26: Five-year AI revenue | C26: Projection L:Q derive employees, proxy seats, price and enterprise revenue independently of A:K. | D26: Revenue summary added Five-Year Projection rows 10–14. | E26: BTOS-adjusted seats multiply a firm-use rate, NOT an employee-use rate.

Sheet 01 Industry Model
A1: AI-EXPOSED WAGE POOL | U.S. PRIVATE INDUSTRIES (2025)
A2: Source → DATA QCEW Raw → DATA QCEW. SOC mapping is done in DATA OEWS against DATA Wharton. Gross exposure is NOT AI cost savings.
L3: AI SOFTWARE SEAT & REVENUE SCENARIO | NOT OBSERVED PAID USERS
A4: NAICS | B4: Industry | C4: QCEW Wages ($bn) | D4: OEWS Wages ($bn) | E4: Matched Wages ($bn) | F4: Exposure-Weighted Wages ($bn) | G4: Wharton Match Rate | H4: Weighted Task Exposure | I4: GROSS EXPOSED ($bn) | J4: BTOS Firms Using AI | K4: Firm-Use Proxy ($bn) | L4: 2025 Employees (QCEW) | M4: Task-Exposed Seat Eq. (Proxy) | N4: AI Price ($/seat/month) | O4: Task-Equivalent Revenue ($bn) | P4: BTOS-Adjusted Seat Eq. (Proxy) | Q4: BTOS-Adjusted Revenue ($bn)
A5: 11 | B5: Agriculture, forestry, fishing and hunting | C5: =IFERROR(_xlfn.XLOOKUP(A5,'DATA QCEW'!$A$2:$A$20,'DATA QCEW'!$C$2:$C$20)/1000000000,"") -> 60.088225 | D5: =SUMIF('DATA OEWS'!$A$2:$A$7806,A5,'DATA OEWS'!$G$2:$G$7806)/1000000000 -> 18.024129 | E5: =SUMIF('DATA OEWS'!$A$2:$A$7806,A5,'DATA OEWS'!$I$2:$I$7806)/1000000000 -> 17.900933 | F5: =SUMIF('DATA OEWS'!$A$2:$A$7806,A5,'DATA OEWS'!$J$2:$J$7806)/1000000000 -> 3.2456895 | G5: =IF(D5=0,"",E5/D5) -> 0.99316495 | H5: =IF(E5=0,"",F5/E5) -> 0.18131399 | I5: =IF(OR(C5="",H5=""),"",C5*H5) -> 10.894836 | J5: =IFERROR(_xlfn.XLOOKUP(A5,'DATA Census'!$A$2:$A$20,'DATA Census'!$C$2:$C$20),"") -> 0.095 | K5: =IF(OR(I5="",J5=""),"",I5*J5) -> 1.0350094 | L5: =IFERROR(_xlfn.XLOOKUP(A5,'DATA QCEW'!$A$2:$A$20,'DATA QCEW'!$F$2:$F$20),"") -> 1231078 | M5: =IF(OR(L5="",H5=""),"",L5*H5) -> 223211.66 | N5: ='Projection Assumptions'!$C$9 -> 30 | O5: =IF(OR(M5="",N5=""),"",M5*N5*12/1000000000) -> 0.080356199 | P5: =IF(OR(M5="",J5=""),"",M5*J5) -> 21205.108 | Q5: =IF(OR(P5="",N5=""),"",P5*N5*12/1000000000) -> 0.0076338389
A6: 21 | B6: Mining, quarrying, and oil and gas extraction | C6: =IFERROR(_xlfn.XLOOKUP(A6,'DATA QCEW'!$A$2:$A$20,'DATA QCEW'!$C$2:$C$20)/1000000000,"") -> 76.216722 | D6: =SUMIF('DATA OEWS'!$A$2:$A$7806,A6,'DATA OEWS'!$G$2:$G$7806)/1000000000 -> 46.718541 | E6: =SUMIF('DATA OEWS'!$A$2:$A$7806,A6,'DATA OEWS'!$I$2:$I$7806)/1000000000 -> 46.156543 | F6: =SUMIF('DATA OEWS'!$A$2:$A$7806,A6,'DATA OEWS'!$J$2:$J$7806)/1000000000 -> 13.397598 | G6: =IF(D6=0,"",E6/D6) -> 0.98797057 | H6: =IF(E6=0,"",F6/E6) -> 0.29026433 | I6: =IF(OR(C6="",H6=""),"",C6*H6) -> 22.122996 | J6: =IFERROR(_xlfn.XLOOKUP(A6,'DATA Census'!$A$2:$A$20,'DATA Census'!$C$2:$C$20),"") -> 0.13 | K6: =IF(OR(I6="",J6=""),"",I6*J6) -> 2.8759895 | L6: =IFERROR(_xlfn.XLOOKUP(A6,'DATA QCEW'!$A$2:$A$20,'DATA QCEW'!$F$2:$F$20),"") -> 570806 | M6: =IF(OR(L6="",H6=""),"",L6*H6) -> 165684.62 | N6: ='Projection Assumptions'!$C$9 -> 30 | O6: =IF(OR(M6="",N6=""),"",M6*N6*12/1000000000) -> 0.059646464 | P6: =IF(OR(M6="",J6=""),"",M6*J6) -> 21539.001 | Q6: =IF(OR(P6="",N6=""),"",P6*N6*12/1000000000) -> 0.0077540403
A7: 22 | B7: Utilities | C7: =IFERROR(_xlfn.XLOOKUP(A7,'DATA QCEW'!$A$2:$A$20,'DATA QCEW'!$C$2:$C$20)/1000000000,"") -> 85.024862 | D7: =SUMIF('DATA OEWS'!$A$2:$A$7806,A7,'DATA OEWS'!$G$2:$G$7806)/1000000000 -> 61.892073 | E7: =SUMIF('DATA OEWS'!$A$2:$A$7806,A7,'DATA OEWS'!$I$2:$I$7806)/1000000000 -> 61.630077 | F7: =SUMIF('DATA OEWS'!$A$2:$A$7806,A7,'DATA OEWS'!$J$2:$J$7806)/1000000000 -> 22.584317 | G7: =IF(D7=0,"",E7/D7) -> 0.99576689 | H7: =IF(E7=0,"",F7/E7) -> 0.3664496 | I7: =IF(OR(C7="",H7=""),"",C7*H7) -> 31.157326 | J7: =IFERROR(_xlfn.XLOOKUP(A7,'DATA Census'!$A$2:$A$20,'DATA Census'!$C$2:$C$20),"") -> 0.167 | K7: =IF(OR(I7="",J7=""),"",I7*J7) -> 5.2032735 | L7: =IFERROR(_xlfn.XLOOKUP(A7,'DATA QCEW'!$A$2:$A$20,'DATA QCEW'!$F$2:$F$20),"") -> 602080 | M7: =IF(OR(L7="",H7=""),"",L7*H7) -> 220631.97 | N7: ='Projection Assumptions'!$C$9 -> 30 | O7: =IF(OR(M7="",N7=""),"",M7*N7*12/1000000000) -> 0.07942751 | P7: =IF(OR(M7="",J7=""),"",M7*J7) -> 36845.54 | Q7: =IF(OR(P7="",N7=""),"",P7*N7*12/1000000000) -> 0.013264394
A8: 23 | B8: Construction | C8: =IFERROR(_xlfn.XLOOKUP(A8,'DATA QCEW'!$A$2:$A$20,'DATA QCEW'!$C$2:$C$20)/1000000000,"") -> 699.89625 | D8: =SUMIF('DATA OEWS'!$A$2:$A$7806,A8,'DATA OEWS'!$G$2:$G$7806)/1000000000 -> 598.12192 | E8: =SUMIF('DATA OEWS'!$A$2:$A$7806,A8,'DATA OEWS'!$I$2:$I$7806)/1000000000 -> 596.27577 | F8: =SUMIF('DATA OEWS'!$A$2:$A$7806,A8,'DATA OEWS'!$J$2:$J$7806)/1000000000 -> 158.59374 | G8: =IF(D8=0,"",E8/D8) -> 0.99691342 | H8: =IF(E8=0,"",F8/E8) -> 0.26597382 | I8: =IF(OR(C8="",H8=""),"",C8*H8) -> 186.15408 | J8: =IFERROR(_xlfn.XLOOKUP(A8,'DATA Census'!$A$2:$A$20,'DATA Census'!$C$2:$C$20),"") -> 0.172 | K8: =IF(OR(I8="",J8=""),"",I8*J8) -> 32.018501 | L8: =IFERROR(_xlfn.XLOOKUP(A8,'DATA QCEW'!$A$2:$A$20,'DATA QCEW'!$F$2:$F$20),"") -> 8251002 | M8: =IF(OR(L8="",H8=""),"",L8*H8) -> 2194550.5 | N8: ='Projection Assumptions'!$C$9 -> 30 | O8: =IF(OR(M8="",N8=""),"",M8*N8*12/1000000000) -> 0.79003818 | P8: =IF(OR(M8="",J8=""),"",M8*J8) -> 377462.69 | Q8: =IF(OR(P8="",N8=""),"",P8*N8*12/1000000000) -> 0.13588657
A9: 31-33 | B9: Manufacturing | C9: =IFERROR(_xlfn.XLOOKUP(A9,'DATA QCEW'!$A$2:$A$20,'DATA QCEW'!$C$2:$C$20)/1000000000,"") -> 1125.5427 | D9: =SUMIF('DATA OEWS'!$A$2:$A$7806,A9,'DATA OEWS'!$G$2:$G$7806)/1000000000 -> 874.49352 | E9: =SUMIF('DATA OEWS'!$A$2:$A$7806,A9,'DATA OEWS'!$I$2:$I$7806)/1000000000 -> 864.06661 | F9: =SUMIF('DATA OEWS'!$A$2:$A$7806,A9,'DATA OEWS'!$J$2:$J$7806)/1000000000 -> 286.93931 | G9: =IF(D9=0,"",E9/D9) -> 0.98807663 | H9: =IF(E9=0,"",F9/E9) -> 0.33208008 | I9: =IF(OR(C9="",H9=""),"",C9*H9) -> 373.7703 | J9: =IFERROR(_xlfn.XLOOKUP(A9,'DATA Census'!$A$2:$A$20,'DATA Census'!$C$2:$C$20),"") -> 0.208 | K9: =IF(OR(I9="",J9=""),"",I9*J9) -> 77.744222 | L9: =IFERROR(_xlfn.XLOOKUP(A9,'DATA QCEW'!$A$2:$A$20,'DATA QCEW'!$F$2:$F$20),"") -> 12579906 | M9: =IF(OR(L9="",H9=""),"",L9*H9) -> 4177536.1 | N9: ='Projection Assumptions'!$C$9 -> 30 | O9: =IF(OR(M9="",N9=""),"",M9*N9*12/1000000000) -> 1.503913 | P9: =IF(OR(M9="",J9=""),"",M9*J9) -> 868927.52 | Q9: =IF(OR(P9="",N9=""),"",P9*N9*12/1000000000) -> 0.31281391
A10: 42 | B10: Wholesale trade | C10: =IFERROR(_xlfn.XLOOKUP(A10,'DATA QCEW'!$A$2:$A$20,'DATA QCEW'!$C$2:$C$20)/1000000000,"") -> 638.87897 | D10: =SUMIF('DATA OEWS'!$A$2:$A$7806,A10,'DATA OEWS'!$G$2:$G$7806)/1000000000 -> 458.15484 | E10: =SUMIF('DATA OEWS'!$A$2:$A$7806,A10,'DATA OEWS'!$I$2:$I$7806)/1000000000 -> 455.37523 | F10: =SUMIF('DATA OEWS'!$A$2:$A$7806,A10,'DATA OEWS'!$J$2:$J$7806)/1000000000 -> 210.41317 | G10: =IF(D10=0,"",E10/D10) -> 0.99393303 | H10: =IF(E10=0,"",F10/E10) -> 0.46206547 | I10: =IF(OR(C10="",H10=""),"",C10*H10) -> 295.20392 | J10: =IFERROR(_xlfn.XLOOKUP(A10,'DATA Census'!$A$2:$A$20,'DATA Census'!$C$2:$C$20),"") -> 0.216 | K10: =IF(OR(I10="",J10=""),"",I10*J10) -> 63.764046 | L10: =IFERROR(_xlfn.XLOOKUP(A10,'DATA QCEW'!$A$2:$A$20,'DATA QCEW'!$F$2:$F$20),"") -> 6037213 | M10: =IF(OR(L10="",H10=""),"",L10*H10) -> 2789587.7 | N10: ='Projection Assumptions'!$C$9 -> 30 | O10: =IF(OR(M10="",N10=""),"",M10*N10*12/1000000000) -> 1.0042516 | P10: =IF(OR(M10="",J10=""),"",M10*J10) -> 602550.94 | Q10: =IF(OR(P10="",N10=""),"",P10*N10*12/1000000000) -> 0.21691834
A11: 44-45 | B11: Retail trade | C11: =IFERROR(_xlfn.XLOOKUP(A11,'DATA QCEW'!$A$2:$A$20,'DATA QCEW'!$C$2:$C$20)/1000000000,"") -> 668.86357 | D11: =SUMIF('DATA OEWS'!$A$2:$A$7806,A11,'DATA OEWS'!$G$2:$G$7806)/1000000000 -> 693.02976 | E11: =SUMIF('DATA OEWS'!$A$2:$A$7806,A11,'DATA OEWS'!$I$2:$I$7806)/1000000000 -> 689.44551 | F11: =SUMIF('DATA OEWS'!$A$2:$A$7806,A11,'DATA OEWS'!$J$2:$J$7806)/1000000000 -> 302.19336 | G11: =IF(D11=0,"",E11/D11) -> 0.99482815 | H11: =IF(E11=0,"",F11/E11) -> 0.43831363 | I11: =IF(OR(C11="",H11=""),"",C11*H11) -> 293.17202 | J11: =IFERROR(_xlfn.XLOOKUP(A11,'DATA Census'!$A$2:$A$20,'DATA Census'!$C$2:$C$20),"") -> 0.168 | K11: =IF(OR(I11="",J11=""),"",I11*J11) -> 49.252899 | L11: =IFERROR(_xlfn.XLOOKUP(A11,'DATA QCEW'!$A$2:$A$20,'DATA QCEW'!$F$2:$F$20),"") -> 15391082 | M11: =IF(OR(L11="",H11=""),"",L11*H11) -> 6746121 | N11: ='Projection Assumptions'!$C$9 -> 30 | O11: =IF(OR(M11="",N11=""),"",M11*N11*12/1000000000) -> 2.4286035 | P11: =IF(OR(M11="",J11=""),"",M11*J11) -> 1133348.3 | Q11: =IF(OR(P11="",N11=""),"",P11*N11*12/1000000000) -> 0.4080054
A12: 48-49 | B12: Transportation and warehousing | C12: =IFERROR(_xlfn.XLOOKUP(A12,'DATA QCEW'!$A$2:$A$20,'DATA QCEW'!$C$2:$C$20)/1000000000,"") -> 455.48394 | D12: =SUMIF('DATA OEWS'!$A$2:$A$7806,A12,'DATA OEWS'!$G$2:$G$7806)/1000000000 -> 478.82617 | E12: =SUMIF('DATA OEWS'!$A$2:$A$7806,A12,'DATA OEWS'!$I$2:$I$7806)/1000000000 -> 477.19288 | F12: =SUMIF('DATA OEWS'!$A$2:$A$7806,A12,'DATA OEWS'!$J$2:$J$7806)/1000000000 -> 157.08135 | G12: =IF(D12=0,"",E12/D12) -> 0.99658896 | H12: =IF(E12=0,"",F12/E12) -> 0.3291779 | I12: =IF(OR(C12="",H12=""),"",C12*H12) -> 149.93525 | J12: =IFERROR(_xlfn.XLOOKUP(A12,'DATA Census'!$A$2:$A$20,'DATA Census'!$C$2:$C$20),"") -> 0.105 | K12: =IF(OR(I12="",J12=""),"",I12*J12) -> 15.743201 | L12: =IFERROR(_xlfn.XLOOKUP(A12,'DATA QCEW'!$A$2:$A$20,'DATA QCEW'!$F$2:$F$20),"") -> 6618917 | M12: =IF(OR(L12="",H12=""),"",L12*H12) -> 2178801.2 | N12: ='Projection Assumptions'!$C$9 -> 30 | O12: =IF(OR(M12="",N12=""),"",M12*N12*12/1000000000) -> 0.78436842 | P12: =IF(OR(M12="",J12=""),"",M12*J12) -> 228774.12 | Q12: =IF(OR(P12="",N12=""),"",P12*N12*12/1000000000) -> 0.082358685
A13: 51 | B13: Information | C13: =IFERROR(_xlfn.XLOOKUP(A13,'DATA QCEW'!$A$2:$A$20,'DATA QCEW'!$C$2:$C$20)/1000000000,"") -> 544.46957 | D13: =SUMIF('DATA OEWS'!$A$2:$A$7806,A13,'DATA OEWS'!$G$2:$G$7806)/1000000000 -> 323.62617 | E13: =SUMIF('DATA OEWS'!$A$2:$A$7806,A13,'DATA OEWS'!$I$2:$I$7806)/1000000000 -> 321.61476 | F13: =SUMIF('DATA OEWS'!$A$2:$A$7806,A13,'DATA OEWS'!$J$2:$J$7806)/1000000000 -> 181.50197 | G13: =IF(D13=0,"",E13/D13) -> 0.99378476 | H13: =IF(E13=0,"",F13/E13) -> 0.5643459 | I13: =IF(OR(C13="",H13=""),"",C13*H13) -> 307.26917 | J13: =IFERROR(_xlfn.XLOOKUP(A13,'DATA Census'!$A$2:$A$20,'DATA Census'!$C$2:$C$20),"") -> 0.502 | K13: =IF(OR(I13="",J13=""),"",I13*J13) -> 154.24912 | L13: =IFERROR(_xlfn.XLOOKUP(A13,'DATA QCEW'!$A$2:$A$20,'DATA QCEW'!$F$2:$F$20),"") -> 2850904 | M13: =IF(OR(L13="",H13=""),"",L13*H13) -> 1608896 | N13: ='Projection Assumptions'!$C$9 -> 30 | O13: =IF(OR(M13="",N13=""),"",M13*N13*12/1000000000) -> 0.57920256 | P13: =IF(OR(M13="",J13=""),"",M13*J13) -> 807665.79 | Q13: =IF(OR(P13="",N13=""),"",P13*N13*12/1000000000) -> 0.29075968
A14: 52 | B14: Finance and insurance | C14: =IFERROR(_xlfn.XLOOKUP(A14,'DATA QCEW'!$A$2:$A$20,'DATA QCEW'!$C$2:$C$20)/1000000000,"") -> 966.66675 | D14: =SUMIF('DATA OEWS'!$A$2:$A$7806,A14,'DATA OEWS'!$G$2:$G$7806)/1000000000 -> 632.3122 | E14: =SUMIF('DATA OEWS'!$A$2:$A$7806,A14,'DATA OEWS'!$I$2:$I$7806)/1000000000 -> 628.98598 | F14: =SUMIF('DATA OEWS'!$A$2:$A$7806,A14,'DATA OEWS'!$J$2:$J$7806)/1000000000 -> 426.99129 | G14: =IF(D14=0,"",E14/D14) -> 0.99473959 | H14: =IF(E14=0,"",F14/E14) -> 0.67885661 | I14: =IF(OR(C14="",H14=""),"",C14*H14) -> 656.22812 | J14: =IFERROR(_xlfn.XLOOKUP(A14,'DATA Census'!$A$2:$A$20,'DATA Census'!$C$2:$C$20),"") -> 0.401 | K14: =IF(OR(I14="",J14=""),"",I14*J14) -> 263.14747 | L14: =IFERROR(_xlfn.XLOOKUP(A14,'DATA QCEW'!$A$2:$A$20,'DATA QCEW'!$F$2:$F$20),"") -> 6316381 | M14: =IF(OR(L14="",H14=""),"",L14*H14) -> 4287917 | N14: ='Projection Assumptions'!$C$9 -> 30 | O14: =IF(OR(M14="",N14=""),"",M14*N14*12/1000000000) -> 1.5436501 | P14: =IF(OR(M14="",J14=""),"",M14*J14) -> 1719454.7 | Q14: =IF(OR(P14="",N14=""),"",P14*N14*12/1000000000) -> 0.6190037
A15: 53 | B15: Real estate and rental and leasing | C15: =IFERROR(_xlfn.XLOOKUP(A15,'DATA QCEW'!$A$2:$A$20,'DATA QCEW'!$C$2:$C$20)/1000000000,"") -> 193.52918 | D15: =SUMIF('DATA OEWS'!$A$2:$A$7806,A15,'DATA OEWS'!$G$2:$G$7806)/1000000000 -> 157.85057 | E15: =SUMIF('DATA OEWS'!$A$2:$A$7806,A15,'DATA OEWS'!$I$2:$I$7806)/1000000000 -> 156.90478 | F15: =SUMIF('DATA OEWS'!$A$2:$A$7806,A15,'DATA OEWS'!$J$2:$J$7806)/1000000000 -> 73.211257 | G15: =IF(D15=0,"",E15/D15) -> 0.99400829 | H15: =IF(E15=0,"",F15/E15) -> 0.46659674 | I15: =IF(OR(C15="",H15=""),"",C15*H15) -> 90.300084 | J15: =IFERROR(_xlfn.XLOOKUP(A15,'DATA Census'!$A$2:$A$20,'DATA Census'!$C$2:$C$20),"") -> 0.308 | K15: =IF(OR(I15="",J15=""),"",I15*J15) -> 27.812426 | L15: =IFERROR(_xlfn.XLOOKUP(A15,'DATA QCEW'!$A$2:$A$20,'DATA QCEW'!$F$2:$F$20),"") -> 2411118 | M15: =IF(OR(L15="",H15=""),"",L15*H15) -> 1125019.8 | N15: ='Projection Assumptions'!$C$9 -> 30 | O15: =IF(OR(M15="",N15=""),"",M15*N15*12/1000000000) -> 0.40500713 | P15: =IF(OR(M15="",J15=""),"",M15*J15) -> 346506.1 | Q15: =IF(OR(P15="",N15=""),"",P15*N15*12/1000000000) -> 0.1247422
A16: 54 | B16: Professional, scientific, and technical services | C16: =IFERROR(_xlfn.XLOOKUP(A16,'DATA QCEW'!$A$2:$A$20,'DATA QCEW'!$C$2:$C$20)/1000000000,"") -> 1454.3907 | D16: =SUMIF('DATA OEWS'!$A$2:$A$7806,A16,'DATA OEWS'!$G$2:$G$7806)/1000000000 -> 1171.2565 | E16: =SUMIF('DATA OEWS'!$A$2:$A$7806,A16,'DATA OEWS'!$I$2:$I$7806)/1000000000 -> 1167.2182 | F16: =SUMIF('DATA OEWS'!$A$2:$A$7806,A16,'DATA OEWS'!$J$2:$J$7806)/1000000000 -> 647.40875 | G16: =IF(D16=0,"",E16/D16) -> 0.99655214 | H16: =IF(E16=0,"",F16/E16) -> 0.55465958 | I16: =IF(OR(C16="",H16=""),"",C16*H16) -> 806.69172 | J16: =IFERROR(_xlfn.XLOOKUP(A16,'DATA Census'!$A$2:$A$20,'DATA Census'!$C$2:$C$20),"") -> 0.427 | K16: =IF(OR(I16="",J16=""),"",I16*J16) -> 344.45736 | L16: =IFERROR(_xlfn.XLOOKUP(A16,'DATA QCEW'!$A$2:$A$20,'DATA QCEW'!$F$2:$F$20),"") -> 10750955 | M16: =IF(OR(L16="",H16=""),"",L16*H16) -> 5963120.2 | N16: ='Projection Assumptions'!$C$9 -> 30 | O16: =IF(OR(M16="",N16=""),"",M16*N16*12/1000000000) -> 2.1467233 | P16: =IF(OR(M16="",J16=""),"",M16*J16) -> 2546252.3 | Q16: =IF(OR(P16="",N16=""),"",P16*N16*12/1000000000) -> 0.91665083
... A23: 81 | B23: Other services (except public administration) | C23: =IFERROR(_xlfn.XLOOKUP(A23,'DATA QCEW'!$A$2:$A$20,'DATA QCEW'!$C$2:$C$20)/1000000000,"") -> 254.46891 | D23: =SUMIF('DATA OEWS'!$A$2:$A$7806,A23,'DATA OEWS'!$G$2:$G$7806)/1000000000 -> 254.71444 | E23: =SUMIF('DATA OEWS'!$A$2:$A$7806,A23,'DATA OEWS'!$I$2:$I$7806)/1000000000 -> 250.74309 | F23: =SUMIF('DATA OEWS'!$A$2:$A$7806,A23,'DATA OEWS'!$J$2:$J$7806)/1000000000 -> 90.672712 | G23: =IF(D23=0,"",E23/D23) -> 0.98440864 | H23: =IF(E23=0,"",F23/E23) -> 0.36161599 | I23: =IF(OR(C23="",H23=""),"",C23*H23) -> 92.02003 | J23: =IFERROR(_xlfn.XLOOKUP(A23,'DATA Census'!$A$2:$A$20,'DATA Census'!$C$2:$C$20),"") -> 0.127 | K23: =IF(OR(I23="",J23=""),"",I23*J23) -> 11.686544 | L23: =IFERROR(_xlfn.XLOOKUP(A23,'DATA QCEW'!$A$2:$A$20,'DATA QCEW'!$F$2:$F$20),"") -> 4675880 | M23: =IF(OR(L23="",H23=""),"",L23*H23) -> 1690873 | N23: ='Projection Assumptions'!$C$9 -> 30 | O23: =IF(OR(M23="",N23=""),"",M23*N23*12/1000000000) -> 0.60871428 | P23: =IF(OR(M23="",J23=""),"",M23*J23) -> 214740.87 | Q23: =IF(OR(P23="",N23=""),"",P23*N23*12/1000000000) -> 0.077306713
B25: TOTAL | 19 PRIVATE INDUSTRIES | C25: =SUM(C5:C23) -> 10515.646 | D25: =SUM(D5:D23) -> 9162.6479 | E25: =SUM(E5:E23) -> 9084.5354 | F25: =SUM(F5:F23) -> 3671.5561 | I25: =SUM(I5:I23) -> 4435.9142 | K25: =SUM(K5:K23) -> 1311.4477 | L25: =SUM(L5:L23) -> 132959111 | M25: =SUM(M5:M23) -> 50267365 | O25: =SUM(O5:O23) -> 18.096251 | P25: =SUM(P5:P23) -> 12633444 | Q25: =SUM(Q5:Q23) -> 4.5480399

Sheet Five-Year Projection
A1: FIVE-YEAR PROJECTION | 2025–2030
A2: BLS 2025–2035 employment projections + illustrative nominal wages + Wharton exposure + Census BTOS firm adoption.
A5: U.S. PRIVATE SECTORS ($bn) | B5: 2025 | C5: 2026 | D5: 2027 | E5: 2028 | F5: 2029 | G5: 2030
A6: Industry Annual Wages ($bn) | B6: =SUMIF($C$17:$C$130,B$5,$F$17:$F$130) -> 10515.646 | C6: =SUMIF($C$17:$C$130,C$5,$F$17:$F$130) -> 10877.917 | D6: =SUMIF($C$17:$C$130,D$5,$F$17:$F$130) -> 11252.782 | E6: =SUMIF($C$17:$C$130,E$5,$F$17:$F$130) -> 11640.684 | F6: =SUMIF($C$17:$C$130,F$5,$F$17:$F$130) -> 12042.078 | G6: =SUMIF($C$17:$C$130,G$5,$F$17:$F$130) -> 12457.439
A7: Gross AI-Exposed Wages ($bn) | B7: =SUMIF($C$17:$C$130,B$5,$J$17:$J$130) -> 4435.9142 | C7: =SUMIF($C$17:$C$130,C$5,$J$17:$J$130) -> 4588.4232 | D7: =SUMIF($C$17:$C$130,D$5,$J$17:$J$130) -> 4746.2206 | E7: =SUMIF($C$17:$C$130,E$5,$J$17:$J$130) -> 4909.4915 | F7: =SUMIF($C$17:$C$130,F$5,$J$17:$J$130) -> 5078.4273 | G7: =SUMIF($C$17:$C$130,G$5,$J$17:$J$130) -> 5253.2262
A8: Firm-Use Proxy ($bn) | B8: =IF(B$5=2025,"",SUMIF($C$17:$C$130,B$5,$K$17:$K$130)) | C8: =IF(C$5=2025,"",SUMIF($C$17:$C$130,C$5,$K$17:$K$130)) -> 1357.2013 | D8: =IF(D$5=2025,"",SUMIF($C$17:$C$130,D$5,$K$17:$K$130)) -> 1641.8751 | E8: =IF(E$5=2025,"",SUMIF($C$17:$C$130,E$5,$K$17:$K$130)) -> 1944.5421 | F8: =IF(F$5=2025,"",SUMIF($C$17:$C$130,F$5,$K$17:$K$130)) -> 2266.1112 | G8: =IF(G$5=2025,"",SUMIF($C$17:$C$130,G$5,$K$17:$K$130)) -> 2607.5329
A9: Firm-use proxy / Gross Exposure | B9: =IF(B$5=2025,"",IFERROR(B8/B7,"")) | C9: =IF(C$5=2025,"",IFERROR(C8/C7,"")) -> 0.29578817 | D9: =IF(D$5=2025,"",IFERROR(D8/D7,"")) -> 0.34593315 | E9: =IF(E$5=2025,"",IFERROR(E8/E7,"")) -> 0.3960781 | F9: =IF(F$5=2025,"",IFERROR(F8/F7,"")) -> 0.44622303 | G9: =IF(G$5=2025,"",IFERROR(G8/G7,"")) -> 0.49636791
A10: Private Employment (million) | B10: =SUMIF($C$17:$C$130,B$5,$L$17:$L$130)/1000000 -> 132.95911 | C10: =SUMIF($C$17:$C$130,C$5,$L$17:$L$130)/1000000 -> 133.49715 | D10: =SUMIF($C$17:$C$130,D$5,$L$17:$L$130)/1000000 -> 134.03877 | E10: =SUMIF($C$17:$C$130,E$5,$L$17:$L$130)/1000000 -> 134.58399 | F10: =SUMIF($C$17:$C$130,F$5,$L$17:$L$130)/1000000 -> 135.13284 | G10: =SUMIF($C$17:$C$130,G$5,$L$17:$L$130)/1000000 -> 135.68536
A11: Task-Exposed Seat Eq. (million) | B11: =SUMIF($C$17:$C$130,B$5,$M$17:$M$130)/1000000 -> 50.267365 | C11: =SUMIF($C$17:$C$130,C$5,$M$17:$M$130)/1000000 -> 50.461789 | D11: =SUMIF($C$17:$C$130,D$5,$M$17:$M$130)/1000000 -> 50.657486 | E11: =SUMIF($C$17:$C$130,E$5,$M$17:$M$130)/1000000 -> 50.854467 | F11: =SUMIF($C$17:$C$130,F$5,$M$17:$M$130)/1000000 -> 51.052739 | G11: =SUMIF($C$17:$C$130,G$5,$M$17:$M$130)/1000000 -> 51.252314
A12: Task-Equivalent AI Revenue ($bn) | B12: =SUMIF($C$17:$C$130,B$5,$O$17:$O$130) -> 18.096251 | C12: =SUMIF($C$17:$C$130,C$5,$O$17:$O$130) -> 18.166244 | D12: =SUMIF($C$17:$C$130,D$5,$O$17:$O$130) -> 18.236695 | E12: =SUMIF($C$17:$C$130,E$5,$O$17:$O$130) -> 18.307608 | F12: =SUMIF($C$17:$C$130,F$5,$O$17:$O$130) -> 18.378986 | G12: =SUMIF($C$17:$C$130,G$5,$O$17:$O$130) -> 18.450833
A13: BTOS-Adj. Seat Eq. (million) | B13: =IF(B$5=2025,"",SUMIF($C$17:$C$130,B$5,$P$17:$P$130)/1000000) | C13: =IF(C$5=2025,"",SUMIF($C$17:$C$130,C$5,$P$17:$P$130)/1000000) -> 12.689267 | D13: =IF(D$5=2025,"",SUMIF($C$17:$C$130,D$5,$P$17:$P$130)/1000000) -> 15.278347 | E13: =IF(E$5=2025,"",SUMIF($C$17:$C$130,E$5,$P$17:$P$130)/1000000) -> 17.887509 | F13: =IF(F$5=2025,"",SUMIF($C$17:$C$130,F$5,$P$17:$P$130)/1000000) -> 20.516952 | G13: =IF(G$5=2025,"",SUMIF($C$17:$C$130,G$5,$P$17:$P$130)/1000000) -> 23.166874
A14: BTOS-Adj. AI Revenue ($bn) | B14: =IF(B$5=2025,"",SUMIF($C$17:$C$130,B$5,$Q$17:$Q$130)) | C14: =IF(C$5=2025,"",SUMIF($C$17:$C$130,C$5,$Q$17:$Q$130)) -> 4.5681362 | D14: =IF(D$5=2025,"",SUMIF($C$17:$C$130,D$5,$Q$17:$Q$130)) -> 5.5002048 | E14: =IF(E$5=2025,"",SUMIF($C$17:$C$130,E$5,$Q$17:$Q$130)) -> 6.4395034 | F14: =IF(F$5=2025,"",SUMIF($C$17:$C$130,F$5,$Q$17:$Q$130)) -> 7.3861028 | G14: =IF(G$5=2025,"",SUMIF($C$17:$C$130,G$5,$Q$17:$Q$130)) -> 8.3400746
L15: ADD-ON: EMPLOYEES → TASK SEATS → IMPLIED AI SUBSCRIPTION REVENUE
A16: NAICS | B16: Industry | C16: Year | D16: BLS Employment CAGR | E16: Nominal Wage Growth | F16: Industry Wages ($bn) | G16: AI Adoption Change (pp) | H16: AI-Using Firms | I16: AI Task Exposure | J16: Gross Exposed Wages ($bn) | K16: Firm-Use Proxy ($bn) | L16: Projected Employees | M16: Task-Exposed Seat Eq. (Proxy) | N16: AI Price ($/month) | O16: Potential AI Revenue ($bn) | P16: BTOS-Adj. Seat Eq. (Proxy) | Q16: BTOS-Adj. AI Revenue ($bn)
A17: 11 | B17: Agriculture, forestry, fishing and hunting | C17: 2025 | D17: =IFERROR(_xlfn.XLOOKUP(A17,'DATA BLS Projections'!$A$2:$A$20,'DATA BLS Projections'!$E$2:$E$20),0) -> 0.001474046 | E17: =IFERROR(_xlfn.XLOOKUP(A17,'Projection Assumptions'!$A$13:$A$31,'Projection Assumptions'!$C$13:$C$31),0) -> 0.03 | F17: =IF(C17=2025,_xlfn.XLOOKUP(A17,'01 Industry Model'!$A$5:$A$23,'01 Industry Model'!$C$5:$C$23),F16*(1+D17)*(1+E17)) -> 60.088225 | G17: =IFERROR(_xlfn.XLOOKUP(A17,'Projection Assumptions'!$A$13:$A$31,'Projection Assumptions'!$D$13:$D$31),0) -> 0.05 | H17: =IF(C17=2025,"",IF(C17=2026,_xlfn.XLOOKUP(A17,'DATA Census'!$A$2:$A$20,'DATA Census'!$C$2:$C$20),MIN(1,H16+G17))) | I17: =MIN(1,MAX(0,_xlfn.XLOOKUP(A17,'01 Industry Model'!$A$5:$A$23,'01 Industry Model'!$H$5:$H$23)+(C17-2025)*_xlfn.XLOOKUP(A17,'Projection Assumptions'!$A$13:$A$31,'Projection Assumptions'!$E$13:$E$31))) -> 0.18131399 | J17: =IF(F17="","",F17*I17) -> 10.894836 | K17: =IF(H17="","",J17*H17) | L17: =IF(C17=2025,IFERROR(_xlfn.XLOOKUP(A17,'DATA QCEW'!$A$2:$A$20,'DATA QCEW'!$F$2:$F$20),""),L16*(1+D17)) -> 1231078 | M17: =IF(OR(L17="",I17=""),"",L17*I17) -> 223211.66 | N17: =IF(C17=2025,'Projection Assumptions'!$C$9,N16*(1+'Projection Assumptions'!$C$10)) -> 30 | O17: =IF(OR(M17="",N17=""),"",M17*N17*12/1000000000) -> 0.080356199 | P17: =IF(OR(M17="",H17=""),"",M17*H17) | Q17: =IF(OR(P17="",N17=""),"",P17*N17*12/1000000000)
A18: 11 | B18: Agriculture, forestry, fishing and hunting | C18: 2026 | D18: =IFERROR(_xlfn.XLOOKUP(A18,'DATA BLS Projections'!$A$2:$A$20,'DATA BLS Projections'!$E$2:$E$20),0) -> 0.001474046 | E18: =IFERROR(_xlfn.XLOOKUP(A18,'Projection Assumptions'!$A$13:$A$31,'Projection Assumptions'!$C$13:$C$31),0) -> 0.03 | F18: =IF(C18=2025,_xlfn.XLOOKUP(A18,'01 Industry Model'!$A$5:$A$23,'01 Industry Model'!$C$5:$C$23),F17*(1+D18)*(1+E18)) -> 61.982102 | G18: =IFERROR(_xlfn.XLOOKUP(A18,'Projection Assumptions'!$A$13:$A$31,'Projection Assumptions'!$D$13:$D$31),0) -> 0.05 | H18: =IF(C18=2025,"",IF(C18=2026,_xlfn.XLOOKUP(A18,'DATA Census'!$A$2:$A$20,'DATA Census'!$C$2:$C$20),MIN(1,H17+G18))) -> 0.095 | I18: =MIN(1,MAX(0,_xlfn.XLOOKUP(A18,'01 Industry Model'!$A$5:$A$23,'01 Industry Model'!$H$5:$H$23)+(C18-2025)*_xlfn.XLOOKUP(A18,'Projection Assumptions'!$A$13:$A$31,'Projection Assumptions'!$E$13:$E$31))) -> 0.18131399 | J18: =IF(F18="","",F18*I18) -> 11.238222 | K18: =IF(H18="","",J18*H18) -> 1.0676311 | L18: =IF(C18=2025,IFERROR(_xlfn.XLOOKUP(A18,'DATA QCEW'!$A$2:$A$20,'DATA QCEW'!$F$2:$F$20),""),L17*(1+D18)) -> 1232892.7 | M18: =IF(OR(L18="",I18=""),"",L18*I18) -> 223540.69 | N18: =IF(C18=2025,'Projection Assumptions'!$C$9,N17*(1+'Projection Assumptions'!$C$10)) -> 30 | O18: =IF(OR(M18="",N18=""),"",M18*N18*12/1000000000) -> 0.080474647 | P18: =IF(OR(M18="",H18=""),"",M18*H18) -> 21236.365 | Q18: =IF(OR(P18="",N18=""),"",P18*N18*12/1000000000) -> 0.0076450915
A19: 11 | B19: Agriculture, forestry, fishing and hunting | C19: 2027 | D19: =IFERROR(_xlfn.XLOOKUP(A19,'DATA BLS Projections'!$A$2:$A$20,'DATA BLS Projections'!$E$2:$E$20),0) -> 0.001474046 | E19: =IFERROR(_xlfn.XLOOKUP(A19,'Projection Assumptions'!$A$13:$A$31,'Projection Assumptions'!$C$13:$C$31),0) -> 0.03 | F19: =IF(C19=2025,_xlfn.XLOOKUP(A19,'01 Industry Model'!$A$5:$A$23,'01 Industry Model'!$C$5:$C$23),F18*(1+D19)*(1+E19)) -> 63.93567 | G19: =IFERROR(_xlfn.XLOOKUP(A19,'Projection Assumptions'!$A$13:$A$31,'Projection Assumptions'!$D$13:$D$31),0) -> 0.05 | H19: =IF(C19=2025,"",IF(C19=2026,_xlfn.XLOOKUP(A19,'DATA Census'!$A$2:$A$20,'DATA Census'!$C$2:$C$20),MIN(1,H18+G19))) -> 0.145 | I19: =MIN(1,MAX(0,_xlfn.XLOOKUP(A19,'01 Industry Model'!$A$5:$A$23,'01 Industry Model'!$H$5:$H$23)+(C19-2025)*_xlfn.XLOOKUP(A19,'Projection Assumptions'!$A$13:$A$31,'Projection Assumptions'!$E$13:$E$31))) -> 0.18131399 | J19: =IF(F19="","",F19*I19) -> 11.592431 | K19: =IF(H19="","",J19*H19) -> 1.6809026 | L19: =IF(C19=2025,IFERROR(_xlfn.XLOOKUP(A19,'DATA QCEW'!$A$2:$A$20,'DATA QCEW'!$F$2:$F$20),""),L18*(1+D19)) -> 1234710 | M19: =IF(OR(L19="",I19=""),"",L19*I19) -> 223870.2 | N19: =IF(C19=2025,'Projection Assumptions'!$C$9,N18*(1+'Projection Assumptions'!$C$10)) -> 30 | O19: =IF(OR(M19="",N19=""),"",M19*N19*12/1000000000) -> 0.080593271 | P19: =IF(OR(M19="",H19=""),"",M19*H19) -> 32461.179 | Q19: =IF(OR(P19="",N19=""),"",P19*N19*12/1000000000) -> 0.011686024
A20: 11 | B20: Agriculture, forestry, fishing and hunting | C20: 2028 | D20: =IFERROR(_xlfn.XLOOKUP(A20,'DATA BLS Projections'!$A$2:$A$20,'DATA BLS Projections'!$E$2:$E$20),0) -> 0.001474046 | E20: =IFERROR(_xlfn.XLOOKUP(A20,'Projection Assumptions'!$A$13:$A$31,'Projection Assumptions'!$C$13:$C$31),0) -> 0.03 | F20: =IF(C20=2025,_xlfn.XLOOKUP(A20,'01 Industry Model'!$A$5:$A$23,'01 Industry Model'!$C$5:$C$23),F19*(1+D20)*(1+E20)) -> 65.950812 | G20: =IFERROR(_xlfn.XLOOKUP(A20,'Projection Assumptions'!$A$13:$A$31,'Projection Assumptions'!$D$13:$D$31),0) -> 0.05 | H20: =IF(C20=2025,"",IF(C20=2026,_xlfn.XLOOKUP(A20,'DATA Census'!$A$2:$A$20,'DATA Census'!$C$2:$C$20),MIN(1,H19+G20))) -> 0.195 | I20: =MIN(1,MAX(0,_xlfn.XLOOKUP(A20,'01 Industry Model'!$A$5:$A$23,'01 Industry Model'!$H$5:$H$23)+(C20-2025)*_xlfn.XLOOKUP(A20,'Projection Assumptions'!$A$13:$A$31,'Projection Assumptions'!$E$13:$E$31))) -> 0.18131399 | J20: =IF(F20="","",F20*I20) -> 11.957805 | K20: =IF(H20="","",J20*H20) -> 2.3317719 | L20: =IF(C20=2025,IFERROR(_xlfn.XLOOKUP(A20,'DATA QCEW'!$A$2:$A$20,'DATA QCEW'!$F$2:$F$20),""),L19*(1+D20)) -> 1236530 | M20: =IF(OR(L20="",I20=""),"",L20*I20) -> 224200.19 | N20: =IF(C20=2025,'Projection Assumptions'!$C$9,N19*(1+'Projection Assumptions'!$C$10)) -> 30 | O20: =IF(OR(M20="",N20=""),"",M20*N20*12/1000000000) -> 0.080712069 | P20: =IF(OR(M20="",H20=""),"",M20*H20) -> 43719.037 | Q20: =IF(OR(P20="",N20=""),"",P20*N20*12/1000000000) -> 0.015738853
A21: 11 | B21: Agriculture, forestry, fishing and hunting | C21: 2029 | D21: =IFERROR(_xlfn.XLOOKUP(A21,'DATA BLS Projections'!$A$2:$A$20,'DATA BLS Projections'!$E$2:$E$20),0) -> 0.001474046 | E21: =IFERROR(_xlfn.XLOOKUP(A21,'Projection Assumptions'!$A$13:$A$31,'Projection Assumptions'!$C$13:$C$31),0) -> 0.03 | F21: =IF(C21=2025,_xlfn.XLOOKUP(A21,'01 Industry Model'!$A$5:$A$23,'01 Industry Model'!$C$5:$C$23),F20*(1+D21)*(1+E21)) -> 68.029467 | G21: =IFERROR(_xlfn.XLOOKUP(A21,'Projection Assumptions'!$A$13:$A$31,'Projection Assumptions'!$D$13:$D$31),0) -> 0.05 | H21: =IF(C21=2025,"",IF(C21=2026,_xlfn.XLOOKUP(A21,'DATA Census'!$A$2:$A$20,'DATA Census'!$C$2:$C$20),MIN(1,H20+G21))) -> 0.245 | I21: =MIN(1,MAX(0,_xlfn.XLOOKUP(A21,'01 Industry Model'!$A$5:$A$23,'01 Industry Model'!$H$5:$H$23)+(C21-2025)*_xlfn.XLOOKUP(A21,'Projection Assumptions'!$A$13:$A$31,'Projection Assumptions'!$E$13:$E$31))) -> 0.18131399 | J21: =IF(F21="","",F21*I21) -> 12.334694 | K21: =IF(H21="","",J21*H21) -> 3.022 | L21: =IF(C21=2025,IFERROR(_xlfn.XLOOKUP(A21,'DATA QCEW'!$A$2:$A$20,'DATA QCEW'!$F$2:$F$20),""),L20*(1+D21)) -> 1238352.7 | M21: =IF(OR(L21="",I21=""),"",L21*I21) -> 224530.67 | N21: =IF(C21=2025,'Projection Assumptions'!$C$9,N20*(1+'Projection Assumptions'!$C$10)) -> 30 | O21: =IF(OR(M21="",N21=""),"",M21*N21*12/1000000000) -> 0.080831042 | P21: =IF(OR(M21="",H21=""),"",M21*H21) -> 55010.015 | Q21: =IF(OR(P21="",N21=""),"",P21*N21*12/1000000000) -> 0.019803605
A22: 11 | B22: Agriculture, forestry, fishing and hunting | C22: 2030 | D22: =IFERROR(_xlfn.XLOOKUP(A22,'DATA BLS Projections'!$A$2:$A$20,'DATA BLS Projections'!$E$2:$E$20),0) -> 0.001474046 | E22: =IFERROR(_xlfn.XLOOKUP(A22,'Projection Assumptions'!$A$13:$A$31,'Projection Assumptions'!$C$13:$C$31),0) -> 0.03 | F22: =IF(C22=2025,_xlfn.XLOOKUP(A22,'01 Industry Model'!$A$5:$A$23,'01 Industry Model'!$C$5:$C$23),F21*(1+D22)*(1+E22)) -> 70.173638 | G22: =IFERROR(_xlfn.XLOOKUP(A22,'Projection Assumptions'!$A$13:$A$31,'Projection Assumptions'!$D$13:$D$31),0) -> 0.05 | H22: =IF(C22=2025,"",IF(C22=2026,_xlfn.XLOOKUP(A22,'DATA Census'!$A$2:$A$20,'DATA Census'!$C$2:$C$20),MIN(1,H21+G22))) -> 0.295 | I22: =MIN(1,MAX(0,_xlfn.XLOOKUP(A22,'01 Industry Model'!$A$5:$A$23,'01 Industry Model'!$H$5:$H$23)+(C22-2025)*_xlfn.XLOOKUP(A22,'Projection Assumptions'!$A$13:$A$31,'Projection Assumptions'!$E$13:$E$31))) -> 0.18131399 | J22: =IF(F22="","",F22*I22) -> 12.723462 | K22: =IF(H22="","",J22*H22) -> 3.7534214 | L22: =IF(C22=2025,IFERROR(_xlfn.XLOOKUP(A22,'DATA QCEW'!$A$2:$A$20,'DATA QCEW'!$F$2:$F$20),""),L21*(1+D22)) -> 1240178.1 | M22: =IF(OR(L22="",I22=""),"",L22*I22) -> 224861.64 | N22: =IF(C22=2025,'Projection Assumptions'!$C$9,N21*(1+'Projection Assumptions'!$C$10)) -> 30 | O22: =IF(OR(M22="",N22=""),"",M22*N22*12/1000000000) -> 0.080950191 | P22: =IF(OR(M22="",H22=""),"",M22*H22) -> 66334.184 | Q22: =IF(OR(P22="",N22=""),"",P22*N22*12/1000000000) -> 0.023880306
A23: 21 | B23: Mining, quarrying, and oil and gas extraction | C23: 2025 | D23: =IFERROR(_xlfn.XLOOKUP(A23,'DATA BLS Projections'!$A$2:$A$20,'DATA BLS Projections'!$E$2:$E$20),0) -> 0.00066063067 | E23: =IFERROR(_xlfn.XLOOKUP(A23,'Projection Assumptions'!$A$13:$A$31,'Projection Assumptions'!$C$13:$C$31),0) -> 0.03 | F23: =IF(C23=2025,_xlfn.XLOOKUP(A23,'01 Industry Model'!$A$5:$A$23,'01 Industry Model'!$C$5:$C$23),F22*(1+D23)*(1+E23)) -> 76.216722 | G23: =IFERROR(_xlfn.XLOOKUP(A23,'Projection Assumptions'!$A$13:$A$31,'Projection Assumptions'!$D$13:$D$31),0) -> 0.05 | H23: =IF(C23=2025,"",IF(C23=2026,_xlfn.XLOOKUP(A23,'DATA Census'!$A$2:$A$20,'DATA Census'!$C$2:$C$20),MIN(1,H22+G23))) | I23: =MIN(1,MAX(0,_xlfn.XLOOKUP(A23,'01 Industry Model'!$A$5:$A$23,'01 Industry Model'!$H$5:$H$23)+(C23-2025)*_xlfn.XLOOKUP(A23,'Projection Assumptions'!$A$13:$A$31,'Projection Assumptions'!$E$13:$E$31))) -> 0.29026433 | J23: =IF(F23="","",F23*I23) -> 22.122996 | K23: =IF(H23="","",J23*H23) | L23: =IF(C23=2025,IFERROR(_xlfn.XLOOKUP(A23,'DATA QCEW'!$A$2:$A$20,'DATA QCEW'!$F$2:$F$20),""),L22*(1+D23)) -> 570806 | M23: =IF(OR(L23="",I23=""),"",L23*I23) -> 165684.62 | N23: =IF(C23=2025,'Projection Assumptions'!$C$9,N22*(1+'Projection Assumptions'!$C$10)) -> 30 | O23: =IF(OR(M23="",N23=""),"",M23*N23*12/1000000000) -> 0.059646464 | P23: =IF(OR(M23="",H23=""),"",M23*H23) | Q23: =IF(OR(P23="",N23=""),"",P23*N23*12/1000000000)
A24: 21 | B24: Mining, quarrying, and oil and gas extraction | C24: 2026 | D24: =IFERROR(_xlfn.XLOOKUP(A24,'DATA BLS Projections'!$A$2:$A$20,'DATA BLS Projections'!$E$2:$E$20),0) -> 0.00066063067 | E24: =IFERROR(_xlfn.XLOOKUP(A24,'Projection Assumptions'!$A$13:$A$31,'Projection Assumptions'!$C$13:$C$31),0) -> 0.03 | F24: =IF(C24=2025,_xlfn.XLOOKUP(A24,'01 Industry Model'!$A$5:$A$23,'01 Industry Model'!$C$5:$C$23),F23*(1+D24)*(1+E24)) -> 78.555085 | G24: =IFERROR(_xlfn.XLOOKUP(A24,'Projection Assumptions'!$A$13:$A$31,'Projection Assumptions'!$D$13:$D$31),0) -> 0.05 | H24: =IF(C24=2025,"",IF(C24=2026,_xlfn.XLOOKUP(A24,'DATA Census'!$A$2:$A$20,'DATA Census'!$C$2:$C$20),MIN(1,H23+G24))) -> 0.13 | I24: =MIN(1,MAX(0,_xlfn.XLOOKUP(A24,'01 Industry Model'!$A$5:$A$23,'01 Industry Model'!$H$5:$H$23)+(C24-2025)*_xlfn.XLOOKUP(A24,'Projection Assumptions'!$A$13:$A$31,'Projection Assumptions'!$E$13:$E$31))) -> 0.29026433 | J24: =IF(F24="","",F24*I24) -> 22.801739 | K24: =IF(H24="","",J24*H24) -> 2.9642261 | L24: =IF(C24=2025,IFERROR(_xlfn.XLOOKUP(A24,'DATA QCEW'!$A$2:$A$20,'DATA QCEW'!$F$2:$F$20),""),L23*(1+D24)) -> 571183.09 | M24: =IF(OR(L24="",I24=""),"",L24*I24) -> 165794.08 | N24: =IF(C24=2025,'Projection Assumptions'!$C$9,N23*(1+'Projection Assumptions'!$C$10)) -> 30 | O24: =IF(OR(M24="",N24=""),"",M24*N24*12/1000000000) -> 0.059685868 | P24: =IF(OR(M24="",H24=""),"",M24*H24) -> 21553.23 | Q24: =IF(OR(P24="",N24=""),"",P24*N24*12/1000000000) -> 0.0077591629
A25: 21 | B25: Mining, quarrying, and oil and gas extraction | C25: 2027 | D25: =IFERROR(_xlfn.XLOOKUP(A25,'DATA BLS Projections'!$A$2:$A$20,'DATA BLS Projections'!$E$2:$E$20),0) -> 0.00066063067 | E25: =IFERROR(_xlfn.XLOOKUP(A25,'Projection Assumptions'!$A$13:$A$31,'Projection Assumptions'!$C$13:$C$31),0) -> 0.03 | F25: =IF(C25=2025,_xlfn.XLOOKUP(A25,'01 Industry Model'!$A$5:$A$23,'01 Industry Model'!$C$5:$C$23),F24*(1+D25)*(1+E25)) -> 80.965191 | G25: =IFERROR(_xlfn.XLOOKUP(A25,'Projection Assumptions'!$A$13:$A$31,'Projection Assumptions'!$D$13:$D$31),0) -> 0.05 | H25: =IF(C25=2025,"",IF(C25=2026,_xlfn.XLOOKUP(A25,'DATA Census'!$A$2:$A$20,'DATA Census'!$C$2:$C$20),MIN(1,H24+G25))) -> 0.18 | I25: =MIN(1,MAX(0,_xlfn.XLOOKUP(A25,'01 Industry Model'!$A$5:$A$23,'01 Industry Model'!$H$5:$H$23)+(C25-2025)*_xlfn.XLOOKUP(A25,'Projection Assumptions'!$A$13:$A$31,'Projection Assumptions'!$E$13:$E$31))) -> 0.29026433 | J25: =IF(F25="","",F25*I25) -> 23.501307 | K25: =IF(H25="","",J25*H25) -> 4.2302352 | L25: =IF(C25=2025,IFERROR(_xlfn.XLOOKUP(A25,'DATA QCEW'!$A$2:$A$20,'DATA QCEW'!$F$2:$F$20),""),L24*(1+D25)) -> 571560.43 | M25: =IF(OR(L25="",I25=""),"",L25*I25) -> 165903.61 | N25: =IF(C25=2025,'Projection Assumptions'!$C$9,N24*(1+'Projection Assumptions'!$C$10)) -> 30 | O25: =IF(OR(M25="",N25=""),"",M25*N25*12/1000000000) -> 0.059725298 | P25: =IF(OR(M25="",H25=""),"",M25*H25) -> 29862.649 | Q25: =IF(OR(P25="",N25=""),"",P25*N25*12/1000000000) -> 0.010750554
A26: 21 | B26: Mining, quarrying, and oil and gas extraction | C26: 2028 | D26: =IFERROR(_xlfn.XLOOKUP(A26,'DATA BLS Projections'!$A$2:$A$20,'DATA BLS Projections'!$E$2:$E$20),0) -> 0.00066063067 | E26: =IFERROR(_xlfn.XLOOKUP(A26,'Projection Assumptions'!$A$13:$A$31,'Projection Assumptions'!$C$13:$C$31),0) -> 0.03 | F26: =IF(C26=2025,_xlfn.XLOOKUP(A26,'01 Industry Model'!$A$5:$A$23,'01 Industry Model'!$C$5:$C$23),F25*(1+D26)*(1+E26)) -> 83.449239 | G26: =IFERROR(_xlfn.XLOOKUP(A26,'Projection Assumptions'!$A$13:$A$31,'Projection Assumptions'!$D$13:$D$31),0) -> 0.05 | H26: =IF(C26=2025,"",IF(C26=2026,_xlfn.XLOOKUP(A26,'DATA Census'!$A$2:$A$20,'DATA Census'!$C$2:$C$20),MIN(1,H25+G26))) -> 0.23 | I26: =MIN(1,MAX(0,_xlfn.XLOOKUP(A26,'01 Industry Model'!$A$5:$A$23,'01 Industry Model'!$H$5:$H$23)+(C26-2025)*_xlfn.XLOOKUP(A26,'Projection Assumptions'!$A$13:$A$31,'Projection Assumptions'!$E$13:$E$31))) -> 0.29026433 | J26: =IF(F26="","",F26*I26) -> 24.222338 | K26: =IF(H26="","",J26*H26) -> 5.5711376 | L26: =IF(C26=2025,IFERROR(_xlfn.XLOOKUP(A26,'DATA QCEW'!$A$2:$A$20,'DATA QCEW'!$F$2:$F$20),""),L25*(1+D26)) -> 571938.02 | M26: =IF(OR(L26="",I26=""),"",L26*I26) -> 166013.21 | N26: =IF(C26=2025,'Projection Assumptions'!$C$9,N25*(1+'Projection Assumptions'!$C$10)) -> 30 | O26: =IF(OR(M26="",N26=""),"",M26*N26*12/1000000000) -> 0.059764755 | P26: =IF(OR(M26="",H26=""),"",M26*H26) -> 38183.038 | Q26: =IF(OR(P26="",N26=""),"",P26*N26*12/1000000000) -> 0.013745894
A27: 21 | B27: Mining, quarrying, and oil and gas extraction | C27: 2029 | D27: =IFERROR(_xlfn.XLOOKUP(A27,'DATA BLS Projections'!$A$2:$A$20,'DATA BLS Projections'!$E$2:$E$20),0) -> 0.00066063067 | E27: =IFERROR(_xlfn.XLOOKUP(A27,'Projection Assumptions'!$A$13:$A$31,'Projection Assumptions'!$C$13:$C$31),0) -> 0.03 | F27: =IF(C27=2025,_xlfn.XLOOKUP(A27,'01 Industry Model'!$A$5:$A$23,'01 Industry Model'!$C$5:$C$23),F26*(1+D27)*(1+E27)) -> 86.009499 | G27: =IFERROR(_xlfn.XLOOKUP(A27,'Projection Assumptions'!$A$13:$A$31,'Projection Assumptions'!$D$13:$D$31),0) -> 0.05 | H27: =IF(C27=2025,"",IF(C27=2026,_xlfn.XLOOKUP(A27,'DATA Census'!$A$2:$A$20,'DATA Census'!$C$2:$C$20),MIN(1,H26+G27))) -> 0.28 | I27: =MIN(1,MAX(0,_xlfn.XLOOKUP(A27,'01 Industry Model'!$A$5:$A$23,'01 Industry Model'!$H$5:$H$23)+(C27-2025)*_xlfn.XLOOKUP(A27,'Projection Assumptions'!$A$13:$A$31,'Projection Assumptions'!$E$13:$E$31))) -> 0.29026433 | J27: =IF(F27="","",F27*I27) -> 24.96549 | K27: =IF(H27="","",J27*H27) -> 6.9903371 | L27: =IF(C27=2025,IFERROR(_xlfn.XLOOKUP(A27,'DATA QCEW'!$A$2:$A$20,'DATA QCEW'!$F$2:$F$20),""),L26*(1+D27)) -> 572315.86 | M27: =IF(OR(L27="",I27=""),"",L27*I27) -> 166122.88 | N27: =IF(C27=2025,'Projection Assumptions'!$C$9,N26*(1+'Projection Assumptions'!$C$10)) -> 30 | O27: =IF(OR(M27="",N27=""),"",M27*N27*12/1000000000) -> 0.059804237 | P27: =IF(OR(M27="",H27=""),"",M27*H27) -> 46514.407 | Q27: =IF(OR(P27="",N27=""),"",P27*N27*12/1000000000) -> 0.016745186
A28: 21 | B28: Mining, quarrying, and oil and gas extraction | C28: 2030 | D28: =IFERROR(_xlfn.XLOOKUP(A28,'DATA BLS Projections'!$A$2:$A$20,'DATA BLS Projections'!$E$2:$E$20),0) -> 0.00066063067 | E28: =IFERROR(_xlfn.XLOOKUP(A28,'Projection Assumptions'!$A$13:$A$31,'Projection Assumptions'!$C$13:$C$31),0) -> 0.03 | F28: =IF(C28=2025,_xlfn.XLOOKUP(A28,'01 Industry Model'!$A$5:$A$23,'01 Industry Model'!$C$5:$C$23),F27*(1+D28)*(1+E28)) -> 88.648309 | G28: =IFERROR(_xlfn.XLOOKUP(A28,'Projection Assumptions'!$A$13:$A$31,'Projection Assumptions'!$D$13:$D$31),0) -> 0.05 | H28: =IF(C28=2025,"",IF(C28=2026,_xlfn.XLOOKUP(A28,'DATA Census'!$A$2:$A$20,'DATA Census'!$C$2:$C$20),MIN(1,H27+G28))) -> 0.33 | I28: =MIN(1,MAX(0,_xlfn.XLOOKUP(A28,'01 Industry Model'!$A$5:$A$23,'01 Industry Model'!$H$5:$H$23)+(C28-2025)*_xlfn.XLOOKUP(A28,'Projection Assumptions'!$A$13:$A$31,'Projection Assumptions'!$E$13:$E$31))) -> 0.29026433 | J28: =IF(F28="","",F28*I28) -> 25.731442 | K28: =IF(H28="","",J28*H28) -> 8.4913759 | L28: =IF(C28=2025,IFERROR(_xlfn.XLOOKUP(A28,'DATA QCEW'!$A$2:$A$20,'DATA QCEW'!$F$2:$F$20),""),L27*(1+D28)) -> 572693.95 | M28: =IF(OR(L28="",I28=""),"",L28*I28) -> 166232.63 | N28: =IF(C28=2025,'Projection Assumptions'!$C$9,N27*(1+'Projection Assumptions'!$C$10)) -> 30 | O28: =IF(OR(M28="",N28=""),"",M28*N28*12/1000000000) -> 0.059843746 | P28: =IF(OR(M28="",H28=""),"",M28*H28) -> 54856.767 | Q28: =IF(OR(P28="",N28=""),"",P28*N28*12/1000000000) -> 0.019748436
... A130: 81 | B130: Other services (except public administration) | C130: 2030 | D130: =IFERROR(_xlfn.XLOOKUP(A130,'DATA BLS Projections'!$A$2:$A$20,'DATA BLS Projections'!$E$2:$E$20),0) -> 0.003692761 | E130: =IFERROR(_xlfn.XLOOKUP(A130,'Projection Assumptions'!$A$13:$A$31,'Projection Assumptions'!$C$13:$C$31),0) -> 0.03 | F130: =IF(C130=2025,_xlfn.XLOOKUP(A130,'01 Industry Model'!$A$5:$A$23,'01 Industry Model'!$C$5:$C$23),F129*(1+D130)*(1+E130)) -> 300.4864 | G130: =IFERROR(_xlfn.XLOOKUP(A130,'Projection Assumptions'!$A$13:$A$31,'Projection Assumptions'!$D$13:$D$31),0) -> 0.05 | H130: =IF(C130=2025,"",IF(C130=2026,_xlfn.XLOOKUP(A130,'DATA Census'!$A$2:$A$20,'DATA Census'!$C$2:$C$20),MIN(1,H129+G130))) -> 0.327 | I130: =MIN(1,MAX(0,_xlfn.XLOOKUP(A130,'01 Industry Model'!$A$5:$A$23,'01 Industry Model'!$H$5:$H$23)+(C130-2025)*_xlfn.XLOOKUP(A130,'Projection Assumptions'!$A$13:$A$31,'Projection Assumptions'!$E$13:$E$31))) -> 0.36161599 | J130: =IF(F130="","",F130*I130) -> 108.66069 | K130: =IF(H130="","",J130*H130) -> 35.532045 | L130: =IF(C130=2025,IFERROR(_xlfn.XLOOKUP(A130,'DATA QCEW'!$A$2:$A$20,'DATA QCEW'!$F$2:$F$20),""),L129*(1+D130)) -> 4762854.5 | M130: =IF(OR(L130="",I130=""),"",L130*I130) -> 1722324.4 | N130: =IF(C130=2025,'Projection Assumptions'!$C$9,N129*(1+'Projection Assumptions'!$C$10)) -> 30 | O130: =IF(OR(M130="",N130=""),"",M130*N130*12/1000000000) -> 0.62003678 | P130: =IF(OR(M130="",H130=""),"",M130*H130) -> 563200.07 | Q130: =IF(OR(P130="",N130=""),"",P130*N130*12/1000000000) -> 0.20275203

Sheet DATA QCEW
A1: NAICS (TEXT) | B1: Industry | C1: 2025 Private Annual Wages ($) | D1: Raw rows with this NAICS | E1: Data Check | F1: 2025 Private Avg Employment
A2: 11 | B2: Agriculture, forestry, fishing and hunting | C2: =IF(D2=1,_xlfn.XLOOKUP(A2,'DATA QCEW Raw'!$E$2:$E$3000,'DATA QCEW Raw'!$D$2:$D$3000),"") -> 60088224865 | D2: =COUNTIF('DATA QCEW Raw'!$E$2:$E$3000,A2) -> 1 | E2: =IF(D2=1,"OK",IF(D2=0,"MISSING","DUPLICATE")) -> OK | F2: =IF(D2=1,_xlfn.XLOOKUP(A2,'DATA QCEW Raw'!$E$2:$E$3000,'DATA QCEW Raw'!$C$2:$C$3000),"") -> 1231078
A3: 21 | B3: Mining, quarrying, and oil and gas extraction | C3: =IF(D3=1,_xlfn.XLOOKUP(A3,'DATA QCEW Raw'!$E$2:$E$3000,'DATA QCEW Raw'!$D$2:$D$3000),"") -> 76216722054 | D3: =COUNTIF('DATA QCEW Raw'!$E$2:$E$3000,A3) -> 1 | E3: =IF(D3=1,"OK",IF(D3=0,"MISSING","DUPLICATE")) -> OK | F3: =IF(D3=1,_xlfn.XLOOKUP(A3,'DATA QCEW Raw'!$E$2:$E$3000,'DATA QCEW Raw'!$C$2:$C$3000),"") -> 570806
A4: 22 | B4: Utilities | C4: =IF(D4=1,_xlfn.XLOOKUP(A4,'DATA QCEW Raw'!$E$2:$E$3000,'DATA QCEW Raw'!$D$2:$D$3000),"") -> 85024861666 | D4: =COUNTIF('DATA QCEW Raw'!$E$2:$E$3000,A4) -> 1 | E4: =IF(D4=1,"OK",IF(D4=0,"MISSING","DUPLICATE")) -> OK | F4: =IF(D4=1,_xlfn.XLOOKUP(A4,'DATA QCEW Raw'!$E$2:$E$3000,'DATA QCEW Raw'!$C$2:$C$3000),"") -> 602080
A5: 23 | B5: Construction | C5: =IF(D5=1,_xlfn.XLOOKUP(A5,'DATA QCEW Raw'!$E$2:$E$3000,'DATA QCEW Raw'!$D$2:$D$3000),"") -> 699896249139 | D5: =COUNTIF('DATA QCEW Raw'!$E$2:$E$3000,A5) -> 1 | E5: =IF(D5=1,"OK",IF(D5=0,"MISSING","DUPLICATE")) -> OK | F5: =IF(D5=1,_xlfn.XLOOKUP(A5,'DATA QCEW Raw'!$E$2:$E$3000,'DATA QCEW Raw'!$C$2:$C$3000),"") -> 8251002
A6: 31-33 | B6: Manufacturing | C6: =IF(D6=1,_xlfn.XLOOKUP(A6,'DATA QCEW Raw'!$E$2:$E$3000,'DATA QCEW Raw'!$D$2:$D$3000),"") -> 1125542676332 | D6: =COUNTIF('DATA QCEW Raw'!$E$2:$E$3000,A6) -> 1 | E6: =IF(D6=1,"OK",IF(D6=0,"MISSING","DUPLICATE")) -> OK | F6: =IF(D6=1,_xlfn.XLOOKUP(A6,'DATA QCEW Raw'!$E$2:$E$3000,'DATA QCEW Raw'!$C$2:$C$3000),"") -> 12579906
A7: 42 | B7: Wholesale trade | C7: =IF(D7=1,_xlfn.XLOOKUP(A7,'DATA QCEW Raw'!$E$2:$E$3000,'DATA QCEW Raw'!$D$2:$D$3000),"") -> 638878973832 | D7: =COUNTIF('DATA QCEW Raw'!$E$2:$E$3000,A7) -> 1 | E7: =IF(D7=1,"OK",IF(D7=0,"MISSING","DUPLICATE")) -> OK | F7: =IF(D7=1,_xlfn.XLOOKUP(A7,'DATA QCEW Raw'!$E$2:$E$3000,'DATA QCEW Raw'!$C$2:$C$3000),"") -> 6037213
A8: 44-45 | B8: Retail trade | C8: =IF(D8=1,_xlfn.XLOOKUP(A8,'DATA QCEW Raw'!$E$2:$E$3000,'DATA QCEW Raw'!$D$2:$D$3000),"") -> 668863568474 | D8: =COUNTIF('DATA QCEW Raw'!$E$2:$E$3000,A8) -> 1 | E8: =IF(D8=1,"OK",IF(D8=0,"MISSING","DUPLICATE")) -> OK | F8: =IF(D8=1,_xlfn.XLOOKUP(A8,'DATA QCEW Raw'!$E$2:$E$3000,'DATA QCEW Raw'!$C$2:$C$3000),"") -> 15391082
A9: 48-49 | B9: Transportation and warehousing | C9: =IF(D9=1,_xlfn.XLOOKUP(A9,'DATA QCEW Raw'!$E$2:$E$3000,'DATA QCEW Raw'!$D$2:$D$3000),"") -> 455483942924 | D9: =COUNTIF('DATA QCEW Raw'!$E$2:$E$3000,A9) -> 1 | E9: =IF(D9=1,"OK",IF(D9=0,"MISSING","DUPLICATE")) -> OK | F9: =IF(D9=1,_xlfn.XLOOKUP(A9,'DATA QCEW Raw'!$E$2:$E$3000,'DATA QCEW Raw'!$C$2:$C$3000),"") -> 6618917
A10: 51 | B10: Information | C10: =IF(D10=1,_xlfn.XLOOKUP(A10,'DATA QCEW Raw'!$E$2:$E$3000,'DATA QCEW Raw'!$D$2:$D$3000),"") -> 544469565204 | D10: =COUNTIF('DATA QCEW Raw'!$E$2:$E$3000,A10) -> 1 | E10: =IF(D10=1,"OK",IF(D10=0,"MISSING","DUPLICATE")) -> OK | F10: =IF(D10=1,_xlfn.XLOOKUP(A10,'DATA QCEW Raw'!$E$2:$E$3000,'DATA QCEW Raw'!$C$2:$C$3000),"") -> 2850904
A11: 52 | B11: Finance and insurance | C11: =IF(D11=1,_xlfn.XLOOKUP(A11,'DATA QCEW Raw'!$E$2:$E$3000,'DATA QCEW Raw'!$D$2:$D$3000),"") -> 966666752201 | D11: =COUNTIF('DATA QCEW Raw'!$E$2:$E$3000,A11) -> 1 | E11: =IF(D11=1,"OK",IF(D11=0,"MISSING","DUPLICATE")) -> OK | F11: =IF(D11=1,_xlfn.XLOOKUP(A11,'DATA QCEW Raw'!$E$2:$E$3000,'DATA QCEW Raw'!$C$2:$C$3000),"") -> 6316381
A12: 53 | B12: Real estate and rental and leasing | C12: =IF(D12=1,_xlfn.XLOOKUP(A12,'DATA QCEW Raw'!$E$2:$E$3000,'DATA QCEW Raw'!$D$2:$D$3000),"") -> 193529178704 | D12: =COUNTIF('DATA QCEW Raw'!$E$2:$E$3000,A12) -> 1 | E12: =IF(D12=1,"OK",IF(D12=0,"MISSING","DUPLICATE")) -> OK | F12: =IF(D12=1,_xlfn.XLOOKUP(A12,'DATA QCEW Raw'!$E$2:$E$3000,'DATA QCEW Raw'!$C$2:$C$3000),"") -> 2411118
A13: 54 | B13: Professional, scientific, and technical services | C13: =IF(D13=1,_xlfn.XLOOKUP(A13,'DATA QCEW Raw'!$E$2:$E$3000,'DATA QCEW Raw'!$D$2:$D$3000),"") -> 1454390668355 | D13: =COUNTIF('DATA QCEW Raw'!$E$2:$E$3000,A13) -> 1 | E13: =IF(D13=1,"OK",IF(D13=0,"MISSING","DUPLICATE")) -> OK | F13: =IF(D13=1,_xlfn.XLOOKUP(A13,'DATA QCEW Raw'!$E$2:$E$3000,'DATA QCEW Raw'!$C$2:$C$3000),"") -> 10750955
... A20: 81 | B20: Other services (except public administration) | C20: =IF(D20=1,_xlfn.XLOOKUP(A20,'DATA QCEW Raw'!$E$2:$E$3000,'DATA QCEW Raw'!$D$2:$D$3000),"") -> 254468914292 | D20: =COUNTIF('DATA QCEW Raw'!$E$2:$E$3000,A20) -> 1 | E20: =IF(D20=1,"OK",IF(D20=0,"MISSING","DUPLICATE")) -> OK | F20: =IF(D20=1,_xlfn.XLOOKUP(A20,'DATA QCEW Raw'!$E$2:$E$3000,'DATA QCEW Raw'!$C$2:$C$3000),"") -> 4675880
A23: TOTAL 19 INDUSTRIES | C23: =SUM(C2:C20) -> 10515645524505
A24: NAICS 99 UNCLASSIFIED | C24: =IFERROR(_xlfn.XLOOKUP("99",'DATA QCEW Raw'!$E$2:$E$3000,'DATA QCEW Raw'!$D$2:$D$3000),"") -> 16545877587
A25: US PRIVATE TOTAL | C25: 10532191402092
A26: RECONCILIATION GAP (SHOULD BE 0) | C26: =IF(C24="","",C23+C24-C25) -> 0

Sheet Projection Assumptions
A1: PROJECTION ASSUMPTIONS | BLUE = EDITABLE
A2: Nominal wage growth, BTOS firm adoption and task exposure expansion are illustrative assumptions, not official forecasts.
B5: Annual nominal wage growth per employee | C5: 0.03 | D5: Illustrative wage assumption (not BLS official forecast)
B6: Annual AI-using firm growth (percentage points) | C6: 0.05 | D6: Linear adoption increase after observed 2026, capped at 100%
B7: Annual task exposure increase (percentage points) | C7: 0 | D7: Keep Wharton task exposure unchanged by default
B9: Enterprise AI monthly spend / seat ($) | C9: 30 | D9: Illustrative price assumption; editable by user. Not BLS or Census data.
B10: Annual AI spend per seat growth | C10: 0 | D10: Illustrative nominal seat price inflation after 2025.
B11: Revenue interpretation | D11: Wharton is task exposure, NOT share of workers using AI. Revenue is a seat-equivalent scenario, not measured AI sales.
A12: NAICS (TEXT) | B12: Industry | C12: Wage Growth per Year | D12: AI Adoption Change (pp) | E12: AI Task Exposure Change (pp) | F12: Use / Override
A13: 11 | B13: Agriculture, forestry, fishing and hunting | C13: =$C$5 -> 0.03 | D13: =$C$6 -> 0.05 | E13: =$C$7 -> 0 | F13: Override C:E for sector-specific scenario
A14: 21 | B14: Mining, quarrying, and oil and gas extraction | C14: =$C$5 -> 0.03 | D14: =$C$6 -> 0.05 | E14: =$C$7 -> 0 | F14: Override C:E for sector-specific scenario
A15: 22 | B15: Utilities | C15: =$C$5 -> 0.03 | D15: =$C$6 -> 0.05 | E15: =$C$7 -> 0 | F15: Override C:E for sector-specific scenario
A16: 23 | B16: Construction | C16: =$C$5 -> 0.03 | D16: =$C$6 -> 0.05 | E16: =$C$7 -> 0 | F16: Override C:E for sector-specific scenario
A17: 31-33 | B17: Manufacturing | C17: =$C$5 -> 0.03 | D17: =$C$6 -> 0.05 | E17: =$C$7 -> 0 | F17: Override C:E for sector-specific scenario
A18: 42 | B18: Wholesale trade | C18: =$C$5 -> 0.03 | D18: =$C$6 -> 0.05 | E18: =$C$7 -> 0 | F18: Override C:E for sector-specific scenario
A19: 44-45 | B19: Retail trade | C19: =$C$5 -> 0.03 | D19: =$C$6 -> 0.05 | E19: =$C$7 -> 0 | F19: Override C:E for sector-specific scenario
A20: 48-49 | B20: Transportation and warehousing | C20: =$C$5 -> 0.03 | D20: =$C$6 -> 0.05 | E20: =$C$7 -> 0 | F20: Override C:E for sector-specific scenario
A21: 51 | B21: Information | C21: =$C$5 -> 0.03 | D21: =$C$6 -> 0.05 | E21: =$C$7 -> 0 | F21: Override C:E for sector-specific scenario
A22: 52 | B22: Finance and insurance | C22: =$C$5 -> 0.03 | D22: =$C$6 -> 0.05 | E22: =$C$7 -> 0 | F22: Override C:E for sector-specific scenario
A23: 53 | B23: Real estate and rental and leasing | C23: =$C$5 -> 0.03 | D23: =$C$6 -> 0.05 | E23: =$C$7 -> 0 | F23: Override C:E for sector-specific scenario
A24: 54 | B24: Professional, scientific, and technical services | C24: =$C$5 -> 0.03 | D24: =$C$6 -> 0.05 | E24: =$C$7 -> 0 | F24: Override C:E for sector-specific scenario
... A31: 81 | B31: Other services (except public administration) | C31: =$C$5 -> 0.03 | D31: =$C$6 -> 0.05 | E31: =$C$7 -> 0 | F31: Override C:E for sector-specific scenario

Sheet DATA BLS Projections
A1: NAICS (TEXT) | B1: Industry | C1: 2025 Employed (000s) | D1: 2035 Employed (000s) | E1: BLS Annual Employment CAGR [FORMULA] | F1: Sector mapping / notes
A2: 11 | B2: Agriculture, forestry, fishing and hunting | C2: 1462.4 | D2: 1484.1 | E2: =IF(OR(C2="",D2=""),"",(D2/C2)^(1/10)-1) -> 0.001474046 | F2: Corresponding private-sector NAICS major sector; rounded BLS 2025 & 2035 employment
A3: 21 | B3: Mining, quarrying, and oil and gas extraction | C3: 573.5 | D3: 577.3 | E3: =IF(OR(C3="",D3=""),"",(D3/C3)^(1/10)-1) -> 0.00066063067 | F3: Corresponding private-sector NAICS major sector; rounded BLS 2025 & 2035 employment
A4: 22 | B4: Utilities | C4: 601.3 | D4: 660.1 | E4: =IF(OR(C4="",D4=""),"",(D4/C4)^(1/10)-1) -> 0.0093733937 | F4: Corresponding private-sector NAICS major sector; rounded BLS 2025 & 2035 employment
A5: 23 | B5: Construction | C5: 8266.7 | D5: 8677.4 | E5: =IF(OR(C5="",D5=""),"",(D5/C5)^(1/10)-1) -> 0.0048604285 | F5: Corresponding private-sector NAICS major sector; rounded BLS 2025 & 2035 employment
A6: 31-33 | B6: Manufacturing | C6: 12633.7 | D6: 12705.8 | E6: =IF(OR(C6="",D6=""),"",(D6/C6)^(1/10)-1) -> 0.00056923549 | F6: Corresponding private-sector NAICS major sector; rounded BLS 2025 & 2035 employment
A7: 42 | B7: Wholesale trade | C7: 6059.5 | D7: 6184.7 | E7: =IF(OR(C7="",D7=""),"",(D7/C7)^(1/10)-1) -> 0.0020472139 | F7: Corresponding private-sector NAICS major sector; rounded BLS 2025 & 2035 employment
A8: 44-45 | B8: Retail trade | C8: 15440.9 | D8: 15413.4 | E8: =IF(OR(C8="",D8=""),"",(D8/C8)^(1/10)-1) -> -0.00017824132 | F8: Corresponding private-sector NAICS major sector; rounded BLS 2025 & 2035 employment
A9: 48-49 | B9: Transportation and warehousing | C9: 6639.5 | D9: 6846.8 | E9: =IF(OR(C9="",D9=""),"",(D9/C9)^(1/10)-1) -> 0.0030792041 | F9: BLS transportation excludes postal service; minor NAICS scope mismatch
A10: 51 | B10: Information | C10: 2861.9 | D10: 3012.9 | E10: =IF(OR(C10="",D10=""),"",(D10/C10)^(1/10)-1) -> 0.0051549744 | F10: Corresponding private-sector NAICS major sector; rounded BLS 2025 & 2035 employment
A11: 52 | B11: Finance and insurance | C11: 6739.3 | D11: 6893.6 | E11: =IF(OR(C11="",D11=""),"",(D11/C11)^(1/10)-1) -> 0.0022663025 | F11: Corresponding private-sector NAICS major sector; rounded BLS 2025 & 2035 employment
A12: 53 | B12: Real estate and rental and leasing | C12: 2456.7 | D12: 2539.7 | E12: =IF(OR(C12="",D12=""),"",(D12/C12)^(1/10)-1) -> 0.0033282241 | F12: Corresponding private-sector NAICS major sector; rounded BLS 2025 & 2035 employment
A13: 54 | B13: Professional, scientific, and technical services | C13: 10779.2 | D13: 11705.9 | E13: =IF(OR(C13="",D13=""),"",(D13/C13)^(1/10)-1) -> 0.0082815677 | F13: Corresponding private-sector NAICS major sector; rounded BLS 2025 & 2035 employment
... A20: 81 | B20: Other services (except public administration) | C20: 6575.7 | D20: 6822.6 | E20: =IF(OR(C20="",D20=""),"",(D20/C20)^(1/10)-1) -> 0.003692761 | F20: Corresponding private-sector NAICS major sector; rounded BLS 2025 & 2035 employment

Sheet DATA QCEW Raw
A1: Industry (paste BLS raw) | B1: Annual Establishments (optional) | C1: 2025 Private Avg Employment (BLS QCEW) | D1: Total Annual Wages ($) | E1: NAICS code [FORMULA] | F1: Industry title [FORMULA] | G1: Sector classification [FORMULA]
A2: NAICS 11 Agriculture, forestry, fishing and hunting | C2: 1231078 | D2: 60088224865 | E2: =IF(LEFT(TRIM(A2),6)="NAICS ",IFERROR(MID(TRIM(A2),7,FIND(" ",TRIM(A2)&" ",7)-7),""),"") -> 11 | F2: =IF(E2="","",TRIM(MID(TRIM(A2),FIND(" ",TRIM(A2)&" ",7)+1,255))) -> Agriculture, forestry, fishing and hunting | G2: =IF(E2="","",IF(COUNTIF('DATA QCEW'!$A$2:$A$20,E2)>0,"19-SECTOR","DETAIL / OTHER")) -> 19-SECTOR
A3: NAICS 21 Mining, quarrying, and oil and gas extraction | C3: 570806 | D3: 76216722054 | E3: =IF(LEFT(TRIM(A3),6)="NAICS ",IFERROR(MID(TRIM(A3),7,FIND(" ",TRIM(A3)&" ",7)-7),""),"") -> 21 | F3: =IF(E3="","",TRIM(MID(TRIM(A3),FIND(" ",TRIM(A3)&" ",7)+1,255))) -> Mining, quarrying, and oil and gas extraction | G3: =IF(E3="","",IF(COUNTIF('DATA QCEW'!$A$2:$A$20,E3)>0,"19-SECTOR","DETAIL / OTHER")) -> 19-SECTOR
A4: NAICS 22 Utilities | C4: 602080 | D4: 85024861666 | E4: =IF(LEFT(TRIM(A4),6)="NAICS ",IFERROR(MID(TRIM(A4),7,FIND(" ",TRIM(A4)&" ",7)-7),""),"") -> 22 | F4: =IF(E4="","",TRIM(MID(TRIM(A4),FIND(" ",TRIM(A4)&" ",7)+1,255))) -> Utilities | G4: =IF(E4="","",IF(COUNTIF('DATA QCEW'!$A$2:$A$20,E4)>0,"19-SECTOR","DETAIL / OTHER")) -> 19-SECTOR
A5: NAICS 23 Construction | C5: 8251002 | D5: 699896249139 | E5: =IF(LEFT(TRIM(A5),6)="NAICS ",IFERROR(MID(TRIM(A5),7,FIND(" ",TRIM(A5)&" ",7)-7),""),"") -> 23 | F5: =IF(E5="","",TRIM(MID(TRIM(A5),FIND(" ",TRIM(A5)&" ",7)+1,255))) -> Construction | G5: =IF(E5="","",IF(COUNTIF('DATA QCEW'!$A$2:$A$20,E5)>0,"19-SECTOR","DETAIL / OTHER")) -> 19-SECTOR
A6: NAICS 31-33 Manufacturing | C6: 12579906 | D6: 1125542676332 | E6: =IF(LEFT(TRIM(A6),6)="NAICS ",IFERROR(MID(TRIM(A6),7,FIND(" ",TRIM(A6)&" ",7)-7),""),"") -> 31-33 | F6: =IF(E6="","",TRIM(MID(TRIM(A6),FIND(" ",TRIM(A6)&" ",7)+1,255))) -> Manufacturing | G6: =IF(E6="","",IF(COUNTIF('DATA QCEW'!$A$2:$A$20,E6)>0,"19-SECTOR","DETAIL / OTHER")) -> 19-SECTOR
A7: NAICS 42 Wholesale trade | C7: 6037213 | D7: 638878973832 | E7: =IF(LEFT(TRIM(A7),6)="NAICS ",IFERROR(MID(TRIM(A7),7,FIND(" ",TRIM(A7)&" ",7)-7),""),"") -> 42 | F7: =IF(E7="","",TRIM(MID(TRIM(A7),FIND(" ",TRIM(A7)&" ",7)+1,255))) -> Wholesale trade | G7: =IF(E7="","",IF(COUNTIF('DATA QCEW'!$A$2:$A$20,E7)>0,"19-SECTOR","DETAIL / OTHER")) -> 19-SECTOR
A8: NAICS 44-45 Retail trade | C8: 15391082 | D8: 668863568474 | E8: =IF(LEFT(TRIM(A8),6)="NAICS ",IFERROR(MID(TRIM(A8),7,FIND(" ",TRIM(A8)&" ",7)-7),""),"") -> 44-45 | F8: =IF(E8="","",TRIM(MID(TRIM(A8),FIND(" ",TRIM(A8)&" ",7)+1,255))) -> Retail trade | G8: =IF(E8="","",IF(COUNTIF('DATA QCEW'!$A$2:$A$20,E8)>0,"19-SECTOR","DETAIL / OTHER")) -> 19-SECTOR
A9: NAICS 48-49 Transportation and warehousing | C9: 6618917 | D9: 455483942924 | E9: =IF(LEFT(TRIM(A9),6)="NAICS ",IFERROR(MID(TRIM(A9),7,FIND(" ",TRIM(A9)&" ",7)-7),""),"") -> 48-49 | F9: =IF(E9="","",TRIM(MID(TRIM(A9),FIND(" ",TRIM(A9)&" ",7)+1,255))) -> Transportation and warehousing | G9: =IF(E9="","",IF(COUNTIF('DATA QCEW'!$A$2:$A$20,E9)>0,"19-SECTOR","DETAIL / OTHER")) -> 19-SECTOR
A10: NAICS 51 Information | C10: 2850904 | D10: 544469565204 | E10: =IF(LEFT(TRIM(A10),6)="NAICS ",IFERROR(MID(TRIM(A10),7,FIND(" ",TRIM(A10)&" ",7)-7),""),"") -> 51 | F10: =IF(E10="","",TRIM(MID(TRIM(A10),FIND(" ",TRIM(A10)&" ",7)+1,255))) -> Information | G10: =IF(E10="","",IF(COUNTIF('DATA QCEW'!$A$2:$A$20,E10)>0,"19-SECTOR","DETAIL / OTHER")) -> 19-SECTOR
A11: NAICS 52 Finance and insurance | C11: 6316381 | D11: 966666752201 | E11: =IF(LEFT(TRIM(A11),6)="NAICS ",IFERROR(MID(TRIM(A11),7,FIND(" ",TRIM(A11)&" ",7)-7),""),"") -> 52 | F11: =IF(E11="","",TRIM(MID(TRIM(A11),FIND(" ",TRIM(A11)&" ",7)+1,255))) -> Finance and insurance | G11: =IF(E11="","",IF(COUNTIF('DATA QCEW'!$A$2:$A$20,E11)>0,"19-SECTOR","DETAIL / OTHER")) -> 19-SECTOR
A12: NAICS 53 Real estate and rental and leasing | C12: 2411118 | D12: 193529178704 | E12: =IF(LEFT(TRIM(A12),6)="NAICS ",IFERROR(MID(TRIM(A12),7,FIND(" ",TRIM(A12)&" ",7)-7),""),"") -> 53 | F12: =IF(E12="","",TRIM(MID(TRIM(A12),FIND(" ",TRIM(A12)&" ",7)+1,255))) -> Real estate and rental and leasing | G12: =IF(E12="","",IF(COUNTIF('DATA QCEW'!$A$2:$A$20,E12)>0,"19-SECTOR","DETAIL / OTHER")) -> 19-SECTOR
A13: NAICS 54 Professional, scientific, and technical services | C13: 10750955 | D13: 1454390668355 | E13: =IF(LEFT(TRIM(A13),6)="NAICS ",IFERROR(MID(TRIM(A13),7,FIND(" ",TRIM(A13)&" ",7)-7),""),"") -> 54 | F13: =IF(E13="","",TRIM(MID(TRIM(A13),FIND(" ",TRIM(A13)&" ",7)+1,255))) -> Professional, scientific, and technical services | G13: =IF(E13="","",IF(COUNTIF('DATA QCEW'!$A$2:$A$20,E13)>0,"19-SECTOR","DETAIL / OTHER")) -> 19-SECTOR
... A20: NAICS 81 Other services (except public administration) | C20: 4675880 | D20: 254468914292 | E20: =IF(LEFT(TRIM(A20),6)="NAICS ",IFERROR(MID(TRIM(A20),7,FIND(" ",TRIM(A20)&" ",7)-7),""),"") -> 81 | F20: =IF(E20="","",TRIM(MID(TRIM(A20),FIND(" ",TRIM(A20)&" ",7)+1,255))) -> Other services (except public administration) | G20: =IF(E20="","",IF(COUNTIF('DATA QCEW'!$A$2:$A$20,E20)>0,"19-SECTOR","DETAIL / OTHER")) -> 19-SECTOR
A21: NAICS 99 Unclassified | D21: 16545877587 | E21: =IF(LEFT(TRIM(A21),6)="NAICS ",IFERROR(MID(TRIM(A21),7,FIND(" ",TRIM(A21)&" ",7)-7),""),"") -> 99 | F21: =IF(E21="","",TRIM(MID(TRIM(A21),FIND(" ",TRIM(A21)&" ",7)+1,255))) -> Unclassified | G21: =IF(E21="","",IF(COUNTIF('DATA QCEW'!$A$2:$A$20,E21)>0,"19-SECTOR","DETAIL / OTHER")) -> DETAIL / OTHER
